Workbook

Sheet 版本测试日报
A2: AcuHMI-1-7 v1.03p01版本软件测试报告 （密级：C级）+A2:I32A2:I34A6A2:I66
A3: 【软件版本】 | B3: v1.03p01 | C3: 【硬件版本】 | D3: v1.05
A4: 【测试日期】 | B4: 2026.04.27-2026.04.29 | C4: 【版本目标】 | D4: 修改点验证
A5: 整体测试进展
A6: 1.用例执行总结：用例执行完成度100%； 2.问题单回归18个，通过18个； 3. 发现并确认产品问题13个。
A7: 风险&阻塞
A8: 序号 | B8: 问题描述 | H8: 责任人 | I8: 期望解决日期
A9: 1
A10: 用例执行情况
A11: 序号 | B11: 测试模块 | C11: 用例总数 | D11: 执行数 | E11: Passed | F11: Failed | G11: Unavailable | H11: Blocked | I11: 执行率
A12: 1 | B12: 接入设备日志管理 | C12: =COUNTIFS(测试用例!A$2:A$1138,版本测试日报!B12,测试用例!$N$2:$N$1138,"<>") -> 30 | D12: =E12+F12+G12+H12 -> 30 | E12: =COUNTIFS(测试用例!$A$2:$A$1138,版本测试日报!B12,测试用例!$M$2:$M$1138,$E$11) -> 27 | F12: =COUNTIFS(测试用例!$A$2:$A$1138,版本测试日报!B12,测试用例!$M$2:$M$1138,$F$11) -> 3 | G12: =COUNTIFS(测试用例!$A$2:$A$1138,版本测试日报!B12,测试用例!$M$2:$M$1138,$G$11) -> 0 | H12: =COUNTIFS(测试用例!$A$2:$A$1138,版本测试日报!B12,测试用例!$M$2:$M$1138,$H$11) -> 0 | I12: =D12/C12 -> 1
A13: 2 | B13: 设备数据协议转换 | C13: =COUNTIFS(测试用例!A$2:A$1138,版本测试日报!B13,测试用例!$N$2:$N$1138,"<>") -> 150 | D13: =E13+F13+G13+H13 -> 99 | E13: =COUNTIFS(测试用例!$A$2:$A$1138,版本测试日报!B13,测试用例!$M$2:$M$1138,$E$11) -> 65 | F13: =COUNTIFS(测试用例!$A$2:$A$1138,版本测试日报!B13,测试用例!$M$2:$M$1138,$F$11) -> 21 | G13: =COUNTIFS(测试用例!$A$2:$A$1138,版本测试日报!B13,测试用例!$M$2:$M$1138,$G$11) -> 13 | H13: =COUNTIFS(测试用例!$A$2:$A$1138,版本测试日报!B13,测试用例!$M$2:$M$1138,$H$11) -> 0 | I13: =D13/C13 -> 0.66
A14: 3 | B14: 系统设置 | C14: =COUNTIFS(测试用例!A$2:A$1138,版本测试日报!B14,测试用例!$N$2:$N$1138,"<>") -> 3 | D14: =E14+F14+G14+H14 -> 3 | E14: =COUNTIFS(测试用例!$A$2:$A$1138,版本测试日报!B14,测试用例!$M$2:$M$1138,$E$11) -> 1 | F14: =COUNTIFS(测试用例!$A$2:$A$1138,版本测试日报!B14,测试用例!$M$2:$M$1138,$F$11) -> 2 | G14: =COUNTIFS(测试用例!$A$2:$A$1138,版本测试日报!B14,测试用例!$M$2:$M$1138,$G$11) -> 0 | H14: =COUNTIFS(测试用例!$A$2:$A$1138,版本测试日报!B14,测试用例!$M$2:$M$1138,$H$11) -> 0 | I14: =D14/C14 -> 1
A15: 4 | B15: Virtual Device | C15: =COUNTIFS(测试用例!A$2:A$1138,版本测试日报!B15,测试用例!$N$2:$N$1138,"<>") -> 18 | D15: =E15+F15+G15+H15 -> 16 | E15: =COUNTIFS(测试用例!$A$2:$A$1138,版本测试日报!B15,测试用例!$M$2:$M$1138,$E$11) -> 14 | F15: =COUNTIFS(测试用例!$A$2:$A$1138,版本测试日报!B15,测试用例!$M$2:$M$1138,$F$11) -> 1 | G15: =COUNTIFS(测试用例!$A$2:$A$1138,版本测试日报!B15,测试用例!$M$2:$M$1138,$G$11) -> 1 | H15: =COUNTIFS(测试用例!$A$2:$A$1138,版本测试日报!B15,测试用例!$M$2:$M$1138,$H$11) -> 0 | I15: =D15/C15 -> 0.88888889
A16: 5 | B16: 接线检查 | C16: =COUNTIFS(测试用例!A$2:A$1138,版本测试日报!B16,测试用例!$N$2:$N$1138,"<>") -> 34 | D16: =E16+F16+G16+H16 -> 0 | E16: =COUNTIFS(测试用例!$A$2:$A$1138,版本测试日报!B16,测试用例!$M$2:$M$1138,$E$11) -> 0 | F16: =COUNTIFS(测试用例!$A$2:$A$1138,版本测试日报!B16,测试用例!$M$2:$M$1138,$F$11) -> 0 | G16: =COUNTIFS(测试用例!$A$2:$A$1138,版本测试日报!B16,测试用例!$M$2:$M$1138,$G$11) -> 0 | H16: =COUNTIFS(测试用例!$A$2:$A$1138,版本测试日报!B16,测试用例!$M$2:$M$1138,$H$11) -> 0 | I16: =D16/C16 -> 0
A17: Total | C17: =SUM(C12:C16) -> 235 | D17: =SUM(D12:D16) -> 148 | E17: =SUM(E12:E16) -> 107 | F17: =SUM(F12:F16) -> 27 | G17: =SUM(G12:G16) -> 14 | H17: =SUM(H12:H16) -> 0 | I17: =D17/C17 -> 0.62978723
A18: 发现问题列表
A19: 问题单号 | B19: 问题简要描述 | H19: 严重程度 | I19: 类别
A21: 问题单回归情况
A22: 问题单号 | B22: 问题简要描述 | G22: 回归测试人员 | H22: 回归通过（是/否） | I22: 类别
A24: 产品问题单解决统计
A25: 状态 | B25: 数量
A26: Closed 已关闭 | B26: 12
A27: Created 已创建 | B27: 2
A28: To be Verified 待验证 | B28: 0
A29: Rejected 已拒绝 | B29: 1
A30: In Progress 正在进行 | B30: 1
A31: HOLDING | B31: 0
A32: Self-testing 自测中 | B32: 0
A33: Reopen 重新打开 | B33: 0

Sheet 测试用例
A1: 模块 | B1: 子模块 | C1: 需求时间 | D1: 需求领域 | E1: FTS编号 | F1: FTS名称(用例编号) | G1: 用例编号 | H1: 用例标题 | I1: 预置条件 | J1: 测试步骤 | K1: 预期结果 | L1: 用例级别 | M1: 是否通过 | N1: 测试负责人 | O1: 待自动化 | P1: 完成自动化 | Q1: 问题单来源 | R1: 备注
A2: About | B2: About | D2: ALL | E2: FTS_AcuHMI_009_08_case01 | F2: 验证设备名字写入及长度 | G2: TestCase_AcuHMI_009_08_case01 | H2: 设备名字大于40个字符，保存配置失败，小于等于40个字符，保存配置成功 | I2: 1、管理权限登录AcuHMI网页 | J2: 1.About->Device information设置name超过40个字符 2.设置name小于等于40个字符 | K2: 1.保存配置失败 2.保存配置成功 | L2: LV3
A3: About | B3: About | D3: ALL | E3: FTS_AcuHMI_009_08_case02 | F3: 验证设备位置写入及长度 | G3: TestCase_AcuHMI_009_08_case02 | H3: 设备位置大于40个字符，保存配置失败，小于等于40个字符，保存配置成功 | I3: 1、管理权限登录AcuHMI网页 | J3: 1.About->Device information设置Location超过40个字符 2.设置name小于等于40个字符 | K3: 1.保存配置失败 2.保存配置成功 | L3: LV3
A4: About | B4: About | D4: ALL | E4: FTS_AcuHMI_009_08_case03 | F4: 验证设备描述写入及长度 | G4: TestCase_AcuHMI_009_08_case03 | H4: 设备描述大于40个字符，保存配置失败，小于等于40个字符，保存配置成功 | I4: 1、管理权限登录AcuHMI网页 | J4: 1.About->Device information设置Description超过40个字符 2.设置Description小于等于40个字符 | K4: 1.保存配置失败 2.保存配置成功 | L4: LV3
A5: About | B5: About | D5: ALL | E5: FTS_AcuHMI_009_08_case04 | F5: 验证设备类型、序号、硬件版本、固件本版、最后更新时间、以太网1MAC地址、以太网2MAC地址 | G5: TestCase_AcuHMI_009_08_case04 | H5: 设备类型、序号、硬件版本、固件本版、最后更新时间、以太网1MAC地址、以太网2MAC地址信息与实际设备信息一致 | I5: 1、管理权限登录AcuHMI网页 | J5: 1.查看About->Device information页面信息显示 | K5: 1.设备类型、序号、硬件版本、固件本版、最后更新时间、以太网1MAC地址、以太网2MAC地址信息与实际设备信息一致 注：需增加格式确认 | L5: LV0
A6: Maintenance | B6: System Status | D6: WEB | E6: FTS_AcuHMI_009_07_case01 | F6: 查看中央处理器占用率、内存占用率、磁盘占用率均满足系统要求，磁盘状态为正常 | G6: TestCase_AcuHMI_009_07_case01 | H6: 查看中央处理器占用率、内存占用率、磁盘占用率均满足系统要求，磁盘状态为正常 | I6: 1、管理权限登录AcuHMI网页 | J6: 1.Maintence->System Status查看系统CPU、RAM、磁盘使用情况 2.点击Reboot System 3.系统重启完成查看System Status | K6: 1.可以正常显示系统允许的各个参数： ·CPU的使用率。 ·RAM的使用情况，包含已经使用的和总共的。 ·Disk的使用情况，包含已经使用的和总共的。 2.系统重启 3.同上1 | L6: LV1
A7: Maintenance | B7: System Status | D7: WEB | E7: FTS_AcuHMI_009_07_case002 | F7: 选择间隔时间为1天，日志等级为危急，搜索事件日志并导出，日志显示事件戳、等级及消息显示准确，并重置筛选条件---Crital暂时不支持 | G7: TestCase_AcuHMI_009_07_case02 | H7: 选择间隔时间为1天，日志等级为危急，搜索事件日志并导出，日志显示事件戳、等级及消息显示准确，并重置筛选条件 | I7: 1、管理权限登录AcuHMI网页 | J7: 1.Maintence->Event设置间隔时间为1天，日志等级为Critical 2.点击Search 3.导出日志Export Logs 4.点击Reset | K7: 1.设置成功 2.日志显示事件戳、等级及消息显示准确 3.日志导出成功 4.筛选条件被重置 | L7: LV0
A8: Maintenance | B8: Event Log | D8: WEB | E8: FTS_AcuHMI_009_07_case002 | F8: 验证事件日志搜索导出功能 | G8: TestCase_AcuHMI_009_07_case02_1 | H8: 选择间隔时间为1周，日志等级为信息，搜索事件日志并导出，日志显示事件戳、等级及消息显示准确，并重置筛选条件 | I8: 1、管理权限登录AcuHMI网页 | J8: 1.Maintence->Event设置间隔时间为1周，日志等级为Info 2.点击Search 3.导出日志Export Logs 4.点击Reset | K8: 1.设置成功 2.日志显示事件戳、等级及消息显示准确 3.日志导出成功 4.筛选条件被重置 | L8: LV1
A9: Maintenance | B9: Event Log | D9: WEB | E9: FTS_AcuHMI_009_07_case002 | F9: 验证事件日志搜索导出功能 | G9: TestCase_AcuHMI_009_07_case02_2 | H9: 选择间隔时间为1月，日志等级为错误，搜索事件日志并导出，日志显示事件戳、等级及消息显示准确，并重置筛选条件 | I9: 1、管理权限登录AcuHMI网页 | J9: 1.Maintence->Event设置间隔时间为1周，日志等级为Error 2.点击Search 3.导出日志Export Logs 4.点击Reset | K9: 1.设置成功 2.日志显示事件戳、等级及消息显示准确 3.日志导出成功 4.筛选条件被重置 | L9: LV1
A10: Maintenance | B10: Event Log | D10: WEB | E10: FTS_AcuHMI_009_07_case03 | F10: 验证事件日志翻页功能 | G10: TestCase_AcuHMI_009_07_case03 | H10: 选择10个每页，点击下一页，每页显示10条日志，下一页切换成功 | I10: 1、管理权限登录AcuHMI网页 2、已有日志50条 | J10: 1.日志显示设置10/page 2.点击Next切换下一页 3.重复步骤2，切换第5页 4.继续Next | K10: 1.页面显示10条日志 2.跳转到下一页，页面显示10条日志 3.前5页均显示10条日志 4.Next点击无反应或不切换到下一页 | L10: LV1
A11: Maintenance | B11: Event Log | D11: WEB | E11: FTS_AcuHMI_009_07_case03 | F11: 验证事件日志翻页功能 | G11: TestCase_AcuHMI_009_07_case03_01 | H11: 选择20个每页，点击最后一个页码，点击上一页，跳转至最后一页，每页显示20条日志，上一页切换成功 | I11: 1、管理权限登录AcuHMI网页 2、已有日志50条 | J11: 1.日志显示设置20/page 2.点击Next切换下一页 3.重复步骤2，切换第3页 4.继续Next | K11: 1.页面显示20条日志 2.跳转到下一页，页面显示20条日志 3.前2页均显示20条日志，第三页显示10条日志 4.Next点击无反应或不切换到下一页 | L11: LV1
A12: Maintenance | B12: Event Log | D12: WEB | E12: FTS_AcuHMI_009_07_case03 | F12: 验证事件日志翻页功能 | G12: TestCase_AcuHMI_009_07_case03_02 | H12: 选择40个每页，点击最后一个页码，再点击第一个页码，点击下一页，跳转至最后一页，跳转至第一页，每页显示40条日志，下一页切换成功 | I12: 1、管理权限登录AcuHMI网页 2、已有日志100条 | J12: 1.日志显示设置40/page 2.点击Next切换下一页 | K12: 1.页面显示40条日志 2.跳转到下一页，页面显示40条日志 | L12: LV1
A13: Maintenance | B13: Event Log | D13: WEB | E13: FTS_AcuHMI_009_07_case03 | F13: 验证事件日志翻页功能 | G13: TestCase_AcuHMI_009_07_case03_03 | H13: 选择80个每页，点击下一页，每页显示80条日志，下一页切换成功 | I13: 1、管理权限登录AcuHMI网页 2、已有日志100条 | J13: 1.日志显示设置80/page 2.点击Next切换下一页 | K13: 1.页面显示80条日志 2.跳转到下一页，页面显示20条日志 | L13: LV1
... A15: Modbus协议 | B15: modbus配置验证 | D15: WEB | E15: FTS_AcuHMI_008_02_case03 | F15: 验证modbus data mapping配置功能 | G15: TestCase_AcuHMI_008_02_case03_01 | H15: 配置modbus port为2000、5999，slave id为已存在设备slaveid，保存配置成功 | I15: 1、管理权限登录AcuHMI网页 | J15: 1.Protocols->Modbus Config： -Modbus Port：2000 -Slave ID：Modbus ID 2.Save保存配置 3.3.设置端口为5999，重复步骤1-2 | K15: 2.配置保存成功，tips提示数据类型、寄存器数量、数据长度、大小端准确 3.同上 | L15: LV2
A16: Modbus协议 | B16: modbus配置验证 | D16: WEB | F16: 验证modbus启用以及禁用功能 | G16: TestCase_AcuHMI_008_02_case01 | H16: 验证modbus启用以及禁用功能 | I16: 1、管理权限登录ARM-XXL网页 | J16: 1.Protocols->Modbus Config： 2.默认关闭，使用Modbus poll连接，查看是否可以连接设备 3.点击enable,显示sliaveid 4.点击保存，使用Modbus poll连接，查看是否可以连接设备 | K16: 2.使用Modbus poll连接，查看不可以连接设备 4.提示保存成功，Modbus Port、 ID为默认值不可修改，使用工具可以正常连接 | L16: LV1
A17: Modbus协议 | B17: modbus配置验证 | D17: WEB | E17: FTS_AcuHMI_008_02_case03 | F17: 验证modbus data mapping配置功能 | G17: TestCase_AcuHMI_008_02_case02 | H17: 配置modbus port为公共端口，slave id为已存在设备slaveid，保存配置成功，tips提示数据类型、寄存器数量、数据长度、大小端准确 | I17: 1、管理权限登录AcuHMI网页 | J17: 1.Protocols->Modbus Config： -Modbus Port：502 -Slave ID：Modbus ID 2.Save保存配置 | K17: 2.配置保存成功，tips提示数据类型、寄存器数量、数据长度、大小端准确 | L17: LV1
A18: Modbus协议 | B18: modbus配置验证 | D18: WEB | E18: FTS_AcuHMI_008_02_case03 | F18: 验证modbus data mapping配置功能 | G18: TestCase_AcuHMI_008_02_case03 | H18: 配置modbus port为1999、6000，slave id为已存在设备slaveid，保存配置失败，系统提示错误信息准确 | I18: 1、管理权限登录AcuHMI网页 | J18: 1.Protocols->Modbus Config： -Modbus Port：1999 -Slave ID：Modbus ID 2.Save保存配置 3.3.设置端口为6000，重复步骤1-2 | K18: 3保存配置失败，系统提示错误信息准确 | L18: LV1
A19: Modbus协议 | B19: Parameter Mapping | D19: WEB | E19: FTS_AcuHMI_008_02_case04 | F19: 验证modbus data mapping开启功能 | G19: TestCase_AcuHMI_008_02_case04 | H19: 选择需要开启modbus data mapping功能的设备，保存配置成功 | I19: 1、管理权限登录AcuHMI网页 2、已添加设备 | J19: 1.Protocols->Device Config从设备列表中选择需要上传的设备，勾选Enable 2.Save保存配置 3.查看Protocols->Parameters Mapping页面 | K19: 1.设置成功 2.提示：Device configuration saved. 3.Device Name下拉框可以看到需要上传的设备，并显示正确的数据 | L19: LV1
A20: Modbus协议 | B20: Parameter Mapping | D20: WEB | E20: FTS_AcuHMI_008_02_case05 | F20: 验证modbus data mapping 选择数据上传功能 | G20: TestCase_AcuHMI_008_02_case05 | H20: 验证modbus data mapping 选择数据上传功能 | I20: 1、管理权限登录AcuHMI网页 2、modbus主从站配置完成 | J20: 1.Protocols->Device Config从设备列表中选择需要上传的设备，勾选Enable 2.Save保存配置 3.查看Protocols->Parameters Mapping页面 4.选择对应设备，并勾选全部Parameters，点击Save | K20: 1.设置成功 2.提示：Device configuration saved. 3.Device Name下拉框可以看到需要上传的设备，并显示正确的数据 4.modbus主站收到从站上传的数据，并显示准确 | L20: LV1
A21: Modbus协议 | B21: Parameter Mapping | D21: WEB | E21: FTS_AcuHMI_008_02_case06 | F21: 验证modbus data mapping 取消数据上传功能 | G21: TestCase_AcuHMI_008_02_case05 | H21: 验证modbus data mapping 取消数据上传功能 | I21: 1、管理权限登录AcuHMI网页 2、modbus主从站配置完成 | J21: 1.Protocols->Device Config从设备列表中选择需要上传的设备，勾选Enable 2.Save保存配置 3.查看Protocols->Parameters Mapping页面 4.选择对应设备，勾选全部Parameters，点击Save 5.选择对应设备，去勾选全部Parameters，点击Save | K21: 1.设置成功 2.提示：Device configuration saved. 3.Device Name下拉框可以看到需要上传的设备，并显示正确的数据 4.modbus主站收到从站上传的数据，并显示准确 5.数据上传失败，主站无法看到设备相关参数 | L21: LV1
A22: Modbus协议 | B22: Parameter Mapping | D22: WEB | E22: FTS_AcuHMI_008_02_case08 | F22: 验证modbus data mapping 切换设备数据上传功能 | G22: TestCase_AcuHMI_008_02_case06 | H22: 验证modbus data mapping 增加减少设备数据上传功能 | I22: 1、管理权限登录AcuHMI网页 2、modbus主从站配置完成 3、已添加多个设备 | J22: 1.Protocols->Device Config从设备列表中选择需要上传的设备，勾选Enable 2.Save保存配置 3.查看Protocols->Parameters Mapping页面 4.选择设备1，勾选全部Parameters，点击Save 5.选择设备1，去勾选任意部分Parameters，点击Save 6.选择设备1，勾选任意Parameters，点击Save | K22: 1.设置成功 2.提示：Device configuration saved. 3.Device Name下拉框可以看到需要上传的设备，并显示正确的数据 4.modbus主站显示全部数据，并显示准确 5.modbus主站显示选中的部分数据，并显示准确 6.modbus主站显示选中的部分数据，并显示准确 | L22: LV1
A23: Modbus协议 | B23: Parameter Mapping | D23: WEB | E23: FTS_AcuHMI_008_02_case07 | F23: 验证modbus data mapping 切换设备数据上传功能 | G23: TestCase_AcuHMI_008_02_case07 | H23: 验证modbus data mapping 切换设备数据上传功能 | I23: 1、管理权限登录AcuHMI网页 2、modbus主从站配置完成 3、已添加多个设备 | J23: 1.Protocols->Device Config从设备列表中选择需要上传的设备，勾选Enable 2.Save保存配置 3.查看Protocols->Parameters Mapping页面 4.选择设备1，勾选全部Parameters，点击Save 5.重复步骤4，切换到其它设备 | K23: 1.设置成功 2.提示：Device configuration saved. 3.Device Name下拉框可以看到需要上传的设备，并显示正确的数据 4.modbus主站收到从站上传的设备1的数据，并显示准确 5.modbus主站收到从站上传的其他设备数据，并显示准确 | L23: LV1
A24: Modbus协议 | B24: Parameter Mapping | D24: WEB | F24: 验证Modbus Data Mapping验证10分钟无请求处理，终止响应 | G24: TestCase_ARM-XXL_001_01_case1_08 | H24: 验证Modbus Data Mapping验证10分钟无请求处理，终止响应 | I24: 1、管理权限登录ARM-XXL网页 2、modbus主从站配置完成 3、已添加多个设备 | J24: 1.Protocols->params mapping下依次选择MMA_20~MMA_24 2.使用Modbus Poll工具获取映射参数 3.页面无操作10分钟，查看工具是否仍然可以获取到数据 4.并且使用抓包软件查看数据包，wrikshark | K24: 2、工具可以正常获取到设备参数 3.工具断链，无法获取到设备参数 | L24: LV3
A25: Modbus协议 | B25: Device Mirror | F25: FTS_ACUREV4100WEB2_DM_001_001 | G25: Device Mirror 页面入口与模块列表展示 | H25: TestCase_ACUREV4100WEB2_DM_001_001 | I25: Device Mirror 页面入口与模块列表展示 | J25: 1.设备已正常上电，相关服务正常启动 2.AcuRev4100WEB2已下挂4100设备 | K25: 1. 进入通信协议 -> Device Mirror 配置页面 | L25: 1. 页面正常加载，展示 Basic Module 1、Measurement Module 1/2/3、WEB Module 共 5 个模块的 Slave ID 映射列表，列表内容完整
A26: Modbus协议 | B26: Device Mirror | F26: FTS_ACUREV4100WEB2_DM_001_002 | G26: Slave ID 字段预定义不可编辑 | H26: TestCase_ACUREV4100WEB2_DM_001_002 | I26: Slave ID 字段预定义不可编辑 | J26: 1.设备已正常上电，相关服务正常启动 2.AcuRev4100WEB2已下挂4100设备 | K26: 1. 进入 Device Mirror 配置页面 2. 尝试点击或修改任意模块的 Slave ID 字段 | L26: 2. 所有 Slave ID 字段均不可编辑，无输入框或编辑按钮，用户无法修改任何预定义配置
A27: Modbus协议 | B27: Device Mirror | F27: FTS_ACUREV4100WEB2_DM_002_001 | G27: 设备通信参数映射与 Passthrough Slave ID 一致 | H27: TestCase_ACUREV4100WEB2_DM_002_001 | I27: 设备通信参数映射与 Passthrough Slave ID 一致 | J27: 1.设备已正常上电，相关服务正常启动 2.AcuRev4100WEB2已下挂4100设备 | K27: 1. 进入 Device Mirror 配置页面 2. 查看 Basic Module 1 的参数映射 Slave ID 和 Passthrough Slave ID 3. 分别查看 Measurement Module 1、2、3 的参数映射 Slave ID 和 Passthrough Slave ID 4. 查看 WEB Module 的参数映射 Slave ID 和 Passthrough Slave ID | L27: 2. 参数映射 Slave ID = 102，Passthrough Slave ID = 102，与规格定义一致 3. Measurement Module 1/2/3 参数映射 Slave ID 分别为 103/104/105，Passthrough Slave ID 与参数映射 Slave ID 一致，均与规格定义一致 4. 参数映射 Slave ID = 106，Passthrough Slave ID 显示为 -（无），与规格定义一致
A28: Modbus协议 | B28: Device Mirror | F28: FTS_ACUREV4100WEB2_DM_003_001 | G28: Basic Parameter 全集映射与 1s 采集周期 | H28: TestCase_ACUREV4100WEB2_DM_003_001 | I28: Basic Parameter 全集映射与 1s 采集周期 | J28: 1.设备已正常上电，相关服务正常启动 2.AcuRev4100WEB2已下挂4100设备 | K28: 1. 使用 Modbus 客户端通过参数映射 Slave ID 读取 AcuRev-4100 Basic Parameter 数据 2. 连续读取，观察数据更新频率 | L28: 1. 返回数据覆盖 Basic Parameter 全集参数，无缺失，且参数值和采集的值一致 2. 数据约每 1s 刷新一次，与规格采集周期一致
A29: Modbus协议 | B29: Device Mirror | F29: FTS_ACUREV4100WEB2_DM_003_002 | G29: Demand 全集映射与 1 分钟采集周期 | H29: TestCase_ACUREV4100WEB2_DM_003_002 | I29: Demand 全集映射与 1 分钟采集周期 | J29: 1.设备已正常上电，相关服务正常启动 2.AcuRev4100WEB2已下挂4100设备 | K29: 1. 使用 Modbus 客户端通过参数映射 Slave ID 读取 AcuRev-4100 Demand 数据 2. 等待超过 1 分钟，观察数据更新 | L29: 1. 返回数据覆盖 Demand 全集参数，无缺失，且参数值和采集的值一致 2. 数据约每 1 分钟更新一次，与规格采集周期一致
A30: Modbus协议 | B30: Device Mirror | F30: FTS_ACUREV4100WEB2_DM_003_003 | G30: Power Quality 全集映射与 3s 采集周期 | H30: TestCase_ACUREV4100WEB2_DM_003_003 | I30: Power Quality 全集映射与 3s 采集周期 | J30: 1.设备已正常上电，相关服务正常启动 2.AcuRev4100WEB2已下挂4100设备 | K30: 1. 使用 Modbus 客户端通过参数映射 Slave ID 读取 Power Quality 数据（THD、Sequence and Unbalance） 2. 连续读取，观察数据更新频率 | L30: 1. 返回数据覆盖 THD、Sequence and Unbalance 全集参数 2. 数据约每 3s 刷新一次，与规格采集周期一致
A31: Modbus协议 | B31: Device Mirror | F31: FTS_ACUREV4100WEB2_DM_003_004 | G31: Energy 全集映射与 3s 采集周期 | H31: TestCase_ACUREV4100WEB2_DM_003_004 | I31: Energy 全集映射与 3s 采集周期 | J31: 1.设备已正常上电，相关服务正常启动 2.AcuRev4100WEB2已下挂4100设备 | K31: 1. 使用 Modbus 客户端通过参数映射 Slave ID 读取 AcuRev-4100 Energy 数据 2. 连续读取，观察数据更新频率 | L31: 1. 返回数据覆盖 Energy 全集参数 2. 数据约每 3s 刷新一次，与规格采集周期一致
A32: Modbus协议 | B32: Device Mirror | F32: FTS_ACUREV4100WEB2_DM_003_005 | G32: IO 全集映射与 1s 采集周期 | H32: TestCase_ACUREV4100WEB2_DM_003_005 | I32: IO 全集映射与 1s 采集周期 | J32: 1.设备已正常上电，相关服务正常启动 2.AcuRev4100WEB2已下挂4100设备 | K32: 1. 使用 Modbus 客户端通过参数映射 Slave ID 读取 IO 数据 2. 连续读取，观察数据更新频率 | L32: 1. 返回数据覆盖 DI status、DI counter、RO Status、DO status 全集参数 2. 数据约每 1s 刷新一次，与规格采集周期一致
A33: Modbus协议 | B33: Device Mirror | F33: FTS_ACUREV4100WEB2_DM_004_001 | G33: Slave ID 106 读取 WEB2 设备基本信息只读且一致 | H33: TestCase_ACUREV4100WEB2_DM_004_001 | I33: Slave ID 106 读取 WEB2 设备基本信息只读且一致 | J33: 1.设备已正常上电，相关服务正常启动 2.AcuRev4100WEB2已下挂4100设备 | K33: 1. 使用 Modbus 客户端通过 Slave ID 106 读取 WEB2 设备基本信息，和WEB页面实际设备基本信息对比，检查是否一致 2. 对比页面展示值与读取值 3. 尝试通过 Modbus 写操作修改任意字段 | L33: 1. 返回 Model/Serial Number/Hardware Version/Firmware Version/Last Updated/Ethernet MAC/WiFi MAC 共 7 个字段，且各字段值与设备的实际信息一致。 2. 字段为只读，写操作被拒绝或无效
A34: Modbus协议 | B34: Device Mirror | F34: FTS_ACUREV4100WEB2_DM_004_002 | G34: Slave ID 106 读取 WEB2 Ethernet/WIFI网络参数一致 | H34: TestCase_ACUREV4100WEB2_DM_004_002 | I34: Slave ID 106 读取 WEB2 Ethernet/WIFI网络参数一致 | J34: 1.设备已正常上电，相关服务正常启动 2.AcuRev4100WEB2已下挂4100设备 | K34: 1. 使用 Modbus 客户端通过 Slave ID 106 读取 WEB2 Ethernet 网络参数，对比设备当前网络配置页面的值 2. 使用 Modbus 客户端通过 Slave ID 106 读取 WEB2 WiFi IP Address，对比设备当前 WiFi 配置页面的值 | L34: 1. 返回 DHCP Enable/IP Address/Subnet Mask/Gateway/DNS1/DNS2 共 6 个字段，且与设备当前 Ethernet 配置一致 2. 读取到的 WiFi IP Address 与设备当前 WiFi 配置一致
A35: Modbus协议 | B35: Device Mirror | F35: FTS_ACUREV4100WEB2_DM_005_001 | G35: Passthrough Slave ID 102 透传 Basic Module 1 数据与直连一致 | H35: TestCase_ACUREV4100WEB2_DM_005_001 | I35: Passthrough Slave ID 102 透传 Basic Module 1 数据与直连一致 | J35: 1.设备已正常上电，相关服务正常启动 2.AcuRev4100WEB2已下挂4100设备 | K35: 1. 使用 Modbus 客户端通过 Passthrough Slave ID 102 读取 Basic Module 1 原始寄存器数据 2. 直连 AcuRev-4100 读取相同寄存器数据 3. 对比两组数据 | L35: 3. 通过 Passthrough Slave ID 102 读取的数据与直连 AcuRev-4100 读取结果一致
A36: Modbus协议 | B36: Device Mirror | F36: FTS_ACUREV4100WEB2_DM_005_002 | G36: Passthrough Slave ID 103/104/105 透传 Measurement Module 1/2/3 数据一致 | H36: TestCase_ACUREV4100WEB2_DM_005_002 | I36: Passthrough Slave ID 103/104/105 透传 Measurement Module 1/2/3 数据一致 | J36: 1.设备已正常上电，相关服务正常启动 2.AcuRev4100WEB2已下挂4100设备 | K36: 1. 分别使用 Passthrough Slave ID 103/104/105 读取 Measurement Module 1/2/3 原始寄存器数据 2. 分别直连对应 AcuRev-4100 读取相同寄存器数据 3. 对比三组数据 | L36: 3. 三个 Measurement Module 通过 Passthrough Slave ID 读取的数据均与直连 AcuRev-4100 读取结果一致
... A40: Modbus协议 | B40: Device Mirror | F40: FTS_ACUREV4100WEB2_DM_006_003 | G40: WEB2 重启后 Device Mirror 自动恢复 | H40: TestCase_ACUREV4100WEB2_DM_006_004 | I40: WEB2 重启后 Device Mirror 自动恢复 | J40: 1.设备已正常上电，相关服务正常启动 2.AcuRev4100WEB2已下挂4100设备 | K40: 1. WEB2 设备正常运行，Device Mirror 功能可访问 2. 重启 WEB2 设备 3. 重启完成后通过各 Slave ID 读取数据 | L40: 3. Device Mirror 功能自动恢复，5 个模块 Slave ID 映射恢复正常，第三方客户端可继续正常访问
A41: UI界面测试 | B41: UI界面测试 | D41: ALL | E41: FTS_AcuHMI_010_07_case01 | F41: 烧录升级时，查看开机界面logo是否为Accuenergy | G41: TestCase_AcuHMI_010_07_case01 | H41: 烧录升级时，查看开机界面logo是否为Accuenergy | I41: 1、管理权限登录AcuHMI网页 2、本地有可用的新固件版本 | J41: 1、手动选择新固件，更新固件 2、查看开机界面 3、查看页面logo | K41: 1.升级成功 2.开机动画logo为Accuenergy 3.页面显示logo为Accuenergy | L41: LV0
A42: UI界面测试 | B42: UI界面测试 | D42: ALL | E42: FTS_AcuHMI_010_07_case02 | F42: 网页升级时，查看开机界面logo是否为Accuenergy | G42: TestCase_AcuHMI_010_07_case02 | H42: 手动选择新固件，进行固件更新 | I42: 1、管理权限登录AcuHMI网页 2、本地有可用的新固件版本 | J42: 1.Firmware Update->Manual Update Firmware Update File选择Browse上传升级文件 2.选择Upload 3.查看开机动画 4.查看页面logo | K42: 2.升级成功 3.开机动画logo为Accuenergy 4.页面显示logo为Accuenergy | L42: LV1
A43: UI界面测试 | B43: UI界面测试 | D43: ALL | E43: FTS_AcuHMI_010_07_case03 | F43: 验证多次手动更新固件功能，查看开机界面logo是否为Accuenergy | G43: TestCase_AcuHMI_010_07_case03 | H43: 连续10次手动选择新固件，进行固件更新 | I43: 1、服务启动正常，账号登录成功 | J43: 1、手动选择新固件，更新固件 2、重复步骤1，9次 | K43: 1.升级成功 2.开机动画logo为Accuenergy 注：PX-EMD-G项目显示Eaton信息 | L43: LV2
A44: UI界面测试 | B44: UI界面测试 | D44: ALL | E44: FTS_AcuHMI_010_07_case04 | F44: 验证文案修改后是否可以正常显示，链接可以正常跳转 | G44: TestCase_AcuHMI_010_07_case04 | H44: 页脚文本显示新增1-877-721-8908，marketing@accuenergy.com，Accuenergy Inc.，440 Comstock Road，Toronto, ON M1L 2H6, Canada以及增加公司网址、点击是否可以正常跳转，显示收件人是否为marketing@accuenergy.com邮箱地址 | I44: 1、管理权限登录AcuHMI网页 | J44: 1.点击查看所有的页面是否页脚都显示完整1-877-721-8908，marketing@accuenergy.com，Accuenergy Inc.，440 Comstock Road，Toronto, ON M1L 2H6, Canada以及增加公司网址、邮箱 2.点击网址www.accuenergy.com可以正常跳转到网页 3.点击邮箱marketing@accuenergy.com打开邮箱弹窗,显示收件人为marketing@accuenergy.com 4.邮箱弹框选择不同的邮箱，,显示收件人为marketing@accuenergy.com | K44: 1.页脚信息显示完整 2.打开公司网址 3.正常跳转邮箱,显示收件人为marketing@accuenergy.com 4.正常跳转邮箱，,显示收件人为marketing@accuenergy.com | L44: LV0
...
