Workbook

Sheet 用例统计
A1: TR编号(模块) | B1: TR名称(模块) | C1: 用例总数 | D1: LV0 | E1: LV1 | F1: LV2 | G1: LV3 | H1: LV4 | I1: 需自动化 | J1: 完成自动化 | K1: LV0（10%） | L1: LV1(15%) | M1: LV2（40%） | N1: LV3(25%) | O1: LV4（10%） | P1: 自动化率 | Q1: 备注 | R1: 自动化实现人
A2: TR_AcuRev1320_001 | B2: 交流频率 | C2: =COUNTIFS(用例执行情况!C:C,"*1320_001*") -> 5 | D2: =COUNTIFS(用例执行情况!C:C,"*1320_001*",用例执行情况!H:H,"LV0") -> 1 | E2: =COUNTIFS(用例执行情况!C:C,"*1320_001*",用例执行情况!H:H,"LV1") -> 2 | F2: =COUNTIFS(用例执行情况!C:C,"*1320_001*",用例执行情况!H:H,"LV2") -> 1 | G2: =COUNTIFS(用例执行情况!C:C,"*1320_001*",用例执行情况!H:H,"LV3") -> 1 | H2: =COUNTIFS(用例执行情况!C:C,"*1320_001*",用例执行情况!H:H,"LV4") -> 0 | I2: =COUNTIFS(用例执行情况!C:C,"*1320_001*",用例执行情况!J:J,"是") -> 0 | J2: =COUNTIFS(用例执行情况!C:C,"*1320_001*",用例执行情况!I:I,"是") -> 3 | K2: =D2/C2 -> 0.2 | L2: =E2/C2 -> 0.4 | M2: =F2/C2 -> 0.2 | N2: =G2/C2 -> 0.2 | O2: =H2/C2 -> 0 | P2: =J2/C2 -> 0.6 | Q2: 1320 Sprint1
A3: TR_AcuRev1320_002 | B3: 交流电压 | C3: =COUNTIFS(用例执行情况!C:C,"*1320_002*") -> 24 | D3: =COUNTIFS(用例执行情况!C:C,"*1320_002*",用例执行情况!H:H,"LV0") -> 2 | E3: =COUNTIFS(用例执行情况!C:C,"*1320_002*",用例执行情况!H:H,"LV1") -> 3 | F3: =COUNTIFS(用例执行情况!C:C,"*1320_002*",用例执行情况!H:H,"LV2") -> 11 | G3: =COUNTIFS(用例执行情况!C:C,"*1320_002*",用例执行情况!H:H,"LV3") -> 6 | H3: =COUNTIFS(用例执行情况!C:C,"*1320_002*",用例执行情况!H:H,"LV4") -> 2 | I3: =COUNTIFS(用例执行情况!C:C,"*1320_002*",用例执行情况!J:J,"是") -> 0 | J3: =COUNTIFS(用例执行情况!C:C,"*1320_002*",用例执行情况!I:I,"是") -> 13 | K3: =D3/C3 -> 0.083333333 | L3: =E3/C3 -> 0.125 | M3: =F3/C3 -> 0.45833333 | N3: =G3/C3 -> 0.25 | O3: =H3/C3 -> 0.083333333 | P3: =J3/C3 -> 0.54166667 | Q3: 1320 Sprint1
A4: TR_AcuRev1320_003 | B4: 交流电流 | C4: =COUNTIFS(用例执行情况!C:C,"*1320_003*") -> 33 | D4: =COUNTIFS(用例执行情况!C:C,"*1320_003*",用例执行情况!H:H,"LV0") -> 4 | E4: =COUNTIFS(用例执行情况!C:C,"*1320_003*",用例执行情况!H:H,"LV1") -> 13 | F4: =COUNTIFS(用例执行情况!C:C,"*1320_003*",用例执行情况!H:H,"LV2") -> 14 | G4: =COUNTIFS(用例执行情况!C:C,"*1320_003*",用例执行情况!H:H,"LV3") -> 1 | H4: =COUNTIFS(用例执行情况!C:C,"*1320_003*",用例执行情况!H:H,"LV4") -> 1 | I4: =COUNTIFS(用例执行情况!C:C,"*1320_003*",用例执行情况!J:J,"是") -> 0 | J4: =COUNTIFS(用例执行情况!C:C,"*1320_003*",用例执行情况!I:I,"是") -> 11 | K4: =D4/C4 -> 0.12121212 | L4: =E4/C4 -> 0.39393939 | M4: =F4/C4 -> 0.42424242 | N4: =G4/C4 -> 0.03030303 | O4: =H4/C4 -> 0.03030303 | P4: =J4/C4 -> 0.33333333 | Q4: 1320 Sprint1
A5: TR_AcuRev1320_004 | B5: 交流功率 | C5: =COUNTIFS(用例执行情况!C:C,"*1320_004*") -> 25 | D5: =COUNTIFS(用例执行情况!C:C,"*1320_004*",用例执行情况!H:H,"LV0") -> 3 | E5: =COUNTIFS(用例执行情况!C:C,"*1320_004*",用例执行情况!H:H,"LV1") -> 5 | F5: =COUNTIFS(用例执行情况!C:C,"*1320_004*",用例执行情况!H:H,"LV2") -> 12 | G5: =COUNTIFS(用例执行情况!C:C,"*1320_004*",用例执行情况!H:H,"LV3") -> 4 | H5: =COUNTIFS(用例执行情况!C:C,"*1320_004*",用例执行情况!H:H,"LV4") -> 1 | I5: =COUNTIFS(用例执行情况!C:C,"*1320_004*",用例执行情况!J:J,"是") -> 0 | J5: =COUNTIFS(用例执行情况!C:C,"*1320_004*",用例执行情况!I:I,"是") -> 15 | K5: =D5/C5 -> 0.12 | L5: =E5/C5 -> 0.2 | M5: =F5/C5 -> 0.48 | N5: =G5/C5 -> 0.16 | O5: =H5/C5 -> 0.04 | P5: =J5/C5 -> 0.6 | Q5: 1320 Sprint1
A6: TR_AcuRev1320_005 | B6: 负载特性(RLC) | C6: =COUNTIFS(用例执行情况!C:C,"*1320_005*") -> 21 | D6: =COUNTIFS(用例执行情况!C:C,"*1320_005*",用例执行情况!H:H,"LV0") -> 2 | E6: =COUNTIFS(用例执行情况!C:C,"*1320_005*",用例执行情况!H:H,"LV1") -> 6 | F6: =COUNTIFS(用例执行情况!C:C,"*1320_005*",用例执行情况!H:H,"LV2") -> 9 | G6: =COUNTIFS(用例执行情况!C:C,"*1320_005*",用例执行情况!H:H,"LV3") -> 4 | H6: =COUNTIFS(用例执行情况!C:C,"*1320_005*",用例执行情况!H:H,"LV4") -> 0 | I6: =COUNTIFS(用例执行情况!C:C,"*1320_005*",用例执行情况!J:J,"是") -> 0 | J6: =COUNTIFS(用例执行情况!C:C,"*1320_005*",用例执行情况!I:I,"是") -> 11 | K6: =D6/C6 -> 0.095238095 | L6: =E6/C6 -> 0.28571429 | M6: =F6/C6 -> 0.42857143 | N6: =G6/C6 -> 0.19047619 | O6: =H6/C6 -> 0 | P6: =J6/C6 -> 0.52380952 | Q6: 1320 Sprint1
A7: TR_AcuRev1320_006 | B7: 相角(phase angle) | C7: =COUNTIFS(用例执行情况!C:C,"*1320_006*") -> 14 | D7: =COUNTIFS(用例执行情况!C:C,"*1320_006*",用例执行情况!H:H,"LV0") -> 3 | E7: =COUNTIFS(用例执行情况!C:C,"*1320_006*",用例执行情况!H:H,"LV1") -> 2 | F7: =COUNTIFS(用例执行情况!C:C,"*1320_006*",用例执行情况!H:H,"LV2") -> 9 | G7: =COUNTIFS(用例执行情况!C:C,"*1320_006*",用例执行情况!H:H,"LV3") -> 0 | H7: =COUNTIFS(用例执行情况!C:C,"*1320_006*",用例执行情况!H:H,"LV4") -> 0 | I7: =COUNTIFS(用例执行情况!C:C,"*1320_006*",用例执行情况!J:J,"是") -> 0 | J7: =COUNTIFS(用例执行情况!C:C,"*1320_006*",用例执行情况!I:I,"是") -> 4 | K7: =D7/C7 -> 0.21428571 | L7: =E7/C7 -> 0.14285714 | M7: =F7/C7 -> 0.64285714 | N7: =G7/C7 -> 0 | O7: =H7/C7 -> 0 | P7: =J7/C7 -> 0.28571429 | Q7: 1320 Sprint1
A8: TR_AcuRev1320_007 | B8: 各次谐波 | C8: =COUNTIFS(用例执行情况!C:C,"*1320_007*") -> 34 | D8: =COUNTIFS(用例执行情况!C:C,"*1320_007*",用例执行情况!H:H,"LV0") -> 3 | E8: =COUNTIFS(用例执行情况!C:C,"*1320_007*",用例执行情况!H:H,"LV1") -> 6 | F8: =COUNTIFS(用例执行情况!C:C,"*1320_007*",用例执行情况!H:H,"LV2") -> 16 | G8: =COUNTIFS(用例执行情况!C:C,"*1320_007*",用例执行情况!H:H,"LV3") -> 7 | H8: =COUNTIFS(用例执行情况!C:C,"*1320_007*",用例执行情况!H:H,"LV4") -> 2 | I8: =COUNTIFS(用例执行情况!C:C,"*1320_007*",用例执行情况!J:J,"是") -> 0 | J8: =COUNTIFS(用例执行情况!C:C,"*1320_007*",用例执行情况!I:I,"是") -> 0 | K8: =D8/C8 -> 0.088235294 | L8: =E8/C8 -> 0.17647059 | M8: =F8/C8 -> 0.47058824 | N8: =G8/C8 -> 0.20588235 | O8: =H8/C8 -> 0.058823529 | P8: =J8/C8 -> 0 | Q8: 1320 Sprint1
A9: TR_AcuRev1320_008 | B9: 谐波因数 | C9: =COUNTIFS(用例执行情况!C:C,"*1320_008*") -> 10 | D9: =COUNTIFS(用例执行情况!C:C,"*1320_008*",用例执行情况!H:H,"LV0") -> 1 | E9: =COUNTIFS(用例执行情况!C:C,"*1320_008*",用例执行情况!H:H,"LV1") -> 2 | F9: =COUNTIFS(用例执行情况!C:C,"*1320_008*",用例执行情况!H:H,"LV2") -> 4 | G9: =COUNTIFS(用例执行情况!C:C,"*1320_008*",用例执行情况!H:H,"LV3") -> 1 | H9: =COUNTIFS(用例执行情况!C:C,"*1320_008*",用例执行情况!H:H,"LV4") -> 2 | I9: =COUNTIFS(用例执行情况!C:C,"*1320_008*",用例执行情况!J:J,"是") -> 0 | J9: =COUNTIFS(用例执行情况!C:C,"*1320_008*",用例执行情况!I:I,"是") -> 0 | K9: =D9/C9 -> 0.1 | L9: =E9/C9 -> 0.2 | M9: =F9/C9 -> 0.4 | N9: =G9/C9 -> 0.1 | O9: =H9/C9 -> 0.2 | P9: =J9/C9 -> 0 | Q9: 1320 Sprint1
A10: TR_AcuRev1320_009 | B10: 电能质量测量 | C10: =COUNTIFS(用例执行情况!C:C,"*1320_009*") -> 54 | D10: =COUNTIFS(用例执行情况!C:C,"*1320_009*",用例执行情况!H:H,"LV0") -> 6 | E10: =COUNTIFS(用例执行情况!C:C,"*1320_009*",用例执行情况!H:H,"LV1") -> 16 | F10: =COUNTIFS(用例执行情况!C:C,"*1320_009*",用例执行情况!H:H,"LV2") -> 21 | G10: =COUNTIFS(用例执行情况!C:C,"*1320_009*",用例执行情况!H:H,"LV3") -> 8 | H10: =COUNTIFS(用例执行情况!C:C,"*1320_009*",用例执行情况!H:H,"LV4") -> 3 | I10: =COUNTIFS(用例执行情况!C:C,"*1320_009*",用例执行情况!J:J,"是") -> 0 | J10: =COUNTIFS(用例执行情况!C:C,"*1320_009*",用例执行情况!I:I,"是") -> 41 | K10: =D10/C10 -> 0.11111111 | L10: =E10/C10 -> 0.2962963 | M10: =F10/C10 -> 0.38888889 | N10: =G10/C10 -> 0.14814815 | O10: =H10/C10 -> 0.055555556 | P10: =J10/C10 -> 0.75925926 | Q10: 1320 Sprint1 | R10: 丛松
A11: TR_AcuRev1320_010 | B11: 电能测量 | C11: =COUNTIFS(用例执行情况!C:C,"*1320_010*") -> 101 | D11: =COUNTIFS(用例执行情况!C:C,"*1320_010*",用例执行情况!H:H,"LV0") -> 8 | E11: =COUNTIFS(用例执行情况!C:C,"*1320_010*",用例执行情况!H:H,"LV1") -> 18 | F11: =COUNTIFS(用例执行情况!C:C,"*1320_010*",用例执行情况!H:H,"LV2") -> 46 | G11: =COUNTIFS(用例执行情况!C:C,"*1320_010*",用例执行情况!H:H,"LV3") -> 21 | H11: =COUNTIFS(用例执行情况!C:C,"*1320_010*",用例执行情况!H:H,"LV4") -> 8 | I11: =COUNTIFS(用例执行情况!C:C,"*1320_010*",用例执行情况!J:J,"是") -> 0 | J11: =COUNTIFS(用例执行情况!C:C,"*1320_010*",用例执行情况!I:I,"是") -> 57 | K11: =D11/C11 -> 0.079207921 | L11: =E11/C11 -> 0.17821782 | M11: =F11/C11 -> 0.45544554 | N11: =G11/C11 -> 0.20792079 | O11: =H11/C11 -> 0.079207921 | P11: =J11/C11 -> 0.56435644 | Q11: 1320 Sprint1
A12: TR_AcuRev1320_011 | B12: 需量测量 | C12: =COUNTIFS(用例执行情况!C:C,"*1320_011*") -> 29 | D12: =COUNTIFS(用例执行情况!C:C,"*1320_011*",用例执行情况!H:H,"LV0") -> 3 | E12: =COUNTIFS(用例执行情况!C:C,"*1320_011*",用例执行情况!H:H,"LV1") -> 2 | F12: =COUNTIFS(用例执行情况!C:C,"*1320_011*",用例执行情况!H:H,"LV2") -> 14 | G12: =COUNTIFS(用例执行情况!C:C,"*1320_011*",用例执行情况!H:H,"LV3") -> 5 | H12: =COUNTIFS(用例执行情况!C:C,"*1320_011*",用例执行情况!H:H,"LV4") -> 5 | I12: =COUNTIFS(用例执行情况!C:C,"*1320_011*",用例执行情况!J:J,"是") -> 0 | J12: =COUNTIFS(用例执行情况!C:C,"*1320_011*",用例执行情况!I:I,"是") -> 0 | K12: =D12/C12 -> 0.10344828 | L12: =E12/C12 -> 0.068965517 | M12: =F12/C12 -> 0.48275862 | N12: =G12/C12 -> 0.17241379 | O12: =H12/C12 -> 0.17241379 | P12: =J12/C12 -> 0 | Q12: 1320 Sprint1 | R12: 王洋&胡赞
A13: TR_AcuRev1320_012 | B13: 接线配置 | C13: =COUNTIFS(用例执行情况!C:C,"*1320_012*") -> 46 | D13: =COUNTIFS(用例执行情况!C:C,"*1320_012*",用例执行情况!H:H,"LV0") -> 4 | E13: =COUNTIFS(用例执行情况!C:C,"*1320_012*",用例执行情况!H:H,"LV1") -> 28 | F13: =COUNTIFS(用例执行情况!C:C,"*1320_012*",用例执行情况!H:H,"LV2") -> 7 | G13: =COUNTIFS(用例执行情况!C:C,"*1320_012*",用例执行情况!H:H,"LV3") -> 3 | H13: =COUNTIFS(用例执行情况!C:C,"*1320_012*",用例执行情况!H:H,"LV4") -> 4 | I13: =COUNTIFS(用例执行情况!C:C,"*1320_012*",用例执行情况!J:J,"是") -> 0 | J13: =COUNTIFS(用例执行情况!C:C,"*1320_012*",用例执行情况!I:I,"是") -> 0 | K13: =D13/C13 -> 0.086956522 | L13: =E13/C13 -> 0.60869565 | M13: =F13/C13 -> 0.15217391 | N13: =G13/C13 -> 0.065217391 | O13: =H13/C13 -> 0.086956522 | P13: =J13/C13 -> 0 | Q13: 1320 Sprint1
A14: TR_AcuRev1320_013 | B14: 时分用电 | C14: =COUNTIFS(用例执行情况!C:C,"*1320_013*") -> 91 | D14: =COUNTIFS(用例执行情况!C:C,"*1320_013*",用例执行情况!H:H,"LV0") -> 6 | E14: =COUNTIFS(用例执行情况!C:C,"*1320_013*",用例执行情况!H:H,"LV1") -> 25 | F14: =COUNTIFS(用例执行情况!C:C,"*1320_013*",用例执行情况!H:H,"LV2") -> 38 | G14: =COUNTIFS(用例执行情况!C:C,"*1320_013*",用例执行情况!H:H,"LV3") -> 18 | H14: =COUNTIFS(用例执行情况!C:C,"*1320_013*",用例执行情况!H:H,"LV4") -> 0 | I14: =COUNTIFS(用例执行情况!C:C,"*1320_013*",用例执行情况!J:J,"是") -> 0 | J14: =COUNTIFS(用例执行情况!C:C,"*1320_013*",用例执行情况!I:I,"是") -> 0 | K14: =D14/C14 -> 0.065934066 | L14: =E14/C14 -> 0.27472527 | M14: =F14/C14 -> 0.41758242 | N14: =G14/C14 -> 0.1978022 | O14: =H14/C14 -> 0 | P14: =J14/C14 -> 0 | Q14: 1320 Sprint1 | R14: 刘丛松
A15: TR_AcuRev1320_014 | B15: 电能质量事件 | C15: =COUNTIFS(用例执行情况!C:C,"*1320_014*") -> 137 | D15: =COUNTIFS(用例执行情况!C:C,"*1320_014*",用例执行情况!H:H,"LV0") -> 14 | E15: =COUNTIFS(用例执行情况!C:C,"*1320_014*",用例执行情况!H:H,"LV1") -> 19 | F15: =COUNTIFS(用例执行情况!C:C,"*1320_014*",用例执行情况!H:H,"LV2") -> 90 | G15: =COUNTIFS(用例执行情况!C:C,"*1320_014*",用例执行情况!H:H,"LV3") -> 11 | H15: =COUNTIFS(用例执行情况!C:C,"*1320_014*",用例执行情况!H:H,"LV4") -> 3 | I15: =COUNTIFS(用例执行情况!C:C,"*1320_014*",用例执行情况!J:J,"是") -> 0 | J15: =COUNTIFS(用例执行情况!C:C,"*1320_014*",用例执行情况!I:I,"是") -> 0 | K15: =D15/C15 -> 0.10218978 | L15: =E15/C15 -> 0.13868613 | M15: =F15/C15 -> 0.65693431 | N15: =G15/C15 -> 0.080291971 | O15: =H15/C15 -> 0.02189781 | P15: =J15/C15 -> 0 | Q15: 1320 Sprint1
A16: TR_AcuRev1320_015 | B16: 告警功能 | C16: =COUNTIFS(用例执行情况!C:C,"*1320_015*") -> 92 | D16: =COUNTIFS(用例执行情况!C:C,"*1320_015*",用例执行情况!H:H,"LV0") -> 5 | E16: =COUNTIFS(用例执行情况!C:C,"*1320_015*",用例执行情况!H:H,"LV1") -> 24 | F16: =COUNTIFS(用例执行情况!C:C,"*1320_015*",用例执行情况!H:H,"LV2") -> 50 | G16: =COUNTIFS(用例执行情况!C:C,"*1320_015*",用例执行情况!H:H,"LV3") -> 13 | H16: =COUNTIFS(用例执行情况!C:C,"*1320_015*",用例执行情况!H:H,"LV4") -> 0 | I16: =COUNTIFS(用例执行情况!C:C,"*1320_015*",用例执行情况!J:J,"是") -> 0 | J16: =COUNTIFS(用例执行情况!C:C,"*1320_015*",用例执行情况!I:I,"是") -> 0 | K16: =D16/C16 -> 0.054347826 | L16: =E16/C16 -> 0.26086957 | M16: =F16/C16 -> 0.54347826 | N16: =G16/C16 -> 0.14130435 | O16: =H16/C16 -> 0 | P16: =J16/C16 -> 0 | Q16: 1320 Sprint1 | R16: 王丽红
A17: TR_AcuRev1320_016 | B17: 记录与统计 | C17: =COUNTIFS(用例执行情况!C:C,"*1320_016*") -> 47 | D17: =COUNTIFS(用例执行情况!C:C,"*1320_016*",用例执行情况!H:H,"LV0") -> 4 | E17: =COUNTIFS(用例执行情况!C:C,"*1320_016*",用例执行情况!H:H,"LV1") -> 10 | F17: =COUNTIFS(用例执行情况!C:C,"*1320_016*",用例执行情况!H:H,"LV2") -> 20 | G17: =COUNTIFS(用例执行情况!C:C,"*1320_016*",用例执行情况!H:H,"LV3") -> 11 | H17: =COUNTIFS(用例执行情况!C:C,"*1320_016*",用例执行情况!H:H,"LV4") -> 2 | I17: =COUNTIFS(用例执行情况!C:C,"*1320_016*",用例执行情况!J:J,"是") -> 0 | J17: =COUNTIFS(用例执行情况!C:C,"*1320_016*",用例执行情况!I:I,"是") -> 0 | K17: =D17/C17 -> 0.085106383 | L17: =E17/C17 -> 0.21276596 | M17: =F17/C17 -> 0.42553191 | N17: =G17/C17 -> 0.23404255 | O17: =H17/C17 -> 0.042553191 | P17: =J17/C17 -> 0 | Q17: 1320 Sprint1
A18: TR_AcuRev1320_017 | B18: DATA Log | C18: =COUNTIFS(用例执行情况!C:C,"*1320_017*") -> 76 | D18: =COUNTIFS(用例执行情况!C:C,"*1320_017*",用例执行情况!H:H,"LV0") -> 4 | E18: =COUNTIFS(用例执行情况!C:C,"*1320_017*",用例执行情况!H:H,"LV1") -> 12 | F18: =COUNTIFS(用例执行情况!C:C,"*1320_017*",用例执行情况!H:H,"LV2") -> 34 | G18: =COUNTIFS(用例执行情况!C:C,"*1320_017*",用例执行情况!H:H,"LV3") -> 17 | H18: =COUNTIFS(用例执行情况!C:C,"*1320_017*",用例执行情况!H:H,"LV4") -> 9 | I18: =COUNTIFS(用例执行情况!C:C,"*1320_017*",用例执行情况!J:J,"是") -> 0 | J18: =COUNTIFS(用例执行情况!C:C,"*1320_017*",用例执行情况!I:I,"是") -> 0 | K18: =D18/C18 -> 0.052631579 | L18: =E18/C18 -> 0.15789474 | M18: =F18/C18 -> 0.44736842 | N18: =G18/C18 -> 0.22368421 | O18: =H18/C18 -> 0.11842105 | P18: =J18/C18 -> 0 | Q18: 1320 Sprint1
A19: TR_AcuRev1320_018 | B19: Input&Output | C19: =COUNTIFS(用例执行情况!C:C,"*1320_018*") -> 58 | D19: =COUNTIFS(用例执行情况!C:C,"*1320_018*",用例执行情况!H:H,"LV0") -> 4 | E19: =COUNTIFS(用例执行情况!C:C,"*1320_018*",用例执行情况!H:H,"LV1") -> 12 | F19: =COUNTIFS(用例执行情况!C:C,"*1320_018*",用例执行情况!H:H,"LV2") -> 26 | G19: =COUNTIFS(用例执行情况!C:C,"*1320_018*",用例执行情况!H:H,"LV3") -> 15 | H19: =COUNTIFS(用例执行情况!C:C,"*1320_018*",用例执行情况!H:H,"LV4") -> 1 | I19: =COUNTIFS(用例执行情况!C:C,"*1320_018*",用例执行情况!J:J,"是") -> 0 | J19: =COUNTIFS(用例执行情况!C:C,"*1320_018*",用例执行情况!I:I,"是") -> 0 | K19: =D19/C19 -> 0.068965517 | L19: =E19/C19 -> 0.20689655 | M19: =F19/C19 -> 0.44827586 | N19: =G19/C19 -> 0.25862069 | O19: =H19/C19 -> 0.017241379 | P19: =J19/C19 -> 0 | Q19: 1320 Sprint1
A20: TR_AcuRev1320_019 | B20: 计时功能 | C20: =COUNTIFS(用例执行情况!C:C,"*1320_019*") -> 28 | D20: =COUNTIFS(用例执行情况!C:C,"*1320_019*",用例执行情况!H:H,"LV0") -> 1 | E20: =COUNTIFS(用例执行情况!C:C,"*1320_019*",用例执行情况!H:H,"LV1") -> 5 | F20: =COUNTIFS(用例执行情况!C:C,"*1320_019*",用例执行情况!H:H,"LV2") -> 14 | G20: =COUNTIFS(用例执行情况!C:C,"*1320_019*",用例执行情况!H:H,"LV3") -> 6 | H20: =COUNTIFS(用例执行情况!C:C,"*1320_019*",用例执行情况!H:H,"LV4") -> 2 | I20: =COUNTIFS(用例执行情况!C:C,"*1320_019*",用例执行情况!J:J,"是") -> 0 | J20: =COUNTIFS(用例执行情况!C:C,"*1320_019*",用例执行情况!I:I,"是") -> 0 | K20: =D20/C20 -> 0.035714286 | L20: =E20/C20 -> 0.17857143 | M20: =F20/C20 -> 0.5 | N20: =G20/C20 -> 0.21428571 | O20: =H20/C20 -> 0.071428571 | P20: =J20/C20 -> 0 | Q20: 1320 Sprint1
A21: TR_AcuRev1320_020 | B21: 数据重置及恢复出厂设置 | C21: =COUNTIFS(用例执行情况!C:C,"*1320_020*") -> 32 | D21: =COUNTIFS(用例执行情况!C:C,"*1320_020*",用例执行情况!H:H,"LV0") -> 2 | E21: =COUNTIFS(用例执行情况!C:C,"*1320_020*",用例执行情况!H:H,"LV1") -> 9 | F21: =COUNTIFS(用例执行情况!C:C,"*1320_020*",用例执行情况!H:H,"LV2") -> 13 | G21: =COUNTIFS(用例执行情况!C:C,"*1320_020*",用例执行情况!H:H,"LV3") -> 5 | H21: =COUNTIFS(用例执行情况!C:C,"*1320_020*",用例执行情况!H:H,"LV4") -> 3 | I21: =COUNTIFS(用例执行情况!C:C,"*1320_020*",用例执行情况!J:J,"是") -> 0 | J21: =COUNTIFS(用例执行情况!C:C,"*1320_020*",用例执行情况!I:I,"是") -> 0 | K21: =D21/C21 -> 0.0625 | L21: =E21/C21 -> 0.28125 | M21: =F21/C21 -> 0.40625 | N21: =G21/C21 -> 0.15625 | O21: =H21/C21 -> 0.09375 | P21: =J21/C21 -> 0 | Q21: 1320 Sprint1
A22: TR_AcuRev1320_021 | B22: 网络模块 | C22: =COUNTIFS(用例执行情况!C:C,"*1320_021*") -> 86 | D22: =COUNTIFS(用例执行情况!C:C,"*1320_021*",用例执行情况!H:H,"LV0") -> 3 | E22: =COUNTIFS(用例执行情况!C:C,"*1320_021*",用例执行情况!H:H,"LV1") -> 23 | F22: =COUNTIFS(用例执行情况!C:C,"*1320_021*",用例执行情况!H:H,"LV2") -> 34 | G22: =COUNTIFS(用例执行情况!C:C,"*1320_021*",用例执行情况!H:H,"LV3") -> 15 | H22: =COUNTIFS(用例执行情况!C:C,"*1320_021*",用例执行情况!H:H,"LV4") -> 11 | I22: =COUNTIFS(用例执行情况!C:C,"*1320_021*",用例执行情况!J:J,"是") -> 0 | J22: =COUNTIFS(用例执行情况!C:C,"*1320_021*",用例执行情况!I:I,"是") -> 0 | K22: =D22/C22 -> 0.034883721 | L22: =E22/C22 -> 0.26744186 | M22: =F22/C22 -> 0.39534884 | N22: =G22/C22 -> 0.1744186 | O22: =H22/C22 -> 0.12790698 | P22: =J22/C22 -> 0 | Q22: 1320 Sprint1
A23: TR_AcuRev1320_022 | B23: BACnet通信协议 | C23: =COUNTIFS(用例执行情况!C:C,"*1320_022*") -> 23 | D23: =COUNTIFS(用例执行情况!C:C,"*1320_022*",用例执行情况!H:H,"LV0") -> 2 | E23: =COUNTIFS(用例执行情况!C:C,"*1320_022*",用例执行情况!H:H,"LV1") -> 12 | F23: =COUNTIFS(用例执行情况!C:C,"*1320_022*",用例执行情况!H:H,"LV2") -> 5 | G23: =COUNTIFS(用例执行情况!C:C,"*1320_022*",用例执行情况!H:H,"LV3") -> 3 | H23: =COUNTIFS(用例执行情况!C:C,"*1320_022*",用例执行情况!H:H,"LV4") -> 1 | I23: =COUNTIFS(用例执行情况!C:C,"*1320_022*",用例执行情况!J:J,"是") -> 0 | J23: =COUNTIFS(用例执行情况!C:C,"*1320_022*",用例执行情况!I:I,"是") -> 0 | K23: =D23/C23 -> 0.086956522 | L23: =E23/C23 -> 0.52173913 | M23: =F23/C23 -> 0.2173913 | N23: =G23/C23 -> 0.13043478 | O23: =H23/C23 -> 0.043478261 | P23: =J23/C23 -> 0 | Q23: 1320 Sprint1 | R23: 王丽红
A24: TR_AcuRev1320_023 | B24: Firmware升级 | C24: =COUNTIFS(用例执行情况!C:C,"*1320_023*") -> 40 | D24: =COUNTIFS(用例执行情况!C:C,"*1320_023*",用例执行情况!H:H,"LV0") -> 2 | E24: =COUNTIFS(用例执行情况!C:C,"*1320_023*",用例执行情况!H:H,"LV1") -> 8 | F24: =COUNTIFS(用例执行情况!C:C,"*1320_023*",用例执行情况!H:H,"LV2") -> 18 | G24: =COUNTIFS(用例执行情况!C:C,"*1320_023*",用例执行情况!H:H,"LV3") -> 11 | H24: =COUNTIFS(用例执行情况!C:C,"*1320_023*",用例执行情况!H:H,"LV4") -> 1 | I24: =COUNTIFS(用例执行情况!C:C,"*1320_023*",用例执行情况!J:J,"是") -> 0 | J24: =COUNTIFS(用例执行情况!C:C,"*1320_023*",用例执行情况!I:I,"是") -> 0 | K24: =D24/C24 -> 0.05 | L24: =E24/C24 -> 0.2 | M24: =F24/C24 -> 0.45 | N24: =G24/C24 -> 0.275 | O24: =H24/C24 -> 0.025 | P24: =J24/C24 -> 0 | Q24: 1320 Sprint1 | R24: 胡赞
A25: TR_AcuRev1320_024 | B25: 铅封功能 | C25: =COUNTIFS(用例执行情况!C:C,"*1320_024*") -> 60 | D25: =COUNTIFS(用例执行情况!C:C,"*1320_024*",用例执行情况!H:H,"LV0") -> 2 | E25: =COUNTIFS(用例执行情况!C:C,"*1320_024*",用例执行情况!H:H,"LV1") -> 13 | F25: =COUNTIFS(用例执行情况!C:C,"*1320_024*",用例执行情况!H:H,"LV2") -> 32 | G25: =COUNTIFS(用例执行情况!C:C,"*1320_024*",用例执行情况!H:H,"LV3") -> 9 | H25: =COUNTIFS(用例执行情况!C:C,"*1320_024*",用例执行情况!H:H,"LV4") -> 4 | I25: =COUNTIFS(用例执行情况!C:C,"*1320_024*",用例执行情况!J:J,"是") -> 0 | J25: =COUNTIFS(用例执行情况!C:C,"*1320_024*",用例执行情况!I:I,"是") -> 0 | K25: =D25/C25 -> 0.033333333 | L25: =E25/C25 -> 0.21666667 | M25: =F25/C25 -> 0.53333333 | N25: =G25/C25 -> 0.15 | O25: =H25/C25 -> 0.066666667 | P25: =J25/C25 -> 0 | Q25: 1320 Sprint1
A26: TR_AcuRev1320_025 | B26: 校准功能 | C26: =COUNTIFS(用例执行情况!C:C,"*1320_025*") -> 6 | D26: =COUNTIFS(用例执行情况!C:C,"*1320_025*",用例执行情况!H:H,"LV0") -> 4 | E26: =COUNTIFS(用例执行情况!C:C,"*1320_025*",用例执行情况!H:H,"LV1") -> 0 | F26: =COUNTIFS(用例执行情况!C:C,"*1320_025*",用例执行情况!H:H,"LV2") -> 0 | G26: =COUNTIFS(用例执行情况!C:C,"*1320_025*",用例执行情况!H:H,"LV3") -> 1 | H26: =COUNTIFS(用例执行情况!C:C,"*1320_025*",用例执行情况!H:H,"LV4") -> 1 | I26: =COUNTIFS(用例执行情况!C:C,"*1320_025*",用例执行情况!J:J,"是") -> 0 | J26: =COUNTIFS(用例执行情况!C:C,"*1320_025*",用例执行情况!I:I,"是") -> 0 | K26: =D26/C26 -> 0.66666667 | L26: =E26/C26 -> 0 | M26: =F26/C26 -> 0 | N26: =G26/C26 -> 0.16666667 | O26: =H26/C26 -> 0.16666667 | P26: =J26/C26 -> 0 | Q26: 1320 Sprint1
A27: TR_AcuRev1320_026 | B27: HMI测量设置及出厂信息 | C27: =COUNTIFS(用例执行情况!C:C,"*1320_026*") -> 89 | D27: =COUNTIFS(用例执行情况!C:C,"*1320_026*",用例执行情况!H:H,"LV0") -> 2 | E27: =COUNTIFS(用例执行情况!C:C,"*1320_026*",用例执行情况!H:H,"LV1") -> 24 | F27: =COUNTIFS(用例执行情况!C:C,"*1320_026*",用例执行情况!H:H,"LV2") -> 45 | G27: =COUNTIFS(用例执行情况!C:C,"*1320_026*",用例执行情况!H:H,"LV3") -> 14 | H27: =COUNTIFS(用例执行情况!C:C,"*1320_026*",用例执行情况!H:H,"LV4") -> 2 | I27: =COUNTIFS(用例执行情况!C:C,"*1320_026*",用例执行情况!J:J,"是") -> 0 | J27: =COUNTIFS(用例执行情况!C:C,"*1320_026*",用例执行情况!I:I,"是") -> 0 | K27: =D27/C27 -> 0.02247191 | L27: =E27/C27 -> 0.26966292 | M27: =F27/C27 -> 0.50561798 | N27: =G27/C27 -> 0.15730337 | O27: =H27/C27 -> 0.02247191 | P27: =J27/C27 -> 0 | Q27: 1320 Sprint1
A28: TR_AcuRev1320_027 | B28: 密码及背光设置 | C28: =COUNTIFS(用例执行情况!C:C,"*1320_027*") -> 33 | D28: =COUNTIFS(用例执行情况!C:C,"*1320_027*",用例执行情况!H:H,"LV0") -> 3 | E28: =COUNTIFS(用例执行情况!C:C,"*1320_027*",用例执行情况!H:H,"LV1") -> 20 | F28: =COUNTIFS(用例执行情况!C:C,"*1320_027*",用例执行情况!H:H,"LV2") -> 6 | G28: =COUNTIFS(用例执行情况!C:C,"*1320_027*",用例执行情况!H:H,"LV3") -> 3 | H28: =COUNTIFS(用例执行情况!C:C,"*1320_027*",用例执行情况!H:H,"LV4") -> 1 | I28: =COUNTIFS(用例执行情况!C:C,"*1320_027*",用例执行情况!J:J,"是") -> 0 | J28: =COUNTIFS(用例执行情况!C:C,"*1320_027*",用例执行情况!I:I,"是") -> 0 | K28: =D28/C28 -> 0.090909091 | L28: =E28/C28 -> 0.60606061 | M28: =F28/C28 -> 0.18181818 | N28: =G28/C28 -> 0.090909091 | O28: =H28/C28 -> 0.03030303 | P28: =J28/C28 -> 0 | Q28: 1320 Sprint1
A29: TR_AcuRev1320_028 | B29: 电源要求 | C29: =COUNTIFS(用例执行情况!C:C,"*1320_028*") -> 2 | D29: =COUNTIFS(用例执行情况!C:C,"*1320_028*",用例执行情况!H:H,"LV0") -> 1 | E29: =COUNTIFS(用例执行情况!C:C,"*1320_028*",用例执行情况!H:H,"LV1") -> 1 | F29: =COUNTIFS(用例执行情况!C:C,"*1320_028*",用例执行情况!H:H,"LV2") -> 0 | G29: =COUNTIFS(用例执行情况!C:C,"*1320_028*",用例执行情况!H:H,"LV3") -> 0 | H29: =COUNTIFS(用例执行情况!C:C,"*1320_028*",用例执行情况!H:H,"LV4") -> 0 | I29: =COUNTIFS(用例执行情况!C:C,"*1320_028*",用例执行情况!J:J,"是") -> 0 | J29: =COUNTIFS(用例执行情况!C:C,"*1320_028*",用例执行情况!I:I,"是") -> 0 | K29: =D29/C29 -> 0.5 | L29: =E29/C29 -> 0.5 | M29: =F29/C29 -> 0 | N29: =G29/C29 -> 0 | O29: =H29/C29 -> 0 | P29: =J29/C29 -> 0 | Q29: 1320 Sprint1
A30: TR_AcuRev1320_029 | B30: 性能验证 | C30: =COUNTIFS(用例执行情况!C:C,"*1320_029*") -> 3 | D30: =COUNTIFS(用例执行情况!C:C,"*1320_029*",用例执行情况!H:H,"LV0") -> 0 | E30: =COUNTIFS(用例执行情况!C:C,"*1320_029*",用例执行情况!H:H,"LV1") -> 0 | F30: =COUNTIFS(用例执行情况!C:C,"*1320_029*",用例执行情况!H:H,"LV2") -> 0 | G30: =COUNTIFS(用例执行情况!C:C,"*1320_029*",用例执行情况!H:H,"LV3") -> 3 | H30: =COUNTIFS(用例执行情况!C:C,"*1320_029*",用例执行情况!H:H,"LV4") -> 0 | I30: =COUNTIFS(用例执行情况!C:C,"*1320_029*",用例执行情况!J:J,"是") -> 0 | J30: =COUNTIFS(用例执行情况!C:C,"*1320_029*",用例执行情况!I:I,"是") -> 0 | K30: =D30/C30 -> 0 | L30: =E30/C30 -> 0 | M30: =F30/C30 -> 0 | N30: =G30/C30 -> 1 | O30: =H30/C30 -> 0 | P30: =J30/C30 -> 0 | Q30: 1320 Sprint1
A31: TR_AcuRev1320_030 | B31: 电气参数稳定性&压力验证 | C31: =COUNTIFS(用例执行情况!C:C,"*1320_030*") -> 14 | D31: =COUNTIFS(用例执行情况!C:C,"*1320_030*",用例执行情况!H:H,"LV0") -> 0 | E31: =COUNTIFS(用例执行情况!C:C,"*1320_030*",用例执行情况!H:H,"LV1") -> 0 | F31: =COUNTIFS(用例执行情况!C:C,"*1320_030*",用例执行情况!H:H,"LV2") -> 4 | G31: =COUNTIFS(用例执行情况!C:C,"*1320_030*",用例执行情况!H:H,"LV3") -> 7 | H31: =COUNTIFS(用例执行情况!C:C,"*1320_030*",用例执行情况!H:H,"LV4") -> 3 | I31: =COUNTIFS(用例执行情况!C:C,"*1320_030*",用例执行情况!J:J,"是") -> 0 | J31: =COUNTIFS(用例执行情况!C:C,"*1320_030*",用例执行情况!I:I,"是") -> 11 | K31: =D31/C31 -> 0 | L31: =E31/C31 -> 0 | M31: =F31/C31 -> 0.28571429 | N31: =G31/C31 -> 0.5 | O31: =H31/C31 -> 0.21428571 | P31: =J31/C31 -> 0.78571429 | Q31: 1320 Sprint1
A32: TR_AcuRev1320_031 | B32: 挂机专项验证 | C32: =COUNTIFS(用例执行情况!C:C,"*1320_031*") -> 8 | D32: =COUNTIFS(用例执行情况!C:C,"*1320_031*",用例执行情况!H:H,"LV0") -> 0 | E32: =COUNTIFS(用例执行情况!C:C,"*1320_031*",用例执行情况!H:H,"LV1") -> 5 | F32: =COUNTIFS(用例执行情况!C:C,"*1320_031*",用例执行情况!H:H,"LV2") -> 0 | G32: =COUNTIFS(用例执行情况!C:C,"*1320_031*",用例执行情况!H:H,"LV3") -> 2 | H32: =COUNTIFS(用例执行情况!C:C,"*1320_031*",用例执行情况!H:H,"LV4") -> 1 | I32: =COUNTIFS(用例执行情况!C:C,"*1320_031*",用例执行情况!J:J,"是") -> 0 | J32: =COUNTIFS(用例执行情况!C:C,"*1320_031*",用例执行情况!I:I,"是") -> 0 | K32: =D32/C32 -> 0 | L32: =E32/C32 -> 0.625 | M32: =F32/C32 -> 0 | N32: =G32/C32 -> 0.25 | O32: =H32/C32 -> 0.125 | P32: =J32/C32 -> 0 | Q32: 1320 Sprint1
A33: TR_AcuRev1320_032 | B33: 上位机DataLogSetting | C33: =COUNTIFS(用例执行情况!C:C,"*1320_032*") -> 30 | D33: =COUNTIFS(用例执行情况!C:C,"*1320_032*",用例执行情况!H:H,"LV0") -> 1 | E33: =COUNTIFS(用例执行情况!C:C,"*1320_032*",用例执行情况!H:H,"LV1") -> 9 | F33: =COUNTIFS(用例执行情况!C:C,"*1320_032*",用例执行情况!H:H,"LV2") -> 8 | G33: =COUNTIFS(用例执行情况!C:C,"*1320_032*",用例执行情况!H:H,"LV3") -> 9 | H33: =COUNTIFS(用例执行情况!C:C,"*1320_032*",用例执行情况!H:H,"LV4") -> 3 | I33: =COUNTIFS(用例执行情况!C:C,"*1320_032*",用例执行情况!J:J,"是") -> 0 | J33: =COUNTIFS(用例执行情况!C:C,"*1320_032*",用例执行情况!I:I,"是") -> 0 | K33: =D33/C33 -> 0.033333333 | L33: =E33/C33 -> 0.3 | M33: =F33/C33 -> 0.26666667 | N33: =G33/C33 -> 0.3 | O33: =H33/C33 -> 0.1 | P33: =J33/C33 -> 0 | Q33: 1320 Sprint1
A34: TR_AcuRev1320_033 | B34: 脉冲计算器 | C34: =COUNTIFS(用例执行情况!C:C,"*1320_033*") -> 7 | D34: =COUNTIFS(用例执行情况!C:C,"*1320_033*",用例执行情况!H:H,"LV0") -> 1 | E34: =COUNTIFS(用例执行情况!C:C,"*1320_033*",用例执行情况!H:H,"LV1") -> 1 | F34: =COUNTIFS(用例执行情况!C:C,"*1320_033*",用例执行情况!H:H,"LV2") -> 1 | G34: =COUNTIFS(用例执行情况!C:C,"*1320_033*",用例执行情况!H:H,"LV3") -> 3 | H34: =COUNTIFS(用例执行情况!C:C,"*1320_033*",用例执行情况!H:H,"LV4") -> 1 | I34: =COUNTIFS(用例执行情况!C:C,"*1320_033*",用例执行情况!J:J,"是") -> 0 | J34: =COUNTIFS(用例执行情况!C:C,"*1320_033*",用例执行情况!I:I,"是") -> 0 | K34: =D34/C34 -> 0.14285714 | L34: =E34/C34 -> 0.14285714 | M34: =F34/C34 -> 0.14285714 | N34: =G34/C34 -> 0.42857143 | O34: =H34/C34 -> 0.14285714 | P34: =J34/C34 -> 0 | Q34: 1320 Sprint1
A35: TR_AcuRev1320_034 | B35: 数据导出导入 | C35: =COUNTIFS(用例执行情况!C:C,"*1320_034*") -> 10 | D35: =COUNTIFS(用例执行情况!C:C,"*1320_034*",用例执行情况!H:H,"LV0") -> 1 | E35: =COUNTIFS(用例执行情况!C:C,"*1320_034*",用例执行情况!H:H,"LV1") -> 1 | F35: =COUNTIFS(用例执行情况!C:C,"*1320_034*",用例执行情况!H:H,"LV2") -> 8 | G35: =COUNTIFS(用例执行情况!C:C,"*1320_034*",用例执行情况!H:H,"LV3") -> 0 | H35: =COUNTIFS(用例执行情况!C:C,"*1320_034*",用例执行情况!H:H,"LV4") -> 0 | I35: =COUNTIFS(用例执行情况!C:C,"*1320_034*",用例执行情况!J:J,"是") -> 0 | J35: =COUNTIFS(用例执行情况!C:C,"*1320_034*",用例执行情况!I:I,"是") -> 0 | K35: =D35/C35 -> 0.1 | L35: =E35/C35 -> 0.1 | M35: =F35/C35 -> 0.8 | N35: =G35/C35 -> 0 | O35: =H35/C35 -> 0 | P35: =J35/C35 -> 0 | Q35: 1320 Sprint1
A36: TR_AcuRev1320_035 | B36: rstp功能验证 | C36: =COUNTIFS(用例执行情况!C:C,"*1320_035*") -> 15 | D36: =COUNTIFS(用例执行情况!C:C,"*1320_035*",用例执行情况!H:H,"LV0") -> 3 | E36: =COUNTIFS(用例执行情况!C:C,"*1320_035*",用例执行情况!H:H,"LV1") -> 3 | F36: =COUNTIFS(用例执行情况!C:C,"*1320_035*",用例执行情况!H:H,"LV2") -> 9 | G36: =COUNTIFS(用例执行情况!C:C,"*1320_035*",用例执行情况!H:H,"LV3") -> 0 | H36: =COUNTIFS(用例执行情况!C:C,"*1320_035*",用例执行情况!H:H,"LV4") -> 0 | I36: =COUNTIFS(用例执行情况!C:C,"*1320_035*",用例执行情况!J:J,"是") -> 0 | J36: =COUNTIFS(用例执行情况!C:C,"*1320_035*",用例执行情况!I:I,"是") -> 0 | K36: =D36/C36 -> 0.2 | L36: =E36/C36 -> 0.2 | M36: =F36/C36 -> 0.6 | N36: =G36/C36 -> 0 | O36: =H36/C36 -> 0 | P36: =J36/C36 -> 0 | Q36: 1320 Sprint1
A37: TR_AcuRev1320_036 | B37: USB接口测试 | C37: =COUNTIFS(用例执行情况!C:C,"*1320_036*") -> 51 | D37: =COUNTIFS(用例执行情况!C:C,"*1320_036*",用例执行情况!H:H,"LV0") -> 2 | E37: =COUNTIFS(用例执行情况!C:C,"*1320_036*",用例执行情况!H:H,"LV1") -> 30 | F37: =COUNTIFS(用例执行情况!C:C,"*1320_036*",用例执行情况!H:H,"LV2") -> 19 | G37: =COUNTIFS(用例执行情况!C:C,"*1320_036*",用例执行情况!H:H,"LV3") -> 0 | H37: =COUNTIFS(用例执行情况!C:C,"*1320_036*",用例执行情况!H:H,"LV4") -> 0 | I37: =COUNTIFS(用例执行情况!C:C,"*1320_036*",用例执行情况!J:J,"是") -> 0 | J37: =COUNTIFS(用例执行情况!C:C,"*1320_036*",用例执行情况!I:I,"是") -> 0 | K37: =D37/C37 -> 0.039215686 | L37: =E37/C37 -> 0.58823529 | M37: =F37/C37 -> 0.37254902 | N37: =G37/C37 -> 0 | O37: =H37/C37 -> 0 | P37: =J37/C37 -> 0 | Q37: 1320 Sprint2
A38: TR_AcuRev1320_037 | B38: 电压闪变 | C38: =COUNTIFS(用例执行情况!C:C,"*1320_037*") -> 9 | D38: =COUNTIFS(用例执行情况!C:C,"*1320_037*",用例执行情况!H:H,"LV0") -> 1 | E38: =COUNTIFS(用例执行情况!C:C,"*1320_037*",用例执行情况!H:H,"LV1") -> 1 | F38: =COUNTIFS(用例执行情况!C:C,"*1320_037*",用例执行情况!H:H,"LV2") -> 7 | G38: =COUNTIFS(用例执行情况!C:C,"*1320_037*",用例执行情况!H:H,"LV3") -> 0 | H38: =COUNTIFS(用例执行情况!C:C,"*1320_037*",用例执行情况!H:H,"LV4") -> 0 | I38: =COUNTIFS(用例执行情况!C:C,"*1320_037*",用例执行情况!J:J,"是") -> 0 | J38: =COUNTIFS(用例执行情况!C:C,"*1320_037*",用例执行情况!I:I,"是") -> 0 | K38: =D38/C38 -> 0.11111111 | L38: =E38/C38 -> 0.11111111 | M38: =F38/C38 -> 0.77777778 | N38: =G38/C38 -> 0 | O38: =H38/C38 -> 0 | P38: =J38/C38 -> 0 | Q38: 1320新增
A39: TR_AcuRev1320_038 | B39: 数据推送到AcuCloud | C39: =COUNTIFS(用例执行情况!C:C,"*1320_038*") -> 10 | D39: =COUNTIFS(用例执行情况!C:C,"*1320_038*",用例执行情况!H:H,"LV0") -> 1 | E39: =COUNTIFS(用例执行情况!C:C,"*1320_038*",用例执行情况!H:H,"LV1") -> 0 | F39: =COUNTIFS(用例执行情况!C:C,"*1320_038*",用例执行情况!H:H,"LV2") -> 9 | G39: =COUNTIFS(用例执行情况!C:C,"*1320_038*",用例执行情况!H:H,"LV3") -> 0 | H39: =COUNTIFS(用例执行情况!C:C,"*1320_038*",用例执行情况!H:H,"LV4") -> 0 | I39: =COUNTIFS(用例执行情况!C:C,"*1320_038*",用例执行情况!J:J,"是") -> 0 | J39: =COUNTIFS(用例执行情况!C:C,"*1320_038*",用例执行情况!I:I,"是") -> 0 | K39: =D39/C39 -> 0.1 | L39: =E39/C39 -> 0 | M39: =F39/C39 -> 0.9 | N39: =G39/C39 -> 0 | O39: =H39/C39 -> 0 | P39: =J39/C39 -> 0 | Q39: 1320新增
A40: TR_AcuRev1320_039 | B40: 数据推送Data Post | C40: =COUNTIFS(用例执行情况!C:C,"*1320_039*") -> 14 | D40: =COUNTIFS(用例执行情况!C:C,"*1320_039*",用例执行情况!H:H,"LV0") -> 2 | E40: =COUNTIFS(用例执行情况!C:C,"*1320_039*",用例执行情况!H:H,"LV1") -> 1 | F40: =COUNTIFS(用例执行情况!C:C,"*1320_039*",用例执行情况!H:H,"LV2") -> 11 | G40: =COUNTIFS(用例执行情况!C:C,"*1320_039*",用例执行情况!H:H,"LV3") -> 0 | H40: =COUNTIFS(用例执行情况!C:C,"*1320_039*",用例执行情况!H:H,"LV4") -> 0 | I40: =COUNTIFS(用例执行情况!C:C,"*1320_039*",用例执行情况!J:J,"是") -> 0 | J40: =COUNTIFS(用例执行情况!C:C,"*1320_039*",用例执行情况!I:I,"是") -> 0 | K40: =D40/C40 -> 0.14285714 | L40: =E40/C40 -> 0.071428571 | M40: =F40/C40 -> 0.78571429 | N40: =G40/C40 -> 0 | O40: =H40/C40 -> 0 | P40: =J40/C40 -> 0 | Q40: 1320新增
...

Sheet 用例定级及比例
A1: 用例级别 | B1: 比例 | C1: 定级说明
A2: LV0 | B2: 0.1 | C2: 产品checklist范围内的测试用例，覆盖最基本功能
A3: LV1 | B3: 0.15 | C3: 产品基本功能验证，不涉及配置及场景测试
A4: LV2 | B4: 0.4 | C4: 产品功能测试常见配置及场景测试
A5: LV3 | B5: 0.25 | C5: 不常见的产品测试、配置及场景测试，以及常见异常测试
A6: LV4 | B6: 0.1 | C6: 冷僻的产品功能、配置及场景测试，以及罕见异常测试

Sheet 后期可能新增web用例
A1: 模块 | B1: 子模块 | C1: 用例编号 | D1: 用例标题 | E1: 预置条件 | F1: 测试步骤 | G1: 预期结果 | H1: 级别 | I1: 自动化 | J1: 需自动化 （是/否） | K1: 测试版本 | L1: 测试结果 | M1: 测试人员 | N1: 备注 | O1: 问题单来源
A2: web页面 | B2: TOU | C2: Function_AcuRev4100_046_16_case01 | D2: 点击setting界面，进入TOU，TOU使能开关设置 | E2: 1、Acuview2上位机 2、AcuRev1320电表 3、web网址 | F2: 1、电表上电，电表通讯正常 2、打开web页面,点击setting界面，进入TOU，TOU使能开关设置（打开/关闭） 3、查看上位机及电表上TOU使能开关的配置是否与Web端保持一致 | G2: 3、查看上位机及电表上TOU使能开关的配置与Web端保持一致
B3: TOU | C3: Function_AcuRev4100_046_16_case02 | D3: 点击setting界面，进入TOU，月结算模式设置 | E3: 1、Acuview2上位机 2、AcuRev1320电表 3、web网址 | F3: 1、电表上电，电表通讯正常 2、打开web页面,点击setting界面，进入TOU，配置月结算模式（月末/指定时间：01 00：00：00；15 15：00：00；29 23：59：00；31 23:59:00） 3、查看上位机及电表上月计算模式配置是否与Web端保持一致 | G3: 3、查看上位机及电表上月计算模式配置与Web端保持一致
B4: TOU | C4: Function_AcuRev4100_046_16_case03 | D4: 点击setting界面，进入TOU，费率配置 | E4: 1、Acuview2上位机 2、AcuRev1320电表 3、web网址 | F4: 1、电表上电，电表通讯正常 2、打开web页面,点击setting界面，进入TOU，费率配置（默认费率/费率全选/费率部分选） 3、查看上位机及电表上费率配置是否与Web端保持一致 | G4: 3、查看上位机及电表上费率配置与Web端保持一致
B5: TOU | C5: Function_AcuRev4100_046_16_case04 | D5: 点击setting界面，进入TOU，TOU Schdeules配置，TOU Schdeules配置内容检查 | E5: 1、Acuview2上位机 2、AcuRev1320电表 3、web网址 | F5: 1、电表上电，电表通讯正常 2、打开web页面,点击setting界面，进入TOU，TOU Schdeules配置（配置一条/配满/配置5条） 3、查看上位机及电表上TOU Schdeules配置条数是否与Web端保持一致 4、新增一个Schdeules，进入配置（配置1个，14，10个时刻，） 5、查看上位机及电表上 TOU Schdeules配置内容是否与Web端保持一致 6、新增一个Schdeules，配置多个时刻，分别设置为（相同费率，不同费率） 7、查看Schdeules中费率配置项是否与外部所使能的费率数相同 8、查看上位机及电表上 TOU Schdeules配置内容是否与Web端保持一致 | G5: 3、查看上位机及电表上TOU Schdeules配置条数与Web端保持一致 5、保持一致 7、相同 8、保持一致
B6: TOU | C6: Function_AcuRev4100_046_16_case05 | D6: 点击setting界面，进入TOU，检查删除TOU Schdeules配置 | E6: 1、Acuview2上位机 2、AcuRev1320电表 3、web网址 | F6: 1、电表上电，电表通讯正常 2、点击setting界面，进入TOU，检查删除TOU Schdeules配置 3、web端TOU Schdeules条数删除功能是否正常，每条Schdeules ID中时段删除是否正常 4、检查在web端删除后，上位机及电表是否保持一致 | G6: 3、web端TOU Schdeules条数删除功能正常，每条Schdeules ID中时段删除正常 4、检查在web端删除后，上位机及电表保持一致
B7: TOU | C7: Function_AcuRev4100_046_16_case06 | D7: 点击setting界面，进入TOU，TOU Season配置、TOU Season配置内容、TOU Season配置内容中start date合法性 | E7: 1、Acuview2上位机 2、AcuRev1320电表 3、web网址 | F7: 1、电表上电，电表通讯正常 2、打开web页面,点击setting界面，进入TOU，TOU Season配置（1条，10条，配满） 3、查看上位机及电表上TOU Season配置条数是否与Web端保持一致 4、打开web页面,点击setting界面，进入TOU，检查TOU Season配置内容 5、检查每条seasonID对应选择的schedule ID是否与TOU Schdeules中条数保持一致 6、配置多条TOU Season，将所有TOU Season配置相同的schedule ID 7、查看上位机及电表上TOU Season配置内容是否与Web端保持一致 8、配置多条TOU Season，将所有TOU Season配置不同的schedule ID 9、查看上位机及电表上TOU Season配置内容是否与Web端保持一致 10、配置多条TOU Season 11、查看这多条TOU Season的start date是否遵守时间递进的逻辑 12、检查这多条TOU Season的start date时间合法性校验 | G7: 3、查看上位机及电表上TOU Season配置条数与Web端保持一致 5、保持一致 7、保持一致 9、保持一致 11、遵守时间递进 12、校验正常
B8: TOU | C8: Function_AcuRev4100_046_16_case07 | D8: 点击setting界面，进入TOU，检查删除TOU Season配置 | E8: 1、Acuview2上位机 2、AcuRev1320电表 3、web网址 | F8: 1、电表上电，电表通讯正常 2、点击setting界面，进入TOU，检查删除TOU Season配置 3、web端TOU Season条数删除功能是否正常 4、检查在web端删除后，上位机及电表是否保持一致 | G8: 3、web端TOU Season条数删除功能正常 4、检查在web端删除后，上位机及电表保持一致
B9: TOU | C9: Function_AcuRev4100_046_16_case08 | D9: 点击setting界面，进入TOU，进行TOU Weekends配置 | E9: 1、Acuview2上位机 2、AcuRev1320电表 3、web网址 | F9: 1、电表上电，电表通讯正常 2、打开web页面，点击setting界面，进入TOU，进行TOU Weekends配置 3、Weekend Selection分别进行全选，选择1个，部分选择，对应1个weekend schedule 4、查看web端设置是否成功 5、设置成功后，查看上位机及电表与web端对应该参数配置是否相同 6、查看TOU Weekends中weekend schedule是否取的是TOU Schdeules中的Schdeules ID | G9: 4、查看web端设置成功 5、设置成功后，查看上位机及电表与web端对应该参数配置相同 6、查看TOU Weekends中weekend schedule取的是TOU Schdeules中的Schdeules ID
B10: TOU | C10: Function_AcuRev4100_046_16_case09 | D10: 点击setting界面，进入TOU，点击特殊周末配置，打开/关闭使能开关 | E10: 1、Acuview2上位机 2、AcuRev1320电表 3、web网址 | F10: 1、电表上电，电表通讯正常 2、打开web页面，点击setting界面，进入TOU，点击特殊周末配置，打开/关闭使能开关 3、查看上位机及电表特殊周末使能开关是否与web端保持一致 4、新增特殊周末Season ID,分别新增1条/配满 5、查看配满时，其条数是否与Tou Season 中的Season ID条数保持一致 6、新增1条Season ID进行配置，查看其中选择的weekend schedule是否取的是TOU Schdeules中的Schdeules ID 7、选择一个特殊周/全选特殊周/选择部分特殊周进行配置 8、配置成功后，查看上位机及电表是否与web端保持配置相同 | G10: 3、查看上位机及电表特殊周末使能开关与web端保持一致 5、查看配满时，其条数与Tou Season 中的Season ID条数保持一致 7、新增1条Season ID进行配置，查看其中选择的weekend schedule取的是TOU Schdeules中的Schdeules ID 8、配置成功后，查看上位机及电表与web端保持配置相同
B11: TOU | C11: Function_AcuRev4100_046_16_case10 | D11: 点击setting界面，进入TOU，检查删除特殊周末配置 | E11: 1、Acuview2上位机 2、AcuRev1320电表 3、web网址 | F11: 1、电表上电，电表通讯正常 2、点击setting界面，进入TOU，检查删除特殊周末配置 3、web端特殊周末条数删除功能是否正常 4、检查在web端删除后，上位机及电表是否保持一致 | G11: 3、web端特殊周末条数删除功能正常 4、检查在web端删除后，上位机及电表保持一致
B12: TOU | C12: Function_AcuRev4100_046_16_case11 | D12: 点击setting界面，进入TOU，TOU Holiday配置、TOU Holiday配置内容、TOU Holiday配置内容中date合法性 | E12: 1、Acuview2上位机 2、AcuRev1320电表 3、web网址 | F12: 1、电表上电，电表通讯正常 2、打开web页面,点击setting界面，进入TOU，TOU Holiday配置（1条，10条，配满） 3、查看上位机及电表上TOU Holiday配置条数是否与Web端保持一致 4、检查每条Holiday ID对应选择的schedule ID是否与TOU Schdeules中条数保持一致 5、配置多条TOU Holiday，将所有TOU Holiday配置相同的schedule ID 6、查看上位机及电表上TOU Holiday配置内容是否与Web端保持一致 7、配置多条TOU Holiday，将所有TOU Holiday配置不同的schedule ID 8、查看上位机及电表上TOU Holiday配置内容是否与Web端保持一致 9、配置多条TOU Holiday 10、检查这多条TOU Holiday的date时间合法性校验 11、在TOU Holiday中配置两条date相同的TOU Holiday，查看是否配置成功 | G12: 3、查看上位机及电表上TOU Holiday配置条数与Web端保持一致 4、保持一致 6、保持一致 8、保持一致 10、时间合法 11、配置成功
B13: TOU | C13: Function_AcuRev4100_046_16_case12 | D13: 点击setting界面，进入TOU，检查删除TOU Holiday配置 | E13: 1、Acuview2上位机 2、AcuRev1320电表 3、web网址 | F13: 1、电表上电，电表通讯正常 2、点击setting界面，进入TOU，检查删除TOU Holiday配置 3、web端TOU Holiday条数删除功能是否正常 4、检查在web端删除后，上位机及电表是否保持一致 | G13: 3、web端TOU Holiday条数删除功能正常 4、检查在web端删除后，上位机及电表保持一致
B14: TOU | C14: Function_AcuRev4100_046_16_case13 | D14: 点击setting界面，进入ten years holiday，配置使能开关 | E14: 1、Acuview2上位机 2、AcuRev1320电表 3、web网址 | F14: 1、电表上电，电表通讯正常 2、点击setting界面，进入ten years holiday，配置使能开关（打开/关闭） 3、检查web端、上位机、电表三者是否保持一致 | G14: 3、三处保持一致
... B19: TOU | C19: Function_AcuRev4100_046_16_case18 | D19: 点击setting界面，进入TOU界面,查看该页面英文描述及拼写 | E19: 1、Acuview2上位机 2、AcuRev1320电表 3、web网址 | F19: 1、电表上电，电表通讯正常 2、web页面，点击setting界面，进入TOU界面,查看该页面英文描述及拼写是否准确 | G19: 2、点击setting界面，进入TOU界面,查看该页面英文描述及拼写准确
B21: Web2交互(HMI配置) | C21: Function_AcuRev4100sprint2_001_10_case1 | D21: 在HMI上setting-web2使能enable DHCP | E21: 1、Acuview2上位机 2、USB串口线 3、AcuRev4100电表 | F21: 1、4100电表正常上电，sscom通过usb与电表链接，配置完成后，链接状态为connected； 2、在HMI上setting-web2使能enable DHCP 3、在sscom通过usb组帧查看电表状态寄存器中bit0是否置1 4、查看HMI-web2页面下对应enable DHCP该项是否标* 5、模拟web2回复4100电表发出的打开dhcp成功，利用sscom组帧手动将状态寄存器中bit0置位0 6、查看HMI-web2页面下对应enable DHCP该项标*是否消失 | G21: 3、电表状态寄存器中bit0置1 4、HMI-web2页面下对应enable DHCP该项标* 5、下发成功 6、HMI-web2页面下对应enable DHCP该项标*消失 | H21: LV0
B22: Web2交互(HMI配置) | C22: Function_AcuRev4100sprint2_001_10_case1-01 | D22: 在HMI上setting使能表计DHCP、关闭DHCP | E22: 1、Acuview2上位机 2、USB串口线 3、AcuRev4100电表 | F22: 1.使能表计DHCP 2.查看web2中Eth1 DHCP、Eth1 IP、Eth1 Subnet、Eth1 Gateway、Eth1DNS1、Eth1DNS2这些数据能否进行修改 3.关闭表计DHCP 4.查看web2中Eth1 DHCP、Eth1 IP、Eth1 Subnet、Eth1 Gateway、Eth1DNS1、Eth1DNS2这些数据的状态 | G22: 2.不能被修改 4.电表DHCP不应该影响web2的网络数据 | H22: LV0
B23: Web2交互(HMI配置) | C23: Function_AcuRev4100sprint2_001_10_case2 | D23: 配置web2的状态寄存器中bit0位enable DHCP置位为1后快速掉电再上电 | E23: 1、Acuview2上位机 2、USB串口线 3、AcuRev4100电表 | F23: 1、4100电表正常上电，sscom通过usb与电表链接，配置完成后，链接状态为connected； 2、在HMI上setting-web2使能enable DHCP 3、在sscom通过usb组帧查看电表状态寄存器中bit0是否置1 4、查看HMI-web2页面下对应enable DHCP该项是否标* 5、此后电表，再上电 6、在sscom通过usb组帧查看电表状态寄存器中bit0是否置1 7、查看HMI-web2页面下对应enable DHCP该项标*是否消失 | G23: 3、电表状态寄存器中bit0置1 4、HMI-web2页面下对应enable DHCP该项标* 6、电表状态寄存器中bit0置1 7、HMI-web2页面下对应enable DHCP该项标*未消失 | H23: LV0
B24: Web2交互(HMI配置) | C24: Function_AcuRev4100sprint2_001_10_case3 | D24: 进入HMI上setting-web2中，修改IP Address | E24: 1、Acuview2上位机 2、USB串口线 3、AcuRev4100电表 | F24: 1、4100电表正常上电，sscom通过usb与电表链接，配置完成后，链接状态为connected； 2、进入HMI上setting-web2中，修改IP Address 3、在sscom通过usb组帧查看电表状态寄存器中bit1是否置1 4、查看HMI-web2页面下对应IP Address该项是否标* 5、模拟web2回复4100电表发出的打开dhcp成功，利用sscom组帧手动将状态寄存器中bit1置位0 6、查看HMI-web2页面下对应IP Address该项标*是否消失 | G24: 3、电表状态寄存器中bit1置1 4、HMI-web2页面下对应IP Address该项标* 5、下发成功 6、HMI-web2页面下对应IP Address该项标*消失 | H24: LV1
B25: Web2交互(HMI配置) | C25: Function_AcuRev4100sprint2_001_10_case4 | D25: 进入HMI上setting-web2中，修改Subnet mask | E25: 1、Acuview2上位机 2、USB串口线 3、AcuRev4100电表 | F25: 1、4100电表正常上电，sscom通过usb与电表链接，配置完成后，链接状态为connected； 2、进入HMI上setting-web2中，修改Subnet mask 3、在sscom通过usb组帧查看电表状态寄存器中bit2是否置1 4、查看HMI-web2页面下对应Subnet mask该项是否标* 5、模拟web2回复4100电表发出的打开dhcp成功，利用sscom组帧手动将状态寄存器中bit2置位0 6、查看HMI-web2页面下对应Subnet mask该项标*是否消失 | G25: 3、电表状态寄存器中bit2置1 4、HMI-web2页面下对应Subnet mask该项标* 5、下发成功 6、HMI-web2页面下对应Subnet mask该项标*消失 | H25: LV1
B26: Web2交互(HMI配置) | C26: Function_AcuRev4100sprint2_001_10_case5 | D26: 进入HMI上setting-web2中，修改Gateway | E26: 1、Acuview2上位机 2、USB串口线 3、AcuRev4100电表 | F26: 1、4100电表正常上电，sscom通过usb与电表链接，配置完成后，链接状态为connected； 2、进入HMI上setting-web2中，修改Gateway 3、在sscom通过usb组帧查看电表状态寄存器中bit3是否置1 4、查看HMI-web2页面下对应Gateway 该项是否标* 5、模拟web2回复4100电表发出的打开dhcp成功，利用sscom组帧手动将状态寄存器中bit3置位0 6、查看HMI-web2页面下对应Gateway 该项标*是否消失 | G26: 3、电表状态寄存器中bit3置1 4、HMI-web2页面下对应Gateway 该项标* 5、下发成功 6、HMI-web2页面下对应Gateway 该项标*消失 | H26: LV1
B27: Web2交互(HMI配置) | C27: Function_AcuRev4100sprint2_001_10_case6 | D27: 进入HMI上setting-web2中，修改DNS1 | E27: 1、Acuview2上位机 2、USB串口线 3、AcuRev4100电表 | F27: 1、4100电表正常上电，sscom通过usb与电表链接，配置完成后，链接状态为connected； 2、进入HMI上setting-web2中，修改DNS1 3、在sscom通过usb组帧查看电表状态寄存器中bit4是否置1 4、查看HMI-web2页面下对应DNS1 该项是否标* 5、模拟web2回复4100电表发出的打开dhcp成功，利用sscom组帧手动将状态寄存器中bit4置位0 6、查看HMI-web2页面下对应DNS1 该项标*是否消失 | G27: 3、电表状态寄存器中bit4置1 4、HMI-web2页面下对应DNS1 该项标* 5、下发成功 6、HMI-web2页面下对应DNS1 该项标*消失 | H27: LV1
B28: Web2交互(HMI配置) | C28: Function_AcuRev4100sprint2_001_10_case7 | D28: 进入HMI上setting-web2中，修改DNS2 | E28: 1、Acuview2上位机 2、USB串口线 3、AcuRev4100电表 | F28: 1、4100电表正常上电，sscom通过usb与电表链接，配置完成后，链接状态为connected； 2、进入HMI上setting-web2中，修改DNS2 3、在sscom通过usb组帧查看电表状态寄存器中bit5是否置1 4、查看HMI-web2页面下对应DNS2该项是否标* 5、模拟web2回复4100电表发出的打开dhcp成功，利用sscom组帧手动将状态寄存器中bit5置位0 6、查看HMI-web2页面下对应DNS2 该项标*是否消失 | G28: 3、电表状态寄存器中bit5置1 4、HMI-web2页面下对应DNS2 该项标* 5、下发成功 6、HMI-web2页面下对应DNS2 该项标*消失 | H28: LV1
B29: Web2交互(HMI配置) | C29: Function_AcuRev4100sprint2_001_10_case8 | D29: 进入HMI上setting-web2中，使能Device Reboot | E29: 1、Acuview2上位机 2、USB串口线 3、AcuRev4100电表 | F29: 1、4100电表正常上电，sscom通过usb与电表链接，配置完成后，链接状态为connected； 2、进入HMI上setting-web2中，使能Device Reboot 3、在sscom通过usb组帧查看电表状态寄存器中bit6是否置1 4、查看HMI-web2页面下对应Device Reboot 该项是否标* 5、模拟web2回复4100电表发出的打开dhcp成功，利用sscom组帧手动将状态寄存器中bit6置位0 6、查看HMI-web2页面下对应Device Reboot 该项标*是否消失 | G29: 3、电表状态寄存器中bit6置1 4、HMI-web2页面下对应Device Reboot 该项标* 5、下发成功 6、HMI-web2页面下对应Device Reboot 该项标*消失 | H29: LV1
B30: Web2交互(HMI配置) | C30: Function_AcuRev4100sprint2_001_10_case9 | D30: 进入HMI上setting-web2中，使能Factory Reset | E30: 1、Acuview2上位机 2、USB串口线 3、AcuRev4100电表 | F30: 1、4100电表正常上电，sscom通过usb与电表链接，配置完成后，链接状态为connected； 2、进入HMI上setting-web2中，使能Factory Reset 3、在sscom通过usb组帧查看电表状态寄存器中bit7是否置1 4、查看HMI-web2页面下对应Factory Reset 该项是否标* 5、模拟web2回复4100电表发出的打开dhcp成功，利用sscom组帧手动将状态寄存器中bit7置位0 6、查看HMI-web2页面下对应Factory Reset 该项标*是否消失 | G30: 3、电表状态寄存器中bit7置1 4、HMI-web2页面下对应Factory Reset 该项标*,web2模块中Eth1 DHCP、Eth1 IP、Eth1 Subnet、Eth1 Gateway、Eth1DNS1、Eth1DNS2的数据均被恢复为默认值：；且均被标* 5、下发成功 6、HMI-web2页面下对应Factory Reset 该项标*消失，其他标*的也需对应bit位写0 | H30: LV0
B31: Web2交互(HMI配置) | C31: Function_AcuRev4100sprint2_001_10_case10 | D31: 进入HMI上setting-web2中，使能Network Reset | E31: 1、Acuview2上位机 2、USB串口线 3、AcuRev4100电表 | F31: 1、4100电表正常上电，sscom通过usb与电表链接，配置完成后，链接状态为connected； 2、进入HMI上setting-web2中，使能Network Reset 3、在sscom通过usb组帧查看电表状态寄存器中bit8是否置1 4、查看HMI-web2页面下对应Network Reset该项是否标* 5、模拟web2回复4100电表发出的打开dhcp成功，利用sscom组帧手动将状态寄存器中bit8置位0 6、查看HMI-web2页面下对应Network Reset该项标*是否消失 | G31: 3、电表状态寄存器中bit8置1 4、HMI-web2页面下对应Network Reset该项标*，web2模块中Eth1 DHCP、Eth1 IP、Eth1 Subnet、Eth1 Gateway、Eth1DNS1、Eth1DNS2的数据均被恢复为默认值：；且均被标* 5、下发成功 6、HMI-web2页面下对应Network Reset该项标*消失，其他标*的也需对应bit位写0 | H31: LV1
B32: Web2交互(HMI配置) | C32: Function_AcuRev4100sprint2_001_10_case11 | D32: 进入HMI上setting-web2中，使能Clock Update Enable | E32: 1、Acuview2上位机 2、USB串口线 3、AcuRev4100电表 | F32: 1、4100电表正常上电，sscom通过usb与电表链接，配置完成后，链接状态为connected； 2、进入HMI上setting-web2中，使能Clock Update Enable 3、在sscom通过usb组帧查看电表状态寄存器中bit9是否置1 4、查看HMI-web2页面下对应Clock Update Enable该项是否标* 5、模拟web2回复4100电表发出的打开dhcp成功，利用sscom组帧手动将状态寄存器中bit9置位0 6、查看HMI-web2页面下对应Clock Update Enable该项标*是否消失 | G32: 3、电表状态寄存器中bit9置1 4、HMI-web2页面下对应Clock Update Enable该项标* 5、下发成功 6、HMI-web2页面下对应Clock Update Enable该项标*消失 | H32: LV1
... B47: Web2交互(链接状态&自发现) | C47: Function_AcuRev4100sprint2_001_13_case2 | D47: 将4块4100电表通过路由器级联，打开这3台电表的DHCP,在路由器中查看是否获取到了这4台电表的SN号,随后关闭电表的DHCP | E47: 1、Acuview2上位机 2、网线 3、AcuRev4100电表 4、路由器 | F47: 1、将4块4100电表通过路由器级联 2、打开这4块电表的DHCP 3、一段时间后（1min）,查看在路由器上是否能获取到这4台电表的SN号 4、随后关闭电表的DHCP 5、一段时间后（1min）,查看在路由器上这4台电表的SN号是否消失 6、重启这四块电表，继续查看在路由器上这4台电表的SN号是否消失 | G47: 3、一段时间后（1min）,在路由器上能获取到这4台电表的SN号 5、这4台电表的SN号不会消失 6、这4台电表的SN号消失 | H47: LV0

Sheet 版本测试日报
A1: AcuRev1320 v1.01p05 软件测试双日报
A2: 【软件版本】 | B2: APP:AcuRev-1320_Application_v1.01p05_20260401.MFEA Boot: AcuRev-1320_H745_Boot_v1.01p05_20260401.hex AcuRev-1320_H750_Boot_v1.01p05_20260401.hex AcuView2: acuview2_develop_v1.10p05_setup.exe | F2: 【硬件版本】 | G2: v1.01p05
A3: 【测试日期】 | B3: 2026.04.03 -2026.04.15 | F3: 【版本目标】 | G3: 全功能测试+精度测试+挂机测试+问题单回归测试
A4: 整体测试进展
A5: 一句话进展: 版本测试第8天，用例执行进度100%， 问题单回归测试进度100%。发现提单问题48个，均已JIRA提单跟踪，打开Acu Cloud功能，点击Test Communication之后电表会发生重启；电表Web页面显示和设置存在问题; data log存在概率乱码或全为0。
A6: 风险&阻塞
A7: 序号 | B7: 问题描述 | L7: 责任人 | M7: 期望解决日期
A8: 1
A9: 2
A10: 用例执行情况
A11: 序号 | B11: 测试模块 | D11: 测试人员 | E11: 基线用例 | F11: 用例总数 | G11: 执行数 | H11: Passed | I11: Failed | J11: Unavailable | K11: Blocked | L11: 已回归问题单 | M11: 执行率
A12: 1 | B12: 交流频率 | D12: 刘静茹&刘丛松&王丽红&王丽红 | E12: =COUNTIFS(用例执行情况!C:C,"*AcuRev1320_001*") -> 5 | F12: =COUNTIFS(用例执行情况!C:C,"*AcuRev1320_001*",用例执行情况!Z:Z,"v1.01p05") -> 3 | G12: =COUNTIFS(用例执行情况!C:C,"*AcuRev1320_001*",用例执行情况!Z:Z,"v1.01p05",用例执行情况!AA:AA,"<>") -> 3 | H12: =COUNTIFS(用例执行情况!C:C,"*AcuRev1320_001*",用例执行情况!Z:Z,"v1.01p05",用例执行情况!AA:AA,"Passed") -> 3 | I12: =COUNTIFS(用例执行情况!C:C,"*AcuRev1320_001*",用例执行情况!Z:Z,"v1.01p05",用例执行情况!AA:AA,"Failed") -> 0 | J12: =COUNTIFS(用例执行情况!C:C,"*AcuRev1320_001*",用例执行情况!Z:Z,"v1.01p05",用例执行情况!AA:AA,"Unavailable") -> 0 | K12: =COUNTIFS(用例执行情况!C:C,"*AcuRev1320_001*",用例执行情况!Z:Z,"v1.01p05",用例执行情况!AA:AA,"Blocked") -> 0 | L12: / | M12: =COUNTIFS(用例执行情况!C:C,"*AcuRev1320_001*",用例执行情况!Z:Z,"v1.01p05",用例执行情况!AA:AA,"<>")/COUNTIFS(用例执行情况!C:C,"*AcuRev1320_001*",用例执行情况!Z:Z,"v1.01p05") -> 1
A13: 2 | B13: 交流电压 | D13: 刘静茹&刘丛松&王丽红&王丽红 | E13: =COUNTIFS(用例执行情况!C:C,"*AcuRev1320_002*") -> 24 | F13: =COUNTIFS(用例执行情况!C:C,"*AcuRev1320_002*",用例执行情况!Z:Z,"v1.01p05") -> 11 | G13: =COUNTIFS(用例执行情况!C:C,"*AcuRev1320_002*",用例执行情况!Z:Z,"v1.01p05",用例执行情况!AA:AA,"<>") -> 11 | H13: =COUNTIFS(用例执行情况!C:C,"*AcuRev1320_002*",用例执行情况!Z:Z,"v1.01p05",用例执行情况!AA:AA,"Passed") -> 11 | I13: =COUNTIFS(用例执行情况!C:C,"*AcuRev1320_002*",用例执行情况!Z:Z,"v1.01p05",用例执行情况!AA:AA,"Failed") -> 0 | J13: =COUNTIFS(用例执行情况!C:C,"*AcuRev1320_002*",用例执行情况!Z:Z,"v1.01p05",用例执行情况!AA:AA,"Unavailable") -> 0 | K13: =COUNTIFS(用例执行情况!C:C,"*AcuRev1320_002*",用例执行情况!Z:Z,"v1.01p05",用例执行情况!AA:AA,"Blocked") -> 0 | L13: / | M13: =COUNTIFS(用例执行情况!C:C,"*AcuRev1320_002*",用例执行情况!Z:Z,"v1.01p05",用例执行情况!AA:AA,"<>")/COUNTIFS(用例执行情况!C:C,"*AcuRev1320_002*",用例执行情况!Z:Z,"v1.01p05") -> 1
A14: 3 | B14: 交流电流 | D14: 刘静茹&刘丛松&王丽红&王丽红 | E14: =COUNTIFS(用例执行情况!C:C,"*AcuRev1320_003*") -> 33 | F14: =COUNTIFS(用例执行情况!C:C,"*AcuRev1320_003*",用例执行情况!Z:Z,"v1.01p05") -> 16 | G14: =COUNTIFS(用例执行情况!C:C,"*AcuRev1320_003*",用例执行情况!Z:Z,"v1.01p05",用例执行情况!AA:AA,"<>") -> 16 | H14: =COUNTIFS(用例执行情况!C:C,"*AcuRev1320_003*",用例执行情况!Z:Z,"v1.01p05",用例执行情况!AA:AA,"Passed") -> 16 | I14: =COUNTIFS(用例执行情况!C:C,"*AcuRev1320_003*",用例执行情况!Z:Z,"v1.01p05",用例执行情况!AA:AA,"Failed") -> 0 | J14: =COUNTIFS(用例执行情况!C:C,"*AcuRev1320_003*",用例执行情况!Z:Z,"v1.01p05",用例执行情况!AA:AA,"Unavailable") -> 0 | K14: =COUNTIFS(用例执行情况!C:C,"*AcuRev1320_003*",用例执行情况!Z:Z,"v1.01p05",用例执行情况!AA:AA,"Blocked") -> 0 | L14: / | M14: =COUNTIFS(用例执行情况!C:C,"*AcuRev1320_003*",用例执行情况!Z:Z,"v1.01p05",用例执行情况!AA:AA,"<>")/COUNTIFS(用例执行情况!C:C,"*AcuRev1320_003*",用例执行情况!Z:Z,"v1.01p05") -> 1
A15: 4 | B15: 交流功率 | D15: 刘静茹&刘丛松&王丽红&王丽红 | E15: =COUNTIFS(用例执行情况!C:C,"*AcuRev1320_004*") -> 25 | F15: =COUNTIFS(用例执行情况!C:C,"*AcuRev1320_004*",用例执行情况!Z:Z,"v1.01p05") -> 12 | G15: =COUNTIFS(用例执行情况!C:C,"*AcuRev1320_004*",用例执行情况!Z:Z,"v1.01p05",用例执行情况!AA:AA,"<>") -> 12 | H15: =COUNTIFS(用例执行情况!C:C,"*AcuRev1320_004*",用例执行情况!Z:Z,"v1.01p05",用例执行情况!AA:AA,"Passed") -> 12 | I15: =COUNTIFS(用例执行情况!C:C,"*AcuRev1320_004*",用例执行情况!Z:Z,"v1.01p05",用例执行情况!AA:AA,"Failed") -> 0 | J15: =COUNTIFS(用例执行情况!C:C,"*AcuRev1320_004*",用例执行情况!Z:Z,"v1.01p05",用例执行情况!AA:AA,"Unavailable") -> 0 | K15: =COUNTIFS(用例执行情况!C:C,"*AcuRev1320_004*",用例执行情况!Z:Z,"v1.01p05",用例执行情况!AA:AA,"Blocked") -> 0 | L15: / | M15: =COUNTIFS(用例执行情况!C:C,"*AcuRev1320_004*",用例执行情况!Z:Z,"v1.01p05",用例执行情况!AA:AA,"<>")/COUNTIFS(用例执行情况!C:C,"*AcuRev1320_004*",用例执行情况!Z:Z,"v1.01p05") -> 1
A16: 5 | B16: 负载特性(RLC) | D16: 刘静茹&刘静茹&刘静茹&王丽红 | E16: =COUNTIFS(用例执行情况!C:C,"*AcuRev1320_005*") -> 21 | F16: =COUNTIFS(用例执行情况!C:C,"*AcuRev1320_005*",用例执行情况!Z:Z,"v1.01p05") -> 13 | G16: =COUNTIFS(用例执行情况!C:C,"*AcuRev1320_005*",用例执行情况!Z:Z,"v1.01p05",用例执行情况!AA:AA,"<>") -> 13 | H16: =COUNTIFS(用例执行情况!C:C,"*AcuRev1320_005*",用例执行情况!Z:Z,"v1.01p05",用例执行情况!AA:AA,"Passed") -> 13 | I16: =COUNTIFS(用例执行情况!C:C,"*AcuRev1320_005*",用例执行情况!Z:Z,"v1.01p05",用例执行情况!AA:AA,"Failed") -> 0 | J16: =COUNTIFS(用例执行情况!C:C,"*AcuRev1320_005*",用例执行情况!Z:Z,"v1.01p05",用例执行情况!AA:AA,"Unavailable") -> 0 | K16: =COUNTIFS(用例执行情况!C:C,"*AcuRev1320_005*",用例执行情况!Z:Z,"v1.01p05",用例执行情况!AA:AA,"Blocked") -> 0 | L16: / | M16: =COUNTIFS(用例执行情况!C:C,"*AcuRev1320_005*",用例执行情况!Z:Z,"v1.01p05",用例执行情况!AA:AA,"<>")/COUNTIFS(用例执行情况!C:C,"*AcuRev1320_005*",用例执行情况!Z:Z,"v1.01p05") -> 1
A17: 6 | B17: 相角(phase angle) | D17: 刘静茹&刘丛松&王丽红&王丽红 | E17: =COUNTIFS(用例执行情况!C:C,"*AcuRev1320_006*") -> 14 | F17: =COUNTIFS(用例执行情况!C:C,"*AcuRev1320_006*",用例执行情况!Z:Z,"v1.01p05") -> 7 | G17: =COUNTIFS(用例执行情况!C:C,"*AcuRev1320_006*",用例执行情况!Z:Z,"v1.01p05",用例执行情况!AA:AA,"<>") -> 7 | H17: =COUNTIFS(用例执行情况!C:C,"*AcuRev1320_006*",用例执行情况!Z:Z,"v1.01p05",用例执行情况!AA:AA,"Passed") -> 7 | I17: =COUNTIFS(用例执行情况!C:C,"*AcuRev1320_006*",用例执行情况!Z:Z,"v1.01p05",用例执行情况!AA:AA,"Failed") -> 0 | J17: =COUNTIFS(用例执行情况!C:C,"*AcuRev1320_006*",用例执行情况!Z:Z,"v1.01p05",用例执行情况!AA:AA,"Unavailable") -> 0 | K17: =COUNTIFS(用例执行情况!C:C,"*AcuRev1320_006*",用例执行情况!Z:Z,"v1.01p05",用例执行情况!AA:AA,"Blocked") -> 0 | L17: / | M17: =COUNTIFS(用例执行情况!C:C,"*AcuRev1320_006*",用例执行情况!Z:Z,"v1.01p05",用例执行情况!AA:AA,"<>")/COUNTIFS(用例执行情况!C:C,"*AcuRev1320_006*",用例执行情况!Z:Z,"v1.01p05") -> 1
A18: 7 | B18: 各次谐波 | D18: 刘丛松&刘静茹&刘静茹&刘静茹 | E18: =COUNTIFS(用例执行情况!C:C,"*AcuRev1320_007*") -> 34 | F18: =COUNTIFS(用例执行情况!C:C,"*AcuRev1320_007*",用例执行情况!Z:Z,"v1.01p05") -> 34 | G18: =COUNTIFS(用例执行情况!C:C,"*AcuRev1320_007*",用例执行情况!Z:Z,"v1.01p05",用例执行情况!AA:AA,"<>") -> 34 | H18: =COUNTIFS(用例执行情况!C:C,"*AcuRev1320_007*",用例执行情况!Z:Z,"v1.01p05",用例执行情况!AA:AA,"Passed") -> 34 | I18: =COUNTIFS(用例执行情况!C:C,"*AcuRev1320_007*",用例执行情况!Z:Z,"v1.01p05",用例执行情况!AA:AA,"Failed") -> 0 | J18: =COUNTIFS(用例执行情况!C:C,"*AcuRev1320_007*",用例执行情况!Z:Z,"v1.01p05",用例执行情况!AA:AA,"Unavailable") -> 0 | K18: =COUNTIFS(用例执行情况!C:C,"*AcuRev1320_007*",用例执行情况!Z:Z,"v1.01p05",用例执行情况!AA:AA,"Blocked") -> 0 | L18: / | M18: =COUNTIFS(用例执行情况!C:C,"*AcuRev1320_007*",用例执行情况!Z:Z,"v1.01p05",用例执行情况!AA:AA,"<>")/COUNTIFS(用例执行情况!C:C,"*AcuRev1320_007*",用例执行情况!Z:Z,"v1.01p05") -> 1
A19: 8 | B19: 谐波因数 | D19: 刘丛松&刘静茹&刘静茹&刘静茹 | E19: =COUNTIFS(用例执行情况!C:C,"*AcuRev1320_008*") -> 10 | F19: =COUNTIFS(用例执行情况!C:C,"*AcuRev1320_008*",用例执行情况!Z:Z,"v1.01p05") -> 10 | G19: =COUNTIFS(用例执行情况!C:C,"*AcuRev1320_008*",用例执行情况!Z:Z,"v1.01p05",用例执行情况!AA:AA,"<>") -> 10 | H19: =COUNTIFS(用例执行情况!C:C,"*AcuRev1320_008*",用例执行情况!Z:Z,"v1.01p05",用例执行情况!AA:AA,"Passed") -> 9 | I19: =COUNTIFS(用例执行情况!C:C,"*AcuRev1320_008*",用例执行情况!Z:Z,"v1.01p05",用例执行情况!AA:AA,"Failed") -> 1 | J19: =COUNTIFS(用例执行情况!C:C,"*AcuRev1320_008*",用例执行情况!Z:Z,"v1.01p05",用例执行情况!AA:AA,"Unavailable") -> 0 | K19: =COUNTIFS(用例执行情况!C:C,"*AcuRev1320_008*",用例执行情况!Z:Z,"v1.01p05",用例执行情况!AA:AA,"Blocked") -> 0 | L19: / | M19: =COUNTIFS(用例执行情况!C:C,"*AcuRev1320_008*",用例执行情况!Z:Z,"v1.01p05",用例执行情况!AA:AA,"<>")/COUNTIFS(用例执行情况!C:C,"*AcuRev1320_008*",用例执行情况!Z:Z,"v1.01p05") -> 1
A20: 9 | B20: 电能质量测量 | D20: 王洋&刘丛松&刘静茹 | E20: =COUNTIFS(用例执行情况!C:C,"*AcuRev1320_009*") -> 54 | F20: =COUNTIFS(用例执行情况!C:C,"*AcuRev1320_009*",用例执行情况!Z:Z,"v1.01p05") -> 27 | G20: =COUNTIFS(用例执行情况!C:C,"*AcuRev1320_009*",用例执行情况!Z:Z,"v1.01p05",用例执行情况!AA:AA,"<>") -> 27 | H20: =COUNTIFS(用例执行情况!C:C,"*AcuRev1320_009*",用例执行情况!Z:Z,"v1.01p05",用例执行情况!AA:AA,"Passed") -> 26 | I20: =COUNTIFS(用例执行情况!C:C,"*AcuRev1320_009*",用例执行情况!Z:Z,"v1.01p05",用例执行情况!AA:AA,"Failed") -> 1 | J20: =COUNTIFS(用例执行情况!C:C,"*AcuRev1320_009*",用例执行情况!Z:Z,"v1.01p05",用例执行情况!AA:AA,"Unavailable") -> 0 | K20: =COUNTIFS(用例执行情况!C:C,"*AcuRev1320_009*",用例执行情况!Z:Z,"v1.01p05",用例执行情况!AA:AA,"Blocked") -> 0 | L20: / | M20: =COUNTIFS(用例执行情况!C:C,"*AcuRev1320_009*",用例执行情况!Z:Z,"v1.01p05",用例执行情况!AA:AA,"<>")/COUNTIFS(用例执行情况!C:C,"*AcuRev1320_009*",用例执行情况!Z:Z,"v1.01p05") -> 1
A21: 10 | B21: 电能测量 | D21: 焦任捷&王洋&王丽红&王丽红&焦任捷 | E21: =COUNTIFS(用例执行情况!C:C,"*AcuRev1320_010*") -> 101 | F21: =COUNTIFS(用例执行情况!C:C,"*AcuRev1320_010*",用例执行情况!Z:Z,"v1.01p05") -> 13 | G21: =COUNTIFS(用例执行情况!C:C,"*AcuRev1320_010*",用例执行情况!Z:Z,"v1.01p05",用例执行情况!AA:AA,"<>") -> 13 | H21: =COUNTIFS(用例执行情况!C:C,"*AcuRev1320_010*",用例执行情况!Z:Z,"v1.01p05",用例执行情况!AA:AA,"Passed") -> 13 | I21: =COUNTIFS(用例执行情况!C:C,"*AcuRev1320_010*",用例执行情况!Z:Z,"v1.01p05",用例执行情况!AA:AA,"Failed") -> 0 | J21: =COUNTIFS(用例执行情况!C:C,"*AcuRev1320_010*",用例执行情况!Z:Z,"v1.01p05",用例执行情况!AA:AA,"Unavailable") -> 0 | K21: =COUNTIFS(用例执行情况!C:C,"*AcuRev1320_010*",用例执行情况!Z:Z,"v1.01p05",用例执行情况!AA:AA,"Blocked") -> 0 | L21: / | M21: =COUNTIFS(用例执行情况!C:C,"*AcuRev1320_010*",用例执行情况!Z:Z,"v1.01p05",用例执行情况!AA:AA,"<>")/COUNTIFS(用例执行情况!C:C,"*AcuRev1320_010*",用例执行情况!Z:Z,"v1.01p05") -> 1
A22: 11 | B22: 需量测量 | D22: 刘静茹&王洋&王洋&王洋&胡赞 | E22: =COUNTIFS(用例执行情况!C:C,"*AcuRev1320_011*") -> 29 | F22: =COUNTIFS(用例执行情况!C:C,"*AcuRev1320_011*",用例执行情况!Z:Z,"v1.01p05") -> 11 | G22: =COUNTIFS(用例执行情况!C:C,"*AcuRev1320_011*",用例执行情况!Z:Z,"v1.01p05",用例执行情况!AA:AA,"<>") -> 11 | H22: =COUNTIFS(用例执行情况!C:C,"*AcuRev1320_011*",用例执行情况!Z:Z,"v1.01p05",用例执行情况!AA:AA,"Passed") -> 10 | I22: =COUNTIFS(用例执行情况!C:C,"*AcuRev1320_011*",用例执行情况!Z:Z,"v1.01p05",用例执行情况!AA:AA,"Failed") -> 1 | J22: =COUNTIFS(用例执行情况!C:C,"*AcuRev1320_011*",用例执行情况!Z:Z,"v1.01p05",用例执行情况!AA:AA,"Unavailable") -> 0 | K22: =COUNTIFS(用例执行情况!C:C,"*AcuRev1320_011*",用例执行情况!Z:Z,"v1.01p05",用例执行情况!AA:AA,"Blocked") -> 0 | L22: / | M22: =COUNTIFS(用例执行情况!C:C,"*AcuRev1320_011*",用例执行情况!Z:Z,"v1.01p05",用例执行情况!AA:AA,"<>")/COUNTIFS(用例执行情况!C:C,"*AcuRev1320_011*",用例执行情况!Z:Z,"v1.01p05") -> 1
A23: 12 | B23: 接线配置 | D23: 刘丛松&刘静茹&刘静茹&刘静茹 | E23: =COUNTIFS(用例执行情况!C:C,"*AcuRev1320_012*") -> 46 | F23: =COUNTIFS(用例执行情况!C:C,"*AcuRev1320_012*",用例执行情况!Z:Z,"v1.01p05") -> 36 | G23: =COUNTIFS(用例执行情况!C:C,"*AcuRev1320_012*",用例执行情况!Z:Z,"v1.01p05",用例执行情况!AA:AA,"<>") -> 36 | H23: =COUNTIFS(用例执行情况!C:C,"*AcuRev1320_012*",用例执行情况!Z:Z,"v1.01p05",用例执行情况!AA:AA,"Passed") -> 29 | I23: =COUNTIFS(用例执行情况!C:C,"*AcuRev1320_012*",用例执行情况!Z:Z,"v1.01p05",用例执行情况!AA:AA,"Failed") -> 5 | J23: =COUNTIFS(用例执行情况!C:C,"*AcuRev1320_012*",用例执行情况!Z:Z,"v1.01p05",用例执行情况!AA:AA,"Unavailable") -> 2 | K23: =COUNTIFS(用例执行情况!C:C,"*AcuRev1320_012*",用例执行情况!Z:Z,"v1.01p05",用例执行情况!AA:AA,"Blocked") -> 0 | L23: / | M23: =COUNTIFS(用例执行情况!C:C,"*AcuRev1320_012*",用例执行情况!Z:Z,"v1.01p05",用例执行情况!AA:AA,"<>")/COUNTIFS(用例执行情况!C:C,"*AcuRev1320_012*",用例执行情况!Z:Z,"v1.01p05") -> 1
A24: 13 | B24: 时分用电 | D24: 焦任捷&刘静茹&刘静茹 | E24: =COUNTIFS(用例执行情况!C:C,"*AcuRev1320_013*") -> 91 | F24: =COUNTIFS(用例执行情况!C:C,"*AcuRev1320_013*",用例执行情况!Z:Z,"v1.01p05") -> 51 | G24: =COUNTIFS(用例执行情况!C:C,"*AcuRev1320_013*",用例执行情况!Z:Z,"v1.01p05",用例执行情况!AA:AA,"<>") -> 51 | H24: =COUNTIFS(用例执行情况!C:C,"*AcuRev1320_013*",用例执行情况!Z:Z,"v1.01p05",用例执行情况!AA:AA,"Passed") -> 48 | I24: =COUNTIFS(用例执行情况!C:C,"*AcuRev1320_013*",用例执行情况!Z:Z,"v1.01p05",用例执行情况!AA:AA,"Failed") -> 3 | J24: =COUNTIFS(用例执行情况!C:C,"*AcuRev1320_013*",用例执行情况!Z:Z,"v1.01p05",用例执行情况!AA:AA,"Unavailable") -> 0 | K24: =COUNTIFS(用例执行情况!C:C,"*AcuRev1320_013*",用例执行情况!Z:Z,"v1.01p05",用例执行情况!AA:AA,"Blocked") -> 0 | L24: / | M24: =COUNTIFS(用例执行情况!C:C,"*AcuRev1320_013*",用例执行情况!Z:Z,"v1.01p05",用例执行情况!AA:AA,"<>")/COUNTIFS(用例执行情况!C:C,"*AcuRev1320_013*",用例执行情况!Z:Z,"v1.01p05") -> 1
A25: 14 | B25: 电能质量事件 | D25: 刘静茹&王丽红/刘丛松&刘丛松&刘静茹 | E25: =COUNTIFS(用例执行情况!C:C,"*AcuRev1320_014*") -> 137 | F25: =COUNTIFS(用例执行情况!C:C,"*AcuRev1320_014*",用例执行情况!Z:Z,"v1.01p05") -> 74 | G25: =COUNTIFS(用例执行情况!C:C,"*AcuRev1320_014*",用例执行情况!Z:Z,"v1.01p05",用例执行情况!AA:AA,"<>") -> 74 | H25: =COUNTIFS(用例执行情况!C:C,"*AcuRev1320_014*",用例执行情况!Z:Z,"v1.01p05",用例执行情况!AA:AA,"Passed") -> 59 | I25: =COUNTIFS(用例执行情况!C:C,"*AcuRev1320_014*",用例执行情况!Z:Z,"v1.01p05",用例执行情况!AA:AA,"Failed") -> 14 | J25: =COUNTIFS(用例执行情况!C:C,"*AcuRev1320_014*",用例执行情况!Z:Z,"v1.01p05",用例执行情况!AA:AA,"Unavailable") -> 1 | K25: =COUNTIFS(用例执行情况!C:C,"*AcuRev1320_014*",用例执行情况!Z:Z,"v1.01p05",用例执行情况!AA:AA,"Blocked") -> 0 | L25: / | M25: =COUNTIFS(用例执行情况!C:C,"*AcuRev1320_014*",用例执行情况!Z:Z,"v1.01p05",用例执行情况!AA:AA,"<>")/COUNTIFS(用例执行情况!C:C,"*AcuRev1320_014*",用例执行情况!Z:Z,"v1.01p05") -> 1
A26: 15 | B26: 告警功能 | D26: 刘静茹&王洋&焦任捷 | E26: =COUNTIFS(用例执行情况!C:C,"*AcuRev1320_015*") -> 92 | F26: =COUNTIFS(用例执行情况!C:C,"*AcuRev1320_015*",用例执行情况!Z:Z,"v1.01p05") -> 19 | G26: =COUNTIFS(用例执行情况!C:C,"*AcuRev1320_015*",用例执行情况!Z:Z,"v1.01p05",用例执行情况!AA:AA,"<>") -> 19 | H26: =COUNTIFS(用例执行情况!C:C,"*AcuRev1320_015*",用例执行情况!Z:Z,"v1.01p05",用例执行情况!AA:AA,"Passed") -> 17 | I26: =COUNTIFS(用例执行情况!C:C,"*AcuRev1320_015*",用例执行情况!Z:Z,"v1.01p05",用例执行情况!AA:AA,"Failed") -> 2 | J26: =COUNTIFS(用例执行情况!C:C,"*AcuRev1320_015*",用例执行情况!Z:Z,"v1.01p05",用例执行情况!AA:AA,"Unavailable") -> 0 | K26: =COUNTIFS(用例执行情况!C:C,"*AcuRev1320_015*",用例执行情况!Z:Z,"v1.01p05",用例执行情况!AA:AA,"Blocked") -> 0 | L26: / | M26: =COUNTIFS(用例执行情况!C:C,"*AcuRev1320_015*",用例执行情况!Z:Z,"v1.01p05",用例执行情况!AA:AA,"<>")/COUNTIFS(用例执行情况!C:C,"*AcuRev1320_015*",用例执行情况!Z:Z,"v1.01p05") -> 1
A27: 16 | B27: 记录与统计 | D27: 王丽红&焦任捷&王丽红&刘丛松&王洋 | E27: =COUNTIFS(用例执行情况!C:C,"*AcuRev1320_016*") -> 47 | F27: =COUNTIFS(用例执行情况!C:C,"*AcuRev1320_016*",用例执行情况!Z:Z,"v1.01p05") -> 28 | G27: =COUNTIFS(用例执行情况!C:C,"*AcuRev1320_016*",用例执行情况!Z:Z,"v1.01p05",用例执行情况!AA:AA,"<>") -> 28 | H27: =COUNTIFS(用例执行情况!C:C,"*AcuRev1320_016*",用例执行情况!Z:Z,"v1.01p05",用例执行情况!AA:AA,"Passed") -> 25 | I27: =COUNTIFS(用例执行情况!C:C,"*AcuRev1320_016*",用例执行情况!Z:Z,"v1.01p05",用例执行情况!AA:AA,"Failed") -> 3 | J27: =COUNTIFS(用例执行情况!C:C,"*AcuRev1320_016*",用例执行情况!Z:Z,"v1.01p05",用例执行情况!AA:AA,"Unavailable") -> 0 | K27: =COUNTIFS(用例执行情况!C:C,"*AcuRev1320_016*",用例执行情况!Z:Z,"v1.01p05",用例执行情况!AA:AA,"Blocked") -> 0 | L27: / | M27: =COUNTIFS(用例执行情况!C:C,"*AcuRev1320_016*",用例执行情况!Z:Z,"v1.01p05",用例执行情况!AA:AA,"<>")/COUNTIFS(用例执行情况!C:C,"*AcuRev1320_016*",用例执行情况!Z:Z,"v1.01p05") -> 1
A28: 17 | B28: DATA Log | D28: 刘丛松&王丽红&王丽红 | E28: =COUNTIFS(用例执行情况!C:C,"*AcuRev1320_017*") -> 76 | F28: =COUNTIFS(用例执行情况!C:C,"*AcuRev1320_017*",用例执行情况!Z:Z,"v1.01p05") -> 64 | G28: =COUNTIFS(用例执行情况!C:C,"*AcuRev1320_017*",用例执行情况!Z:Z,"v1.01p05",用例执行情况!AA:AA,"<>") -> 64 | H28: =COUNTIFS(用例执行情况!C:C,"*AcuRev1320_017*",用例执行情况!Z:Z,"v1.01p05",用例执行情况!AA:AA,"Passed") -> 42 | I28: =COUNTIFS(用例执行情况!C:C,"*AcuRev1320_017*",用例执行情况!Z:Z,"v1.01p05",用例执行情况!AA:AA,"Failed") -> 22 | J28: =COUNTIFS(用例执行情况!C:C,"*AcuRev1320_017*",用例执行情况!Z:Z,"v1.01p05",用例执行情况!AA:AA,"Unavailable") -> 0 | K28: =COUNTIFS(用例执行情况!C:C,"*AcuRev1320_017*",用例执行情况!Z:Z,"v1.01p05",用例执行情况!AA:AA,"Blocked") -> 0 | L28: / | M28: =COUNTIFS(用例执行情况!C:C,"*AcuRev1320_017*",用例执行情况!Z:Z,"v1.01p05",用例执行情况!AA:AA,"<>")/COUNTIFS(用例执行情况!C:C,"*AcuRev1320_017*",用例执行情况!Z:Z,"v1.01p05") -> 1
A29: 18 | B29: Input&Output | D29: 焦任捷&王洋&王丽红&刘静茹 | E29: =COUNTIFS(用例执行情况!C:C,"*AcuRev1320_018*") -> 58 | F29: =COUNTIFS(用例执行情况!C:C,"*AcuRev1320_018*",用例执行情况!Z:Z,"v1.01p05") -> 12 | G29: =COUNTIFS(用例执行情况!C:C,"*AcuRev1320_018*",用例执行情况!Z:Z,"v1.01p05",用例执行情况!AA:AA,"<>") -> 12 | H29: =COUNTIFS(用例执行情况!C:C,"*AcuRev1320_018*",用例执行情况!Z:Z,"v1.01p05",用例执行情况!AA:AA,"Passed") -> 10 | I29: =COUNTIFS(用例执行情况!C:C,"*AcuRev1320_018*",用例执行情况!Z:Z,"v1.01p05",用例执行情况!AA:AA,"Failed") -> 0 | J29: =COUNTIFS(用例执行情况!C:C,"*AcuRev1320_018*",用例执行情况!Z:Z,"v1.01p05",用例执行情况!AA:AA,"Unavailable") -> 1 | K29: =COUNTIFS(用例执行情况!C:C,"*AcuRev1320_018*",用例执行情况!Z:Z,"v1.01p05",用例执行情况!AA:AA,"Blocked") -> 1 | L29: / | M29: =COUNTIFS(用例执行情况!C:C,"*AcuRev1320_018*",用例执行情况!Z:Z,"v1.01p05",用例执行情况!AA:AA,"<>")/COUNTIFS(用例执行情况!C:C,"*AcuRev1320_018*",用例执行情况!Z:Z,"v1.01p05") -> 1
A30: 19 | B30: 计时功能 | D30: 王丽红&刘静茹&刘静茹 | E30: =COUNTIFS(用例执行情况!C:C,"*AcuRev1320_019*") -> 28 | F30: =COUNTIFS(用例执行情况!C:C,"*AcuRev1320_019*",用例执行情况!Z:Z,"v1.01p05") -> 11 | G30: =COUNTIFS(用例执行情况!C:C,"*AcuRev1320_019*",用例执行情况!Z:Z,"v1.01p05",用例执行情况!AA:AA,"<>") -> 11 | H30: =COUNTIFS(用例执行情况!C:C,"*AcuRev1320_019*",用例执行情况!Z:Z,"v1.01p05",用例执行情况!AA:AA,"Passed") -> 11 | I30: =COUNTIFS(用例执行情况!C:C,"*AcuRev1320_019*",用例执行情况!Z:Z,"v1.01p05",用例执行情况!AA:AA,"Failed") -> 0 | J30: =COUNTIFS(用例执行情况!C:C,"*AcuRev1320_019*",用例执行情况!Z:Z,"v1.01p05",用例执行情况!AA:AA,"Unavailable") -> 0 | K30: =COUNTIFS(用例执行情况!C:C,"*AcuRev1320_019*",用例执行情况!Z:Z,"v1.01p05",用例执行情况!AA:AA,"Blocked") -> 0 | L30: / | M30: =COUNTIFS(用例执行情况!C:C,"*AcuRev1320_019*",用例执行情况!Z:Z,"v1.01p05",用例执行情况!AA:AA,"<>")/COUNTIFS(用例执行情况!C:C,"*AcuRev1320_019*",用例执行情况!Z:Z,"v1.01p05") -> 1
A31: 20 | B31: 数据重置及恢复出厂设置 | D31: 刘静茹 | E31: =COUNTIFS(用例执行情况!C:C,"*AcuRev1320_020*") -> 32 | F31: =COUNTIFS(用例执行情况!C:C,"*AcuRev1320_020*",用例执行情况!Z:Z,"v1.01p05") -> 17 | G31: =COUNTIFS(用例执行情况!C:C,"*AcuRev1320_020*",用例执行情况!Z:Z,"v1.01p05",用例执行情况!AA:AA,"<>") -> 17 | H31: =COUNTIFS(用例执行情况!C:C,"*AcuRev1320_020*",用例执行情况!Z:Z,"v1.01p05",用例执行情况!AA:AA,"Passed") -> 14 | I31: =COUNTIFS(用例执行情况!C:C,"*AcuRev1320_020*",用例执行情况!Z:Z,"v1.01p05",用例执行情况!AA:AA,"Failed") -> 2 | J31: =COUNTIFS(用例执行情况!C:C,"*AcuRev1320_020*",用例执行情况!Z:Z,"v1.01p05",用例执行情况!AA:AA,"Unavailable") -> 1 | K31: =COUNTIFS(用例执行情况!C:C,"*AcuRev1320_020*",用例执行情况!Z:Z,"v1.01p05",用例执行情况!AA:AA,"Blocked") -> 0 | L31: / | M31: =COUNTIFS(用例执行情况!C:C,"*AcuRev1320_020*",用例执行情况!Z:Z,"v1.01p05",用例执行情况!AA:AA,"<>")/COUNTIFS(用例执行情况!C:C,"*AcuRev1320_020*",用例执行情况!Z:Z,"v1.01p05") -> 1
A32: 21 | B32: 网络模块 | D32: 刘静茹&王洋&焦任捷 | E32: =COUNTIFS(用例执行情况!C:C,"*AcuRev1320_021*") -> 86 | F32: =COUNTIFS(用例执行情况!C:C,"*AcuRev1320_021*",用例执行情况!Z:Z,"v1.01p05") -> 18 | G32: =COUNTIFS(用例执行情况!C:C,"*AcuRev1320_021*",用例执行情况!Z:Z,"v1.01p05",用例执行情况!AA:AA,"<>") -> 18 | H32: =COUNTIFS(用例执行情况!C:C,"*AcuRev1320_021*",用例执行情况!Z:Z,"v1.01p05",用例执行情况!AA:AA,"Passed") -> 15 | I32: =COUNTIFS(用例执行情况!C:C,"*AcuRev1320_021*",用例执行情况!Z:Z,"v1.01p05",用例执行情况!AA:AA,"Failed") -> 3 | J32: =COUNTIFS(用例执行情况!C:C,"*AcuRev1320_021*",用例执行情况!Z:Z,"v1.01p05",用例执行情况!AA:AA,"Unavailable") -> 0 | K32: =COUNTIFS(用例执行情况!C:C,"*AcuRev1320_021*",用例执行情况!Z:Z,"v1.01p05",用例执行情况!AA:AA,"Blocked") -> 0 | L32: / | M32: =COUNTIFS(用例执行情况!C:C,"*AcuRev1320_021*",用例执行情况!Z:Z,"v1.01p05",用例执行情况!AA:AA,"<>")/COUNTIFS(用例执行情况!C:C,"*AcuRev1320_021*",用例执行情况!Z:Z,"v1.01p05") -> 1
A33: 22 | B33: BACnet通信协议 | D33: 刘丛松&王丽红&王丽红 | E33: =COUNTIFS(用例执行情况!C:C,"*AcuRev1320_022*") -> 23 | F33: =COUNTIFS(用例执行情况!C:C,"*AcuRev1320_022*",用例执行情况!Z:Z,"v1.01p05") -> 20 | G33: =COUNTIFS(用例执行情况!C:C,"*AcuRev1320_022*",用例执行情况!Z:Z,"v1.01p05",用例执行情况!AA:AA,"<>") -> 20 | H33: =COUNTIFS(用例执行情况!C:C,"*AcuRev1320_022*",用例执行情况!Z:Z,"v1.01p05",用例执行情况!AA:AA,"Passed") -> 17 | I33: =COUNTIFS(用例执行情况!C:C,"*AcuRev1320_022*",用例执行情况!Z:Z,"v1.01p05",用例执行情况!AA:AA,"Failed") -> 1 | J33: =COUNTIFS(用例执行情况!C:C,"*AcuRev1320_022*",用例执行情况!Z:Z,"v1.01p05",用例执行情况!AA:AA,"Unavailable") -> 2 | K33: =COUNTIFS(用例执行情况!C:C,"*AcuRev1320_022*",用例执行情况!Z:Z,"v1.01p05",用例执行情况!AA:AA,"Blocked") -> 0 | L33: / | M33: =COUNTIFS(用例执行情况!C:C,"*AcuRev1320_022*",用例执行情况!Z:Z,"v1.01p05",用例执行情况!AA:AA,"<>")/COUNTIFS(用例执行情况!C:C,"*AcuRev1320_022*",用例执行情况!Z:Z,"v1.01p05") -> 1
