Workbook

Sheet 说明
A1: 版本号 | B1: 说明
A2: v1.0 | B2: 初版用例版本v1.0+用例发布日期(2025xxxx)区别
A3: v1.01 | B3: 后期新增、更新统一使用v1.01+更新日期(2025xxxx)区别

Sheet 测试用例
A1: 模块 | B1: 子模块 | C1: 用例编号 | D1: 用例标题 | E1: 预置条件 | F1: 测试步骤 | G1: 预期结果 | H1: 级别 | I1: 自动化 | J1: 需自动化 （是/否） | K1: 测试版本 | L1: 测试结果 | M1: 测试人员 | N1: 备注 | O1: 问题单来源
A2: 交流频率 | B2: 交流频率 | C2: Function_AcuRev1320_001_01_case1 | D2: 交流电在45 HZ 、55HZ、65 Hz，测量精度要求0.1% | E2: 1、Acuview2上位机 2、网线/RTU串口线 3、AcuRev1320电表 | F2: 1、连接AcuRev1320电表到Acuview2上，链接状态为connected 2、交流电源输入频率为45HZ。 3、Acuview2上和HMI上检查交流电频率是否在精度范围内，范围:44.955 ~ 45.045 4、交流电源输入频率为55HZ。 5、Acuview2上和HMI上检查交流电频率是否在精度范围内，范围:54.945 ~ 55.055 6、交流电源输入频率为65HZ。 7、Acuview2上检查交流电频率是否在精度范围内，范围:64.935 ~ 65.065 8、以上步骤同时在web页面上检查，交流电频率是否在精度范围内（是否与上位机及电表一致） | G2: 3、Acuview2上和HMI上检查交流电频率在精度范围内，范围:44.955 ~ 45.045 5、Acuview2上和HMI上检查交流电频率在精度范围内，范围:54.945 ~ 55.055 7、Acuview2上检查交流电频率在精度范围内，范围:64.935 ~ 65.065 8、web页面上检查交流电频率在精度范围内（与上位机及电表一致） | H2: LV2 | I2: 是
B3: 交流频率 | C3: Function_AcuRev1320_001_01_case2 | D3: 交流电在50HZ 、60 Hz，测量精度要求0.1% | E3: 1、Acuview2上位机 2、网线/RTU串口线 3、AcuRev1320电表 | F3: 1、连接AcuRev1320电表到Acuview2上，链接状态为connected 2、交流电源输入频率为50HZ。 3、Acuview2上和HMI上检查交流电频率是否在精度范围内，范围:49.95 ~ 50.05 4、交流电源输入频率为60HZ。 5、Acuview2上和HMI上检查交流电频率是否在精度范围内，范围:59.94 ~ 60.06 | G3: 3、Acuview2上和HMI上检查交流电频率在精度范围内，范围:49.95 ~ 50.05 5、Acuview2上和HMI上检查交流电频率在精度范围内，范围:59.94 ~ 60.06 | H3: LV0 | I3: 是
B4: 交流频率 | C4: Function_AcuRev1320_001_01_case3 | D4: 电表上设置60HZ, 交流电在40HZ 、70 Hz，无测量精度要求 | E4: 1、Acuview2上位机 2、网线/RTU串口线 3、AcuRev1320电表 | F4: 1、连接AcuRev1320电表到Acuview2上，链接状态为connected 1.1、电表上设置60HZ 2、交流电源输入频率为40HZ。 3、Acuview2上和HMI上检查交流电频率可以测试到频率数据，无精度要求 4、交流电源输入频率为70HZ。 5、Acuview2上和HMI上检查交流电频率可以测试到频率数据，无精度要求 | G4: 3、Acuview2上和HMI上检查交流电频率可以测试到频率数据，无精度要求 5、Acuview2上和HMI上检查交流电频率可以测试到频率数据，无精度要求 | H4: LV3 | I4: 是
B5: 交流频率 | C5: Function_AcuRev1320_001_01_case4 | D5: 关闭输出后，电表不会有频率显示 | E5: 1、Acuview2上位机 2、网线/RTU串口线 3、AcuRev1320电表 | F5: 1、输出50HZ频率 2、关闭源输出 3、HMI查看系统频率 4、查看上位机及web页面，频率显示是多少 | G5: 3、关闭源输出，频率显示0 4、关闭源输出，频率显示0 | H5: LV1
B6: 交流频率 | C6: Function_AcuRev1320_001_01_case5 | D6: 验证上位机Real-time 聚合数据的各个页面，测量频率正常 | E6: 1、Acuview2上位机 2、网线/RTU串口线 3、AcuRev1320电表 4、接线方式3E4w y | F6: 1、 交流电源输入频率为50HZ。 2、 等待4 小时 3、 检查Real-Time Metering （200ms）、Real-Time Metering （3s）、Real-Time Metering （10min）、Real-Time Metering （2hr）、High-Speed Metering 页面的频率 | G6: 3、 各个页面频率测量值均为50HZ 备注： 除了200ms页面，其他页面没有精度要求，测量值接近不能偏离太远 | H6: LV1
A7: 交流电压 | B7: 线-地电压(相电压)验证 | C7: Function_AcuRev1320_002_01_case1 | D7: 交流电Van、Vbn、Vcn输入额定电压分别均为69V,120V,测量Van、Vbn、Vcn、Vlnavg满足精度要求0.1% | E7: 1、Acuview2上位机 2、网线/RTU串口线 3、AcuRev1320电表 4、接线方式3E4w y y | F7: 1、连接AcuRev1320电表到Acuview2上，链接状态为connected 2、交流电源输入相电压Van、Vbn、Vcn的额定电压为69V。 3、Acuview2上和HMI上检查交流电相电压是否均在精度范围内， Van、Vbn、Vcn范围(V):68.931 ~ 69.069， Vlnavg范围(V)：68.931 ~ 69.069 4、交流电源输入相电压Van、Vbn、Vcn的额定电压为120V。 5、Acuview2上和HMI上检查交流电相电压是否均在精度范围内，范围(V):119.88 ~ 120.12， Vlnavg范围(V)：119.88 ~ 120.12 6、以上步骤中，检查web页面与Acuview2、HMI上交流电相电压是否一致，是否均在精度范围内 | G7: 3、Acuview2上和HMI上检查交流电相电压均在精度范围内，范围(V):68.931 ~ 69.069，Vlnavg范围(V)：68.931 ~ 69.069 5、Acuview2上和HMI上检查交流电相电压均在精度范围内，范围(V):119.88 ~ 120.12，Vlnavg范围(V)：119.88 ~ 120.12 6、以上步骤中，检查web页面与Acuview2、HMI上交流电相电压一致，均在精度范围内 | H7: LV0 | I7: 是 | J7: Y
B8: 线-地电压(相电压)验证 | C8: Function_AcuRev1320_002_01_case2 | D8: 交流电Van、Vbn、Vcn输入额定电压分别均为230V,347V,测量Van、Vbn、Vcn、Vlnavg满足精度要求0.1% | E8: 1、Acuview2上位机 2、网线/RTU串口线 3、AcuRev1320电表 4、接线方式3E4w y y | F8: 1、连接AcuRev1320电表到Acuview2上，链接状态为connected 2、交流电源输入相电压Van、Vbn、Vcn的额定电压为230V。 3、Acuview2上和HMI上检查交流电相电压是否均在精度范围内，范围(V):229.77 ~ 230.23， Vlnavg范围(V)：229.77 ~ 230.23 4、交流电源输入相电压Van、Vbn、Vcn的额定电压为347V。 5、Acuview2上和HMI上检查交流电相电压是否均在精度范围内，范围(V):346.653 ~ 347.347， Vlnavg范围(V)：346.653 ~ 347.347 6、以上步骤中，检查web页面与Acuview2、HMI上交流电相电压是否一致，是否均在精度范围内 | G8: 3、Acuview2上和HMI上检查交流电相电压均在精度范围内，范围(V):229.77 ~ 230.23， Vlnavg范围(V)：229.77 ~ 230.23 5、Acuview2上和HMI上检查交流电相电压均在精度范围内，范围(V):346.653 ~ 347.347， Vlnavg范围(V)：346.653 ~ 347.347 6、以上步骤中，检查web页面与Acuview2、HMI上交流电相电压一致，均在精度范围内 | H8: LV1 | I8: 是 | J8: Y
B9: 线-地电压(相电压)验证 | C9: Function_AcuRev1320_002_01_case3 | D9: 交流电Van、Vbn、Vcn输入启动电压分别均为10.2V、20V,电表有测量值,测量Van、Vbn、Vcn、Vlnavg没有精度要求 | E9: 1、Acuview2上位机 2、网线/RTU串口线 3、AcuRev1320电表 4、接线方式3E4w y y | F9: 1、连接AcuRev1320电表到Acuview2上，链接状态为connected 2、交流电源输入相电压Van、Vbn、Vcn的额定电压为10.2V。 3、Acuview2上和HMI上检查交流电相电压是否有测量显示，精度没有要求 4、交流电源输入相电压Van、Vbn、Vcn的额定电压为20V。 5、Acuview2上和HMI上检查交流电相电压是否有测量显示，精度没有要求 | G9: 3、Acuview2上和HMI上检查交流电相电压有测量显示，没有精度要求 5、Acuview2上和HMI上检查交流电相电压有测量显示，没有精度要求 | H9: LV3 | I9: 是 | J9: Y
B10: 线-地电压(相电压)验证 | C10: Function_AcuRev1320_002_01_case4 | D10: 交流电Van、Vbn、Vcn输入电压分别均为0V，1V，9V,电表Van、Vbn、Vcn、Vlnavg无测量值 | E10: 1、Acuview2上位机 2、网线/RTU串口线 3、AcuRev1320电表 4、接线方式3E4w y y | F10: 1、连接AcuRev1320电表到Acuview2上，链接状态为connected 2、交流电源输入相电压Van、Vbn、Vcn的额定电压为0V。 3、Acuview2上和HMI上检查交流电相电压是否为0V 4、交流电源输入相电压Van、Vbn、Vcn的额定电压为1V。 5、Acuview2上和HMI上检查交流电相电压是否为0V，不考虑精度 6、交流电源输入相电压Van、Vbn、Vcn的额定电压为9V。 7、Acuview2上和HMI上检查交流电相电压是否为0V，不考虑精度 8、查看web页面数据是否与上位机及电表数据一致 | G10: 3、5、7、Acuview2上和HMI上检查交流电相电压为0V 6、查看web页面数据是否与上位机及电表数据一致 | H10: LV4 | J10: Y
B11: 线-地电压(相电压)验证 | C11: Function_AcuRev1320_002_01_case5 | D11: 交流电Van、Vbn、Vcn输入额定电压为(69V,120V,230V),测量Van、Vbn、Vcn、Vlnavg满足精度要求0.1% | E11: 1、Acuview2上位机 2、网线/RTU串口线 3、AcuRev1320电表 4、接线方式3E4w y | F11: 1、连接AcuRev1320电表到Acuview2上，链接状态为connected 2、交流电源输入相电压Van、Vbn、Vcn的额定电压分别为(69V,120V,230V)。 3、Acuview2上和HMI上检查交流电相电压是否均在精度范围内，Van范围(V):68.931 ~ 69.069，Vbn范围(V):119.88 ~ 120.12，Vcn范围(V):229.77 ~ 230.23，Vlnavg范围(V):139.527 ~ 139.8063333 4、检查web页面上是否与Acuview2、HMI上交流电相电压一致，是否在范围内 | G11: 3、Acuview2上和HMI上检查交流电相电压均在精度范围内，Van范围(V):68.931 ~ 69.069，Vbn范围(V):119.88 ~ 120.12，Vcn范围(V):229.77 ~ 230.23，Vlnavg范围(V):139.527 ~ 139.8063333 4、检查web页面上与Acuview2、HMI上交流电相电压一致，在范围内 | H11: LV1 | I11: 是
B12: 线-地电压(相电压)验证 | C12: Function_AcuRev1320_002_01_case6_1 | D12: 交流电Van、Vbn、Vcn输入额定电压为(100V,100V,100V),φA、φB、φC分别为(0°、240°、120°)，断开交流源输入，Van、Vbn、Vcn、Vlnavg测量值全为0V | E12: 1、Acuview2上位机 2、网线/RTU串口线 3、AcuRev1320电表 4、接线方式3E4w y y | F12: 1、连接AcuRev1320电表到Acuview2上，链接状态为connected 2、交流电Van、Vbn、Vcn输入额定电压为(100V,100V,100V),φA、φB、φC分别为(0°、240°、120°) 3、Acuview2上和HMI上检查交流电相电压是否均在精度范围内 4、断开交流源输入 5、立即Acuview2上和HMI上检查交流电相电压Van、Vbn、Vcn、Vlnavg测量值全为0V 6, 反复执行步骤2~5， 5次。功能正常 | G12: 3、Acuview2上和HMI上检查交流电相电压均在精度0.1%范围内 5、立即Acuview2上和HMI上检查交流电相电压Vab，Vac、Vbc、Vllavg测量值全为0V 6, 反复执行步骤2~5， 5次。功能正常 | H12: LV4
B13: 线-地电压(相电压)验证 | C13: Function_AcuRev1320_002_01_case6_2 | D13: 交流电Van、Vbn、Vcn输入额定电压为(220V,220V,220V)顺序，且φA、φB、φC分别为(0°、120°、240°)，Van、Vbn、Vcn、Vlnavg测量值满足精度要求0.1% | E13: 1、Acuview2上位机 2、网线/RTU串口线 3、AcuRev1320电表 4、接线方式3E4w y y | F13: 1、连接AcuRev1320电表到Acuview2上，链接状态为connected 2、交流电源输入相电压Van、Vbn、Vcn的额定电压为220V。 3、电表相序设置为ABC，φA、φB、φC分别为(0°、120°、240°) 4、Acuview2上和HMI上检查交流电相电压Van、Vbn、Vcn、Vlnavg测量值是否满足精度要求0.1% | G13: 4、Acuview2上和HMI上检查交流电相电压均在精度范围内，范围(V):219.7800 ~ 220.2200 ， Vlnavg范围(V)：219.7800 ~ 220.2200 | H13: LV2 | I13: 是
B14: 线-地电压(相电压)验证 | C14: Function_AcuRev1320_002_01_case6_3 | D14: 交流电Van、Vbn、Vcn输入额定电压为(220V,220V,220V),逆序，且φA、φB、φC分别为(0°、120°、240°)，Van、Vbn、Vcn、Vlnavg测量值满足精度要求0.1% | E14: 1、Acuview2上位机 2、网线/RTU串口线 3、AcuRev1320电表 4、接线方式3E4w y y | F14: 1、连接AcuRev1320电表到Acuview2上，链接状态为connected 2、交流电源输入相电压Van、Vbn、Vcn的额定电压为220V。 3、电表相序设置为ACB，φA、φB、φC分别为(0°、120°、240°) 4、Acuview2上和HMI上检查交流电相电压Van、Vbn、Vcn、Vlnavg测量值是否满足精度要求0.1% | G14: 4、Acuview2上和HMI上检查交流电相电压均在精度范围内，范围(V):219.7800 ~ 220.2200 ， Vlnavg范围(V)：219.7800 ~ 220.2200 | H14: LV2 | I14: 是
B15: 线-地电压(相电压)验证 | C15: Function_AcuRev1320_002_01_case6_4 | D15: 交流电Van、Vbn、Vcn输入额定电压为(120V,120V,120V)顺序，且φA、φB、φC分别为(0°、130°、250°)，Van、Vbn、Vcn、Vlnavg测量值满足精度要求0.1% | E15: 1、Acuview2上位机 2、网线/RTU串口线 3、AcuRev1320电表 4、接线方式3E4w y y | F15: 1、连接AcuRev1320电表到Acuview2上，链接状态为connected 2、交流电源输入相电压Van、Vbn、Vcn的额定电压为120V。 3、电表相序设置为ABC，φA、φB、φC分别为(0°、130°、250°) 4、Acuview2上和HMI上检查交流电相电压Van、Vbn、Vcn、Vlnavg测量值是否满足精度要求0.1% 5、检查web页面上是否与Acuview2、HMI上交流电相电压一致，是否在范围内 | G15: 4、Acuview2上和HMI上检查交流电相电压均在精度范围内，范围(V):119.8800 ~ 120.1200 ， Vlnavg范围(V)：119.8800 ~ 120.1200 5、检查web页面上与Acuview2、HMI上交流电相电压一致，在范围内 | H15: LV2 | I15: 是
B16: 线-地电压(相电压)验证 | C16: Function_AcuRev1320_002_01_case7_1 | D16: 只加电压,看电压正常精度正常， 电流测量值为0 | E16: 1、Acuview2上位机 2、网线/RTU串口线 3、AcuRev1320电表 4、接线方式3E4w y y | F16: 1、连接AcuRev1320电表到Acuview2上，链接状态为connected 2、交流电源输入相电压Van、Vbn、Vcn的额定电压为120V。 3、电表相序设置为ABC，φA、φB、φC分别为(0°、240°、120°) 4、电表未接电流。 5、Acuview2上和HMI上检查交流电相电压Van、Vbn、Vcn、Vlnavg测量值是否满足精度要求0.1% 6、ABC三相, 输入通道input1-3、电流是否均为0A | G16: 5、Acuview2上和HMI上检查交流电相电压Van、Vbn、Vcn、Vlnavg测量值满足精度要求0.1% 6、ABC三相, 输入通道input1-3电流均为0A | H16: LV3
B17: 线-地电压(相电压)验证 | C17: Function_AcuRev1320_002_01_case7_2 | D17: 电压为0，只加电流, 电流测量值正常，但不计算夹角、功率、能量；电压为10V，电流测量值正常，且计算夹角、功率、能量 | E17: 1、Acuview2上位机 2、网线/RTU串口线 3、AcuRev1320电表 4、接线方式3E4w y y | F17: 1、连接AcuRev1320电表到Acuview2上，链接状态为connected 2、交流电源输入相电压Van、Vbn、Vcn的额定电压为0V。 3、电表相序设置为ABC，φA、φB、φC分别为(0°、240°、120°) 4、input1-3 设置为3A 5、Acuview2上和HMI上检查交流电相电压Van、Vbn、Vcn、Vlnavg测量值是否为0V。 6、ABC三相, 输入通道input1-3电流均为3A 7、交流电源输入相电压Van、Vbn、Vcn的额定电压为10V。 8、电表相序设置为ABC，φA、φB、φC分别为(0°、240°、120°) 9、input1-3 设置为3A 10、ABC三相, 输入通道input1-3电流均为3A | G17: 5、Acuview2上和HMI上检查交流电相电压Van、Vbn、Vcn、Vlnavg测量值为0V 6、ABC三相, 输入通道input1-3、均为3A，同时功率、夹角、能量不计算 10、ABC三相, 输入通道input1-3、电流均为3A，同时计算功率、夹角、能量 | H17: LV3
B18: 线-地电压(相电压)验证 | C18: Function_AcuRev1320_002_01_case7_3 | D18: 电表接入电压线束，但交流源没有开机的情况下，电表可以测试到电压值为0V | E18: 1、Acuview2上位机 2、网线/RTU串口线 3、AcuRev1320电表 4、接线方式3E4w y y | F18: 1、电表接入电压线束，但交流源没有开机的情况下， 2、检查电表可以测试到电压值是否为0V | G18: 2、检查电表可以测试到电压值为0V | H18: LV3
B19: 线-地电压(相电压)验证 | C19: Function_AcuRev1320_002_01_case8 | D19: 交流电Van、Vbn、Vcn输入额定电压分别均为480V （电气规格支持的最大相电压480V）,测量Van、Vbn、Vcn、Vlnavg满足精度要求0.1% | E19: 1、Acuview2上位机 2、网线/RTU串口线 3、AcuRev1320电表 4、接线方式3E4w y y | F19: 1、连接AcuRev1320电表到Acuview2上，链接状态为connected 2、交流电源输入相电压Van、Vbn、Vcn的额定电压为480V。 3、Acuview2上和HMI上检查交流电相电压是否均在精度范围内， Van、Vbn、Vcn范围(V):479.52 ~ 480.48， Vlnavg范围(V)：479.52 ~ 480.48 4、检查web页面与Acuview2、HMI上交流电相电压是否一致，是否均在精度范围内 | G19: 3、Acuview2上和HMI上检查交流电相电压均在精度范围内，范围(V):Van、Vbn、Vcn范围(V):479.52 ~ 480.48， Vlnavg范围(V)：479.52 ~ 480.48 4、 以上步骤中，检查web页面与Acuview2、HMI上交流电相电压一致，均在精度范围内 | H19: LV2
B20: 线-线电压(线电压)验证 | C20: Function_AcuRev1320_002_02_case1 | D20: 交流电Van、Vbn、Vcn均输入电压69V和120V, 测量Vab，Vac、Vbc、Vllavg精度均满足要求0.1% | E20: 1、Acuview2上位机 2、网线/RTU串口线 3、AcuRev1320电表 4、接线方式3E4w y y | F20: 1、连接AcuRev1320电表到Acuview2上，链接状态为connected 2、交流电源输入相电压Van、Vbn、Vcn的额定电压为69V。 3、Acuview2上和HMI上检查交流电相电压是否均在精度范围内，范围(V):119.388492 ~ 119.627508， Vllavg范围(V)：119.388492 ~ 119.627508 4、交流电源输入相电压Van、Vbn、Vcn的额定电压为120V。 5、Acuview2上和HMI上检查交流电相电压是否均在精度范围内，范围(V):207.63216 ~ 208.04784， Vllavg范围(V)：207.63216 ~ 208.04784 6、以上步骤中，检查web页面是否与Acuview2上、hmi数据保持一致，是否均在范围内 | G20: 3、Acuview2上和HMI上检查交流电相电压均在精度范围内，范围(V):119.388492 ~ 119.627508， Vllavg范围(V)：119.388492 ~ 119.627508 5、Acuview2上和HMI上检查交流电相电压均在精度范围内，范围(V):207.63216 ~ 208.04784， Vllavg范围(V)：207.63216 ~ 208.04784 6、以上步骤中，检查web页面与Acuview2上、hmi数据保持一致，均在范围内 | H20: LV0 | I20: 是 | J20: Y
B21: 线-线电压(线电压)验证 | C21: Function_AcuRev1320_002_02_case2 | D21: 交流电Van、Vbn、Vcn均输入电压230V和347V,测量Vab，Vac、Vbc、Vllavg精度均满足要求0.1% | E21: 1、Acuview2上位机 2、网线/RTU串口线 3、AcuRev1320电表 4、接线方式3E4w y y | F21: 1、连接AcuRev1320电表到Acuview2上，链接状态为connected 2、交流电源输入相电压Van、Vbn、Vcn的额定电压为230V。 3、Acuview2上和HMI上检查交流电相电压是否均在精度范围内，范围(V):397.96164 ~ 398.75836， Vllavg范围(V)：397.96164 ~ 398.75836 4、交流电源输入相电压Van、Vbn、Vcn的额定电压为。 5、Acuview2上和HMI上检查交流电相电压是否均在精度范围内347，范围(V):600.402996 ~ 601.605004， Vllavg范围(V)：600.402996 ~ 601.605004 6、以上步骤中，检查web页面是否与Acuview2上、hmi数据保持一致，是否均在范围内 | G21: 3、Acuview2上和HMI上检查交流电相电压均在精度范围内，范围(V):397.96164 ~ 398.75836， Vllavg范围(V)：397.96164 ~ 398.75836 5、Acuview2上和HMI上检查交流电相电压均在精度范围内347，范围(V):600.402996 ~ 601.605004， Vllavg范围(V)：600.402996 ~ 601.605004 6、以上步骤中，检查web页面与Acuview2上、hmi数据保持一致，均在范围内 | H21: LV1 | I21: 是 | J21: Y
B22: 线-线电压(线电压)验证 | C22: Function_AcuRev1320_002_02_case3 | D22: 交流电Van、Vbn、Vcn均输入启动电压10.2V、20V,电表有测量值，测量Vab，Vac、Vbc、Vllavg精度没有要求 | E22: 1、Acuview2上位机 2、网线/RTU串口线 3、AcuRev1320电表 4、接线方式3E4w y y | F22: 1、连接AcuRev1320电表到Acuview2上，链接状态为connected 2、交流电源输入相电压Van、Vbn、Vcn的额定电压为10.2V。 3、Acuview2上和HMI上检查交流电线电压是否有测量显示， 精度没有要求 4、交流电源输入相电压Van、Vbn、Vcn的额定电压为20V。 5、Acuview2上和HMI上检查交流电线电压是否有测量显示, 精度没有要求 | G22: 3、Acuview2上和HMI上检查交流电线电压有测量显示，精度没有要求 5、Acuview2上和HMI上检查交流电线电压有测量显示，精度没有要求 | H22: LV3 | I22: 是 | J22: Y
B23: 线-线电压(线电压)验证 | C23: Function_AcuRev1320_002_02_case4 | D23: 交流电Van、Vbn、Vcn均输入电压0V，1V，9V,电表Vab，Vac、Vbc、Vllavg无测量值 | E23: 1、Acuview2上位机 2、网线/RTU串口线 3、AcuRev1320电表 4、接线方式3E4w y y | F23: 1、连接AcuRev1320电表到Acuview2上，链接状态为connected 2、交流电源输入相电压Van、Vbn、Vcn的额定电压为0V。 3、Acuview2上和HMI上检查交流电线电压是否为0V 4、交流电源输入相电压Van、Vbn、Vcn的额定电压为1V。 5、Acuview2上和HMI上检查交流电线电压是否为0V 6、交流电源输入相电压Van、Vbn、Vcn的额定电压为9V。 7、Acuview2上和HMI上检查交流电线电压是否为0V 6、以上步骤中，检查web页面数据是否符合要求 | G23: 3、5、7、Acuview2上和HMI上检查交流电线电压为0V 6、以上步骤中，检查web页面数据符合要求 | H23: LV3 | I23: 是 | J23: Y
B24: 线-线电压(线电压)验证 | C24: Function_AcuRev1320_002_02_case5 | D24: 交流电Van、Vbn、Vcn输入额定电压为(69V,120V,230V), θA、θB、θC分别为(0°、60°、120°)测量Vab，Vac、Vbc、Vllavg满足精度要求0.1% | E24: 1、Acuview2上位机 2、网线/RTU串口线 3、AcuRev1320电表 4、接线方式3E4w y y | F24: 1、连接AcuRev1320电表到Acuview2上，链接状态为connected 2、交流电源输入相电压Van、Vbn、Vcn的电压为(69V,120V,230V), θA、θB、θC分别为(0°、60°、120°)。 3、Acuview2上和HMI上检查交流电相电压是否均在精度范围内， 4、以上步骤中，检查web页面数据是否符合要求 | G24: 3、Acuview2上和HMI上检查交流电相电压均在精度范围内 4、以上步骤中，检查web页面数据符合要求 备注: 也可以使用excel公式计算任意角度和电压的线电压。 | H24: LV2
B25: 线-线电压(线电压)验证 | C25: Function_AcuRev1320_002_02_case6_1 | D25: 交流电Van、Vbn、Vcn输入额定电压为(120V,120V,120V),逆序，且φA、φB、φC分别为(0°、260°、140°)，Vab、Vac、Vbc、Vllavg测量值满足精度要求0.1% | E25: 1、Acuview2上位机 2、网线/RTU串口线 3、AcuRev1320电表 4、接线方式3E4w y y | F25: 1、连接AcuRev1320电表到Acuview2上，链接状态为connected 2、交流电源输入相电压Van、Vbn、Vcn的额定电压为120V。 3、电表相序设置为ACB，φA、φB、φC分别为(0°、260°、140°) 4、Acuview2上和HMI上检查交流电相电压Vab、Vac、Vbc、Vllavg测量值是否满足精度要求0.1% | G25: 4、Acuview2上和HMI上检查交流电相电压均在精度范围内，详细如下: Vab：183.8507 183.6668 ~ 184.0345 Vcb：207.8461 207.6383 ~ 208.0539 Vca：225.5262 225.3007 ~ 225.7518 Vlnavg：205.7410 205.5353 ~ 205.9467 | H25: LV2 | I25: 是
B26: 线-线电压(线电压)验证 | C26: Function_AcuRev1320_002_02_case6_2 | D26: 交流电Van、Vbn、Vcn输入额定电压为(220V,220V,220V),顺序，且φA、φB、φC分别为(0°、260°、140°)，Vab、Vac、Vbc、Vllavg测量值满足精度要求0.1% | E26: 1、Acuview2上位机 2、网线/RTU串口线 3、AcuRev1320电表 4、接线方式3E4w y y | F26: 1、连接AcuRev1320电表到Acuview2上，链接状态为connected 2、交流电源输入相电压Van、Vbn、Vcn的额定电压为120V。 3、电表相序设置为ABC，φA、φB、φC分别为(0°、260°、140°) 4、Acuview2上和HMI上检查交流电相电压Vab、Vac、Vbc、Vllavg测量值是否满足精度要求0.1% | G26: 4、Acuview2上和HMI上检查交流电相电压均在精度范围内，详细如下: 备注: 也可以使用excel公式计算任意角度和电压的线电压。 | H26: LV2 | I26: 是
B27: 线-线电压(线电压)验证 | C27: Function_AcuRev1320_002_02_case7 | D27: 交流电Van、Vbn、Vcn输入额定电压分别均为479.2V （电气规格支持的最大线电压830）,测量Vab、Vac、Vbc、Vllavg测量值满足精度要求0.1% | E27: 1、Acuview2上位机 2、网线/RTU串口线 3、AcuRev1320电表 4、接线方式3E4w y y | F27: 1、连接AcuRev1320电表到Acuview2上，链接状态为connected 2、交流电源输入相电压Van、Vbn、Vcn的额定电压为479.2V 3、电表相序设置为ABC，φA、φB、φC分别为(0°、240°、120°) 4、Acuview2上和HMI上检查交流电相电压Vab、Vac、Vbc、Vllavg测量值是否满足精度要求0.1% | G27: 4、Acuview2上和HMI上检查交流电相电压均在精度范围内，详细如下: Vab：829.8255 828.9957 ~ 830.6554 Vcb：829.8255 828.9957 ~ 830.6554 Vca：829.8255 828.9957 ~ 830.6554 Vlnavg：829.8255 828.9957 ~ 830.6554 | H27: LV2
B28: 聚合页面的电压测量值验证 | C28: Function_AcuRev1320_002_03_case1 | D28: 交流电Van、Vbn、Vcn 输入电压120V，验证上位机Real-time 聚合数据的各个页面，Va、Vb、Vc、VlnAvg、Vab、Vac、Vca、Vllavg测量正常 | E28: 1、Acuview2上位机 2、网线/RTU串口线 3、AcuRev1320电表 4、接线方式3E4w y | F28: 1、连接AcuRev1320电表到Acuview2上，链接状态为connected 2、交流电源输入相电压Van、Vbn、Vcn的额定电压为120V。 3、等待4小时 4、 检查检查Real-Time Metering （200ms）、Real-Time Metering （3s）、Real-Time Metering （10min）、Real-Time Metering （2hr）、High-Speed Metering 页面的Va、Vb、Vc、VlnAvg、Vab、Vac、Vca、Vllavg测量值 | G28: 4、 各个页面相电压及其平均值测量值均为120V；线电压及其平均值为207.846V 备注： 除了200ms页面，其他页面没有精度要求，测量值接近不能偏离太远 | H28: LV2
B29: 聚合页面的电压测量值验证 | C29: Function_AcuRev1320_002_03_case2 | D29: 交流电Van、Vbn、Vcn 输入电压120V，验证上位机Real-Time Metering （10min）页面的刷新逻辑 | E29: 1、Acuview2上位机 2、网线/RTU串口线 3、AcuRev1320电表 4、接线方式3E4w y | F29: 1、连接AcuRev1320电表到Acuview2上，链接状态为connected 2、配置电表时间为任意日期的10:05 3、交流电源输入相电压Van、Vbn、Vcn的额定电压为120V。 4、10:10时检查上位机的Real-Time Metering （10min）页面 5、交流电源输入相电压Van、Vbn、Vcn的额定电压为150V。 6、10:20时检查上位机的Real-Time Metering （10min）页面 | G29: 4、 Real-Time Metering （10min）页面相电压及其平均值测量值均为120V；线电压及其平均值为207.846V 6、 Real-Time Metering （10min）页面相电压及其平均值测量值均为150V；线电压及其平均值为259.8076V 备注： 除了200ms页面，其他页面没有精度要求，测量值接近不能偏离太远 | H29: LV2
B30: 聚合页面的电压测量值验证 | C30: Function_AcuRev1320_002_03_case3 | D30: 交流电Van、Vbn、Vcn 输入电压120V，验证上位机Real-Time Metering （2hr）页面的刷新逻辑 | E30: 1、Acuview2上位机 2、网线/RTU串口线 3、AcuRev1320电表 4、接线方式3E4w y | F30: 1、连接AcuRev1320电表到Acuview2上，链接状态为connected 2、配置电表时间为任意日期的10:05 3、交流电源输入相电压Van、Vbn、Vcn的额定电压为120V。 4、10:10时检查上位机的Real-Time Metering （10min）页面 5、12:10时检查上位机的Real-Time Metering （10min）页面 | G30: 4、 Real-Time Metering （10min）页面相电压及其平均值测量值均为120V；线电压及其平均值为207.846V 5、 Real-Time Metering （2hr）页面相电压及其平均值测量值均为150V；线电压及其平均值为259.8076V | H30: LV2
A31: 交流电流 | B31: 相电流测量验证 | C31: Function_AcuRev1320_003_01_case1 | D31: CT选型5A/333mV，3E4WY，输入三路电流分别为(5A、5A，5A)，在上位机上分别配置为对应A相、B相、C相，测量Ia,Ib,Ic,Iavg满足精度0.1% | E31: 1、Acuview2上位机 2、网线/RTU串口线 3、AcuRev1320电表 4、接线方式3E4w y y | F31: 1、连接AcuRev1320电表到Acuview2上，链接状态为connected 2、输入三路电流分别为(5A、5A，5A)，在上位机上分别配置为对应A相、B相、C相 3、Acuview2上和HMI上检查交流电相电流是否均在精度0.1%范围内 4、检查web页面上，电流数据是否与Acuview2、HMI一致，是否均在范围内 | G31: 3、Acuview2上和HMI上检查交流电相电流均在精度范围内 4、检查web页面上，电流数据与Acuview2、HMI一致，均在范围内 Ia： 4.995 ~ 5.005 Ib: 4.995 ~ 5.005 Ic: 4.995 ~ 5.005 Iavg: 4.995 ~ 5.005 | H31: LV0 | I31: 是 | J31: Y
B32: 相电流测量验证 | C32: Function_AcuRev1320_003_01_case2 | D32: CT选型5A/333mV，输入三路电流分别为（0.05，0.05，0.05）,在上位机上分别配置为对应A相、B相、C相，测量Ia,Ib,Ic,Iavg满足精度0.1% | E32: 1、Acuview2上位机 2、网线/RTU串口线 3、AcuRev1320电表 4、接线方式3E4w y y | F32: 1、连接AcuRev1320电表到Acuview2上，链接状态为connected 2、输入三路电流分别为（0.05，0.05，0.05）,在上位机上分别配置为对应A相、B相、C相。 3、Acuview2上和HMI上检查交流电相电流是否均在精度0.1%范围内 | G32: 3、Acuview2上和HMI上检查交流电相电流均在精度范围内 Ia： 0.04995 ~ 0.05005 Ib: 0.04995 ~ 0.05005 Ic: 0.04995 ~ 0.05005 Iavg: 0.04995 ~ 0.05005 | H32: LV0 | I32: 是 | J32: Y
B33: 相电流测量验证 | C33: Function_AcuRev1320_003_01_case3 | D33: CT选型5A/333mV，输入一路电流分别为（6A），在上位机均配置为对应A相，测量Ia,Ib,Ic,Iavg满足精度0.1% | E33: 1、Acuview2上位机 2、网线/RTU串口线 3、AcuRev1320电表 4、接线方式3E4w y y | F33: 1、连接AcuRev1320电表到Acuview2上，链接状态为connected 2、输入一路电流分别为（6A），在上位机均配置为对应A相 3、Acuview2上和HMI上检查交流电相电流是否均在精度0.1%范围内 | G33: 3、Acuview2上和HMI上检查交流电相电流均在精度范围内 Ia： 5.994 ~ 6.006 Ib: 0 ~ 0 Ic: 0 ~ 0 Iavg: 1.998 ~ 2.002 | H33: LV1 | I33: 是
B34: 相电流测量验证 | C34: Function_AcuRev1320_003_01_case4 | D34: CT选型5A/333mV，输入两路电流分别为(4A、5A),在上位机均配置为对应B相和C相，测量Ia,Ib,Ic,Iavg满足精度0.1% | E34: 1、Acuview2上位机 2、网线/RTU串口线 3、AcuRev1320电表 4、接线方式3E4w y y | F34: 1、连接AcuRev1320电表到Acuview2上，链接状态为connected 2、输入两路电流分别为(4A、5A),在上位机均配置为对应B相和C相。 3、Acuview2上和HMI上检查交流电相电流是否均在精度0.1%范围内 | G34: 3、Acuview2上和HMI上检查交流电相电流均在精度范围内 Ia： 0 ~ 0 Ib: 3.996 ~ 4.004 Ic: 4.995 ~ 5.005 Iavg: 2.997 ~ 3.003 | H34: LV1 | I34: 是
B35: 相电流测量验证 | C35: Function_AcuRev1320_003_01_case5 | D35: CT选型5A/333mV，输入三路电流(0.005A、0.03A、0.00375A)，在上位机上分别配置为对应A相、B相、C相，测量Ia,Ib,Ic,Iavg有显示值，无精度要求 | E35: 1、Acuview2上位机 2、网线/RTU串口线 3、AcuRev1320电表 | F35: 1、连接AcuRev1320电表到Acuview2上，链接状态为connected 2、输入三路电流(0.005A、0.03A、0.00375A)，在上位机上分别配置为对应A相、B相、C相。 3、Acuview2上和HMI上检查交流电相电流是否均在精度0.1%范围内 | G35: 3、Acuview2上和HMI上检查交流电相电流有测量数据，无精度要求。 | H35: LV2 | I35: 是 | J35: Y
B36: 相电流测量验证 | C36: Function_AcuRev1320_003_01_case6 | D36: CT选型5A/333mV，输入三路电流(0.003A、0.00370A、0A)，在上位机上分别配置为对应A相、B相、C相，测量Ia,Ib,Ic,Iavg測量值为0 | E36: 1、Acuview2上位机 2、网线/RTU串口线 3、AcuRev1320电表 | F36: 1、连接AcuRev1320电表到Acuview2上，链接状态为connected 2、输入三路电流(0.003A、0.00370A、0A)，在上位机上分别配置为对应A相、B相、C相。 3、Acuview上检查交流电相电流是否均均为0A | G36: 3、Acuview2上和HMI上检查交流电相电流均为0A，不要求精度 2026/3/23： 截止电流为0.375的0.9倍 | H36: LV3 | I36: 是 | J36: Y
B37: 相电流测量验证 | C37: Function_AcuRev1320_003_01_case7 | D37: CT选型5A/333mV，输入三路电流分别为(3A、4A，5A)，顺序ABC，相角设置为(0°、240°、120°)，电表设置电流分别为Positive、Negative，在上位机上分别配置为对应A相、B相、C相，测量Ia,Ib,Ic,Iavg满足精度0.1% | E37: 1、Acuview2上位机 2、网线/RTU串口线 3、AcuRev1320电表 | F37: 1、连接AcuRev1320电表到Acuview2上，链接状态为connected 2、输入三路电流分别为(3A、4A，5A)，在上位机上分别配置为对应A相、B相、C相 3、电表上设置为顺序ABC， 相角设置为(0°、240°、120°) 4、电表设置电流方向为Positive 5、Acuview2上和HMI上检查交流电相电流是否均在精度0.1%范围内 6、电表设置电流方向为Negative 7、Acuview2上和HMI上检查交流电相电流是否均在精度0.1%范围内 8、查看web页面是否与上位机及电表保持一致 | G37: 5、Acuview2上和HMI上检查交流电相电流均在精度范围内 Ia： 2.997 ~ 3.003 Ib: 3.996 ~ 4.004 Ic: 4.995 ~ 5.005 Iavg: 3.996 ~ 4.004 6、Acuview2上和HMI上检查交流电相电流均在精度范围内 Ia：2.997 ~ 3.003 Ib: 3.996 ~ 4.004 Ic: 4.995 ~ 5.005 Iavg: 3.996 ~ 4.004 用户通道&输入通道&系统参数PF 为-1 用户通道&输入通道&系统参数有功功率P为负数 8、查看web页面与上位机及电表保持一致 | H37: LV2
B38: 相电流测量验证 | C38: Function_AcuRev1320_003_01_case7_1 | D38: Ia、Ib、Ic 输入电流3A，验证上位机Real-time 聚合数据的各个页面，Ia、Ib、Ic、Iavg 测量正常 | E38: 1、Acuview2上位机 2、网线/RTU串口线 3、AcuRev1320电表 4、接线方式3E4w y | F38: 1、连接AcuRev1320电表到Acuview2上，链接状态为connected 2、交流电源输入电流Ia、Ib、Ic 为3A 3、等待4小时 4、 检查检查Real-Time Metering （200ms）、Real-Time Metering （3s）、Real-Time Metering （10min）、Real-Time Metering （2hr）、High-Speed Metering 页面的Ia、Ib、Ic 、Iavg的测量值 | G38: 4、 各个页面电流及其平均值测量值均为3A 备注： 除了200ms页面，其他页面没有精度要求，测量值接近不能偏离太远 | H38: LV2
B39: 相电流测量验证 | C39: Function_AcuRev1320_003_01_case8_1 | D39: CT选型RCT16-100A类型，3E4w y y输入三路电流分别为(10A、10A，10A)，顺序ABC，相角设置为(0°、240°、120°)，在上位机上分别配置为对应A相、B相、C相，测量Ia,Ib,Ic,Iavg, input1~3满足精度 0.5% | E39: 1、Acuview2上位机 2、网线/RTU串口线 3、AcuRev1320电表 4、接线方式3E4w y y | F39: 1、连接AcuRev1320电表到Acuview2上，链接状态为connected 2、输入三路电流分别为(10A、10A，10A)，在上位机上分别配置为对应A相、B相、C相 3、电表上设置为顺序ABC， 相角设置为(0°、240°、120°) 4、电表设置电流方向为Positive 5、Acuview2上和HMI上检查交流电相电流是否均在精度0.5%范围内 6、电表设置电流方向为Negative 7、Acuview2上和HMI上检查交流电相电流是否均在精度 0.5%范围内 8、查看web页面是否与电表及上位机保持一致 | G39: 5、Acuview2上和HMI上检查交流电相电流均在精度范围内 8、查看web页面与电表及上位机保持一致 | H39: LV1
B40: 相电流测量验证 | C40: Function_AcuRev1320_003_01_case8_2 | D40: CT选型RCT16-500A类型，3E4w y y输入三路电流分别为(25A、25A，25A)，顺序ABC，相角设置为(0°、240°、120°)，在上位机上分别配置为对应A相、B相、C相，测量Ia,Ib,Ic,Iavg, input1~3满足精 0.5% | E40: 1、Acuview2上位机 2、网线/RTU串口线 3、AcuRev1320电表 4、接线方式3E4w y y | F40: 1、连接AcuRev1320电表到Acuview2上，链接状态为connected 2、输入三路电流分别为(25A、25A，25A)，在上位机上分别配置为对应A相、B相、C相 3、电表上设置为顺序ABC， 相角设置为(0°、240°、120°) 4、电表设置电流方向为Positive 5、Acuview2上和HMI上检查交流电相电流是否均在精度0.5%范围内 6、电表设置电流方向为Negative 7、Acuview2上和HMI上检查交流电相电流是否均在精度0.5%范围内 8、查看web页面是否与电表及上位机保持一致 | G40: 5、Acuview2上和HMI上检查交流电相电流均在精度范围内 8、查看web页面与电表及上位机保持一致 | H40: LV1
...

Sheet 测试用例12.8之前
A1: 模块 | B1: 子模块 | C1: 用例编号 | D1: 用例标题 | E1: 预置条件 | F1: 测试步骤 | G1: 预期结果 | H1: 级别 | I1: 自动化 | J1: 需自动化 （是/否） | K1: 测试版本 | L1: 测试结果 | M1: 测试人员 | N1: 备注 | O1: 问题单来源
A2: 交流频率 | B2: 交流频率 | C2: Function_AcuRev4100_001_01_case1 | D2: 交流电在42.5 HZ 、65HZ、69 Hz，测量精度要求0.2% | E2: 1、Acuview2上位机 2、网线/RTU串口线 3、AcuRev4100电表 | F2: 1、连接AcuRev4100电表到Acuview2上，链接状态为connected 2、交流电源输入频率为42.5HZ。 3、Acuview2上和HMI上检查交流电频率是否在精度范围内，范围:42.415 ~ 42.585 4、交流电源输入频率为65HZ。 5、Acuview2上和HMI上检查交流电频率是否在精度范围内，范围:64.87 ~ 65.13 6、交流电源输入频率为69HZ。 7、Acuview2上检查交流电频率是否在精度范围内，范围:68.862 ~ 69.138 | G2: 3、Acuview2上和HMI上检查交流电频率在精度范围内，范围:42.415 ~ 42.585 5、Acuview2上和HMI上检查交流电频率在精度范围内，范围:64.87 ~ 65.13 7、Acuview2上检查交流电频率在精度范围内，范围:68.862 ~ 69.138 | H2: LV2 | I2: 是
B3: 交流频率 | C3: Function_AcuRev4100_001_01_case2 | D3: 交流电在45 HZ 、55Hz，测量精度要求0.2% | E3: 1、Acuview2上位机 2、网线/RTU串口线 3、AcuRev4100电表 | F3: 1、连接AcuRev4100电表到Acuview2上，链接状态为connected 2、交流电源输入频率45HZ。 3、Acuview2上和HMI上检查交流电频率是否在精度范围内，范围: 4、交流电源输入频率为55HZ。 5、Acuview2上和HMI上检查交流电频率是否在精度范围内，范围: | G3: 3、Acuview2上和HMI上检查交流电频率在精度范围内，范围:44.991 ~ 45.009 5、Acuview2上和HMI上检查交流电频率在精度范围内，范围:54.989 ~ 55.011 | H3: LV1 | I3: 是
B4: 交流频率 | C4: Function_AcuRev4100_001_01_case3 | D4: 交流电在50HZ 、60 Hz，测量精度要求0.2% | E4: 1、Acuview2上位机 2、网线/RTU串口线 3、AcuRev4100电表 | F4: 1、连接AcuRev4100电表到Acuview2上，链接状态为connected 2、交流电源输入频率为50HZ。 3、Acuview2上和HMI上检查交流电频率是否在精度范围内，范围:49.9 ~ 50.1 4、交流电源输入频率为60HZ。 5、Acuview2上和HMI上检查交流电频率是否在精度范围内，范围:59.88 ~ 60.12 | G4: 3、Acuview2上和HMI上检查交流电频率在精度范围内，范围:49.9 ~ 50.1 5、Acuview2上和HMI上检查交流电频率在精度范围内，范围:59.88 ~ 60.12 | H4: LV0 | I4: 是
B5: 交流频率 | C5: Function_AcuRev4100_001_01_case4 | D5: 电表上设置60HZ, 交流电在40HZ 、70 Hz，无测量精度要求 | E5: 1、Acuview2上位机 2、网线/RTU串口线 3、AcuRev4100电表 | F5: 1、连接AcuRev4100电表到Acuview2上，链接状态为connected 1.1、电表上设置60HZ 2、交流电源输入频率为40HZ。 3、Acuview2上和HMI上检查交流电频率可以测试到频率数据，无精度要求 4、交流电源输入频率为70HZ。 5、Acuview2上和HMI上检查交流电频率可以测试到频率数据，无精度要求 | G5: 3、Acuview2上和HMI上检查交流电频率可以测试到频率数据，无精度要求 5、Acuview2上和HMI上检查交流电频率可以测试到频率数据，无精度要求 | H5: LV3 | I5: 是
B6: 交流频率 | C6: Function_AcuRev4100_001_01_case5 | D6: 关闭输出后，电表不会有频率显示 | E6: 1、Acuview2上位机 2、网线/RTU串口线 3、AcuRev4100电表 | F6: 1、输出50HZ频率 2、关闭源输出 3、HMI查看系统频率 | G6: 1、关闭源输出，频率显示0 | H6: LV1
A7: 交流电压 | B7: 线-地电压(相电压)验证 | C7: Function_AcuRev4100_002_01_case1 | D7: 交流电Van、Vbn、Vcn输入额定电压分别均为69V,120V,测量Van、Vbn、Vcn、Vlnavg满足精度要求0.1% | E7: 1、Acuview2上位机 2、网线/RTU串口线 3、AcuRev4100电表 | F7: 1、连接AcuRev4100电表到Acuview2上，链接状态为connected 2、交流电源输入相电压Van、Vbn、Vcn的额定电压为69V。 3、Acuview2上和HMI上检查交流电相电压是否均在精度范围内， Van、Vbn、Vcn范围(V):68.931 ~ 69.069， Vlnavg范围(V)：68.931 ~ 69.069 4、交流电源输入相电压Van、Vbn、Vcn的额定电压为120V。 5、Acuview2上和HMI上检查交流电相电压是否均在精度范围内，范围(V):119.88 ~ 120.12， Vlnavg范围(V)：119.88 ~ 120.12 | G7: 3、Acuview2上和HMI上检查交流电相电压均在精度范围内，范围(V):68.931 ~ 69.069，Vlnavg范围(V)：68.931 ~ 69.069 5、Acuview2上和HMI上检查交流电相电压均在精度范围内，范围(V):119.88 ~ 120.12，Vlnavg范围(V)：119.88 ~ 120.12 | H7: LV1 | I7: 是
B8: 线-地电压(相电压)验证 | C8: Function_AcuRev4100_002_01_case2 | D8: 交流电Van、Vbn、Vcn输入额定电压分别均为230V,347V,测量Van、Vbn、Vcn、Vlnavg满足精度要求0.1% | E8: 1、Acuview2上位机 2、网线/RTU串口线 3、AcuRev4100电表 | F8: 1、连接AcuRev4100电表到Acuview2上，链接状态为connected 2、交流电源输入相电压Van、Vbn、Vcn的额定电压为230V。 3、Acuview2上和HMI上检查交流电相电压是否均在精度范围内，范围(V):229.77 ~ 230.23， Vlnavg范围(V)：229.77 ~ 230.23 4、交流电源输入相电压Van、Vbn、Vcn的额定电压为347V。 5、Acuview2上和HMI上检查交流电相电压是否均在精度范围内，范围(V):346.653 ~ 347.347， Vlnavg范围(V)：346.653 ~ 347.347 | G8: 3、Acuview2上和HMI上检查交流电相电压均在精度范围内，范围(V):229.77 ~ 230.23， Vlnavg范围(V)：229.77 ~ 230.23 5、Acuview2上和HMI上检查交流电相电压均在精度范围内，范围(V):346.653 ~ 347.347， Vlnavg范围(V)：346.653 ~ 347.347 | H8: LV2 | I8: 是
B9: 线-地电压(相电压)验证 | C9: Function_AcuRev4100_002_01_case3 | D9: 交流电Van、Vbn、Vcn输入电压分别均为220V,380V,测量Van、Vbn、Vcn、Vlnavg满足精度要求0.1% | E9: 1、Acuview2上位机 2、网线/RTU串口线 3、AcuRev4100电表 | F9: 1、连接AcuRev4100电表到Acuview2上，链接状态为connected 2、交流电源输入相电压Van、Vbn、Vcn的额定电压为220V。 3、Acuview2上和HMI上检查交流电相电压是否均在精度范围内，范围(V):219.78 ~ 220.22， Vlnavg范围(V)：219.78 ~ 220.22 4、交流电源输入相电压Van、Vbn、Vcn的额定电压为380V。 5、Acuview2上和HMI上检查交流电相电压是否均在精度范围内，范围(V):379.62 ~ 380.38， Vlnavg范围(V)：379.62 ~ 380.38 | G9: 3、Acuview2上和HMI上检查交流电相电压均在精度范围内，范围(V):219.78 ~ 220.22， Vlnavg范围(V)：219.78 ~ 220.22 5、Acuview2上和HMI上检查交流电相电压均在精度范围内，范围(V):379.62 ~ 380.38， Vlnavg范围(V)：379.62 ~ 380.38 | H9: LV0 | I9: 是
B10: 线-地电压(相电压)验证 | C10: Function_AcuRev4100_002_01_case4 | D10: 交流电Van、Vbn、Vcn输入电压分别均为100V,200V,测量Van、Vbn、Vcn、Vlnavg满足精度要求0.1% | E10: 1、Acuview2上位机 2、网线/RTU串口线 3、AcuRev4100电表 | F10: 1、连接AcuRev4100电表到Acuview2上，链接状态为connected 2、交流电源输入相电压Van、Vbn、Vcn的额定电压为100V。 3、Acuview2上和HMI上检查交流电相电压是否均在精度范围内，范围(V):99.9 ~ 100.1， Vlnavg范围(V)：99.9 ~ 100.1 4、交流电源输入相电压Van、Vbn、Vcn的额定电压为200V。 5、Acuview2上和HMI上检查交流电相电压是否均在精度范围内，范围(V):199.8 ~ 200.2， Vlnavg范围(V)：199.8 ~ 200.2 | G10: 3、Acuview2上和HMI上检查交流电相电压均在精度范围内，范围(V):99.9 ~ 100.1， Vlnavg范围(V)：99.9 ~ 100.1 5、Acuview2上和HMI上检查交流电相电压均在精度范围内，范围(V):199.8 ~ 200.2， Vlnavg范围(V)：199.8 ~ 200.2 | H10: LV2 | I10: 是
B11: 线-地电压(相电压)验证 | C11: Function_AcuRev4100_002_01_case5 | D11: 交流电Van、Vbn、Vcn输入电压分别均为300V,400V,测量Van、Vbn、Vcn、Vlnavg满足精度要求0.1% | E11: 1、Acuview2上位机 2、网线/RTU串口线 3、AcuRev4100电表 | F11: 1、连接AcuRev4100电表到Acuview2上，链接状态为connected 2、交流电源输入相电压Van、Vbn、Vcn的额定电压为300V。 3、Acuview2上和HMI上检查交流电相电压是否均在精度范围内，范围(V):199.8 ~ 200.2， Vlnavg范围(V)：199.8 ~ 200.2 4、交流电源输入相电压Van、Vbn、Vcn的额定电压为400V。 5、Acuview2上和HMI上检查交流电相电压是否均在精度范围内，范围(V):399.6 ~ 400.4， Vlnavg范围(V)：399.6 ~ 400.4 | G11: 3、Acuview2上和HMI上检查交流电相电压均在精度范围内，范围(V):199.8 ~ 200.2， Vlnavg范围(V)：199.8 ~ 200.2 5、Acuview2上和HMI上检查交流电相电压均在精度范围内，范围(V):399.6 ~ 400.4， Vlnavg范围(V)：399.6 ~ 400.4 | H11: LV2 | I11: 是
B12: 线-地电压(相电压)验证 | C12: Fault_AcuRev4100_002_01_case6 | D12: 交流电Van、Vbn、Vcn输入范围外电压分别均为40V,68V,测量Van、Vbn、Vcn、Vlnavg满足精度要求0.1% | E12: 1、Acuview2上位机 2、网线/RTU串口线 3、AcuRev4100电表 | F12: 1、连接AcuRev4100电表到Acuview2上，链接状态为connected 2、交流电源输入相电压Van、Vbn、Vcn的额定电压为40V。 3、Acuview2上和HMI上检查交流电相电压是否有测量显示，满足精度要求0.1% 4、交流电源输入相电压Van、Vbn、Vcn的额定电压为68V。 5、Acuview2上和HMI上检查交流电相电压是否有测量显示，满足精度要求0.1% | G12: 3、Acuview2上和HMI上检查交流电相电压有测量显示，满足精度要求0.1% 5、Acuview2上和HMI上检查交流电相电压有测量显示，满足精度要求0.1% | H12: LV3 | I12: 是
B13: 线-地电压(相电压)验证 | C13: Fault_AcuRev4100_002_01_case7 | D13: 交流电Van、Vbn、Vcn输入启动电压分别均为10.2V、20V,电表有测量值,测量Van、Vbn、Vcn、Vlnavg没有精度要求 | E13: 1、Acuview2上位机 2、网线/RTU串口线 3、AcuRev4100电表 | F13: 1、连接AcuRev4100电表到Acuview2上，链接状态为connected 2、交流电源输入相电压Van、Vbn、Vcn的额定电压为10.2V。 3、Acuview2上和HMI上检查交流电相电压是否有测量显示，精度没有要求 4、交流电源输入相电压Van、Vbn、Vcn的额定电压为20V。 5、Acuview2上和HMI上检查交流电相电压是否有测量显示，精度没有要求 | G13: 3、Acuview2上和HMI上检查交流电相电压有测量显示，没有精度要求 5、Acuview2上和HMI上检查交流电相电压有测量显示，没有精度要求 | H13: LV3 | I13: 是
B14: 线-地电压(相电压)验证 | C14: Fault_AcuRev4100_002_01_case8 | D14: 交流电Van、Vbn、Vcn输入电压分别均为1V，9V,电表Van、Vbn、Vcn、Vlnavg无测量值 | E14: 1、Acuview2上位机 2、网线/RTU串口线 3、AcuRev4100电表 | F14: 1、连接AcuRev4100电表到Acuview2上，链接状态为connected 2、交流电源输入相电压Van、Vbn、Vcn的额定电压为1V。 3、Acuview2上和HMI上检查交流电相电压是否为0V 4、交流电源输入相电压Van、Vbn、Vcn的额定电压为9V。 5、Acuview2上和HMI上检查交流电相电压是否为0V，不考虑精度 | G14: 3、Acuview2上和HMI上检查交流电相电压为0V 5、Acuview2上和HMI上检查交流电相电压为0V | H14: LV4
B15: 线-地电压(相电压)验证 | C15: Fault_AcuRev4100_002_01_case8_1 | D15: 交流电Van、Vbn、Vcn输入电压分别均为0V,电表Van、Vbn、Vcn、Vlnavg测量值为0V | E15: 1、Acuview2上位机 2、网线/RTU串口线 3、AcuRev4100电表 | F15: 1、连接AcuRev4100电表到Acuview2上，链接状态为connected 2、交流电源输入相电压Van、Vbn、Vcn的额定电压为0V。 3、Acuview2上和HMI上检查交流电相电压是否为0V | G15: 3、Acuview2上和HMI上检查交流电相电压为0V | H15: LV4 | I15: 是
B16: 线-地电压(相电压)验证 | C16: Function_AcuRev4100_002_01_case9 | D16: 交流电Van、Vbn、Vcn输入额定电压为(69V,120V,230V),测量Van、Vbn、Vcn、Vlnavg满足精度要求0.1% | E16: 1、Acuview2上位机 2、网线/RTU串口线 3、AcuRev4100电表 | F16: 1、连接AcuRev4100电表到Acuview2上，链接状态为connected 2、交流电源输入相电压Van、Vbn、Vcn的额定电压分别为(69V,120V,230V)。 3、Acuview2上和HMI上检查交流电相电压是否均在精度范围内，Van范围(V):68.931 ~ 69.069，Vbn范围(V):119.88 ~ 120.12，Vcn范围(V):229.77 ~ 230.23，Vlnavg范围(V):139.527 ~ 139.8063333 | G16: 3、Acuview2上和HMI上检查交流电相电压均在精度范围内，Van范围(V):68.931 ~ 69.069，Vbn范围(V):119.88 ~ 120.12，Vcn范围(V):229.77 ~ 230.23，Vlnavg范围(V):139.527 ~ 139.8063333 | H16: LV2 | I16: 是
B17: 线-地电压(相电压)验证 | C17: Function_AcuRev4100_002_01_case10 | D17: 交流电Van、Vbn、Vcn输入额定电压为(347V,100V,220V),测量Van、Vbn、Vcn、Vlnavg满足精度要求0.1% | E17: 1、Acuview2上位机 2、网线/RTU串口线 3、AcuRev4100电表 | F17: 1、连接AcuRev4100电表到Acuview2上，链接状态为connected 2、交流电源输入相电压Van、Vbn、Vcn的额定电压分别为(347V,100V,220V)。 3、Acuview2上和HMI上检查交流电相电压是否均在精度范围内，Van范围(V):346.653 ~ 347.347，Vbn范围(V):99.9 ~ 100.1，Vcn范围(V):219.78 ~ 220.22，Vlnavg范围(V):222.111 ~ 222.5556667 | G17: 3、Acuview2上和HMI上检查交流电相电压均在精度范围内,Van范围(V):346.653 ~ 347.347，Vbn范围(V):99.9 ~ 100.1，Vcn范围(V):219.78 ~ 220.22，Vlnavg范围(V):222.111 ~ 222.5556667 | H17: LV2 | I17: 是
B18: 线-地电压(相电压)验证 | C18: Function_AcuRev4100_002_01_case11 | D18: 交流电Van、Vbn、Vcn输入额定电压为(220V,380V,440V),测量Van、Vbn、Vcn、Vlnavg满足精度要求0.1% | E18: 1、Acuview2上位机 2、网线/RTU串口线 3、AcuRev4100电表 | F18: 1、连接AcuRev4100电表到Acuview2上，链接状态为connected 2、交流电源输入相电压Van、Vbn、Vcn的额定电压分别为(220V,380V,440V)。 3、Acuview2上和HMI上检查交流电相电压是否均在精度范围内，Van范围(V): 219.78 ~ 220.22，Vbn范围(V): 379.62 ~ 380.38，Vcn范围(V): 399.6 ~ 400.4，Vlnavg范围(V): 333 ~ 333.6666667 | G18: 3、Acuview2上和HMI上检查交流电相电压均在精度范围内，Van范围(V): 219.78 ~ 220.22，Vbn范围(V): 379.62 ~ 380.38，Vcn范围(V): 439.5600 ~ 440.4400 ，Vlnavg范围(V): 346.3200 ~ 347.0133 | H18: LV2 | I18: 是
B19: 线-地电压(相电压)验证 | C19: Fault_AcuRev4100_002_01_case11_1 | D19: 交流电Van、Vbn、Vcn输入额定电压为(100V,100V,100V),φA、φB、φC分别为(0°、240°、120°)，断开交流源输入，Van、Vbn、Vcn、Vlnavg测量值全为0V | E19: 1、Acuview2上位机 2、网线/RTU串口线 3、AcuRev4100电表 | F19: 1、连接AcuRev4100电表到Acuview2上，链接状态为connected 2、交流电Van、Vbn、Vcn输入额定电压为(100V,100V,100V),φA、φB、φC分别为(0°、240°、120°) 3、Acuview2上和HMI上检查交流电相电压是否均在精度范围内 4、断开交流源输入 5、立即Acuview2上和HMI上检查交流电相电压Van、Vbn、Vcn、Vlnavg测量值全为0V | G19: 3、Acuview2上和HMI上检查交流电相电压均在精度0.1%范围内 5、立即Acuview2上和HMI上检查交流电相电压Vab，Vac、Vbc、Vllavg测量值全为0V | H19: LV3
B20: 线-地电压(相电压)验证 | C20: Fault_AcuRev4100_002_01_case11_2 | D20: 交流电Van、Vbn、Vcn输入额定电压为(220V,220V,220V),φA、φB、φC分别为(0°、240°、120°)，立即反复降低电压到10%，Van、Vbn、Vcn、Vlnavg测量值满足精度要求 | E20: 1、Acuview2上位机 2、网线/RTU串口线 3、AcuRev4100电表 | F20: 1、连接AcuRev4100电表到Acuview2上，链接状态为connected 2、交流电Van、Vbn、Vcn输入额定电压为(220V,220V,220V),φA、φB、φC分别为(0°、240°、120°) 3、立即降低电压到10%， 等待10s 4、立即升电压到100%， 等待10s 5、Acuview2上和HMI上检查交流电相电压是否均在精度0.1%范围内 | G20: 5、Acuview2上和HMI上检查交流电相电压均在精度0.1%范围内 | H20: LV3
B21: 线-地电压(相电压)验证 | C21: Fault_AcuRev4100_002_01_case11_3 | D21: 交流电Van、Vbn、Vcn输入额定电压为(220V,220V,220V),φA、φB、φC分别为(0°、240°、120°)，立即反复降低电压到50%，Van、Vbn、Vcn、Vlnavg测量值满足精度要求 | E21: 1、Acuview2上位机 2、网线/RTU串口线 3、AcuRev4100电表 | F21: 1、连接AcuRev4100电表到Acuview2上，链接状态为connected 2、交流电Van、Vbn、Vcn输入额定电压为(220V,220V,220V),φA、φB、φC分别为(0°、240°、120°) 3、立即降低电压到50%， 等待10s 4、Acuview2上和HMI上检查交流电相电压是否均在精度0.1%范围内 5、立即升电压到100%， 等待10s 6、Acuview2上和HMI上检查交流电相电压是否均在精度0.1%范围内 | G21: 4、Acuview2上和HMI上检查交流电相电压均在精度0.1%范围内 6、Acuview2上和HMI上检查交流电相电压均在精度0.1%范围内 | H21: LV3
B22: 线-地电压(相电压)验证 | C22: Fault_AcuRev4100_002_01_case11_4 | D22: 交流电Van、Vbn、Vcn输入额定电压为(220V,220V,220V)顺序，且φA、φB、φC分别为(0°、120°、240°)，Van、Vbn、Vcn、Vlnavg测量值满足精度要求0.1% | E22: 1、Acuview2上位机 2、网线/RTU串口线 3、AcuRev4100电表 | F22: 1、连接AcuRev4100电表到Acuview2上，链接状态为connected 2、交流电源输入相电压Van、Vbn、Vcn的额定电压为220V。 3、电表相序设置为ABC，φA、φB、φC分别为(0°、120°、240°) 4、Acuview2上和HMI上检查交流电相电压Van、Vbn、Vcn、Vlnavg测量值是否满足精度要求0.1% | G22: 4、Acuview2上和HMI上检查交流电相电压均在精度范围内，范围(V):219.7800 ~ 220.2200 ， Vlnavg范围(V)：219.7800 ~ 220.2200 | H22: LV2 | I22: 是
B23: 线-地电压(相电压)验证 | C23: Fault_AcuRev4100_002_01_case11_5 | D23: 交流电Van、Vbn、Vcn输入额定电压为(220V,220V,220V),逆序，且φA、φB、φC分别为(0°、120°、240°)，Van、Vbn、Vcn、Vlnavg测量值满足精度要求0.1% | E23: 1、Acuview2上位机 2、网线/RTU串口线 3、AcuRev4100电表 | F23: 1、连接AcuRev4100电表到Acuview2上，链接状态为connected 2、交流电源输入相电压Van、Vbn、Vcn的额定电压为220V。 3、电表相序设置为ACB，φA、φB、φC分别为(0°、120°、240°) 4、Acuview2上和HMI上检查交流电相电压Van、Vbn、Vcn、Vlnavg测量值是否满足精度要求0.1% | G23: 4、Acuview2上和HMI上检查交流电相电压均在精度范围内，范围(V):219.7800 ~ 220.2200 ， Vlnavg范围(V)：219.7800 ~ 220.2200 | H23: LV3 | I23: 是
B24: 线-地电压(相电压)验证 | C24: Fault_AcuRev4100_002_01_case11_6 | D24: 交流电Van、Vbn、Vcn输入额定电压为(120V,120V,120V),逆序，且φA、φB、φC分别为(0°、240°、120°)，Van、Vbn、Vcn、Vlnavg测量值满足精度要求0.1% | E24: 1、Acuview2上位机 2、网线/RTU串口线 3、AcuRev4100电表 | F24: 1、连接AcuRev4100电表到Acuview2上，链接状态为connected 2、交流电源输入相电压Van、Vbn、Vcn的额定电压为120V。 3、电表相序设置为ACB，φA、φB、φC分别为(0°、240°、120°) 4、Acuview2上和HMI上检查交流电相电压Van、Vbn、Vcn、Vlnavg测量值是否满足精度要求0.1% | G24: 4、Acuview2上和HMI上检查交流电相电压均在精度范围内，范围(V):119.8800 ~ 120.1200 ， Vlnavg范围(V)：119.8800 ~ 120.1200 | H24: LV3 | I24: 是
B25: 线-地电压(相电压)验证 | C25: Fault_AcuRev4100_002_01_case11_7 | D25: 交流电Van、Vbn、Vcn输入额定电压为(120V,120V,120V)顺序，且φA、φB、φC分别为(0°、120°、240°)，Van、Vbn、Vcn、Vlnavg测量值满足精度要求0.1% | E25: 1、Acuview2上位机 2、网线/RTU串口线 3、AcuRev4100电表 | F25: 1、连接AcuRev4100电表到Acuview2上，链接状态为connected 2、交流电源输入相电压Van、Vbn、Vcn的额定电压为120V。 3、电表相序设置为ABC，φA、φB、φC分别为(0°、120°、240°) 4、Acuview2上和HMI上检查交流电相电压Van、Vbn、Vcn、Vlnavg测量值是否满足精度要求0.1% | G25: 4、Acuview2上和HMI上检查交流电相电压均在精度范围内，范围(V):119.8800 ~ 120.1200 ， Vlnavg范围(V)：119.8800 ~ 120.1200 | H25: LV2 | I25: 是
B26: 线-地电压(相电压)验证 | C26: Fault_AcuRev4100_002_01_case11_8 | D26: 交流电Van、Vbn、Vcn输入额定电压为(120V,120V,120V)顺序，且φA、φB、φC分别为(0°、130°、250°)，Van、Vbn、Vcn、Vlnavg测量值满足精度要求0.1% | E26: 1、Acuview2上位机 2、网线/RTU串口线 3、AcuRev4100电表 | F26: 1、连接AcuRev4100电表到Acuview2上，链接状态为connected 2、交流电源输入相电压Van、Vbn、Vcn的额定电压为120V。 3、电表相序设置为ABC，φA、φB、φC分别为(0°、130°、250°) 4、Acuview2上和HMI上检查交流电相电压Van、Vbn、Vcn、Vlnavg测量值是否满足精度要求0.1% | G26: 4、Acuview2上和HMI上检查交流电相电压均在精度范围内，范围(V):119.8800 ~ 120.1200 ， Vlnavg范围(V)：119.8800 ~ 120.1200 | H26: LV2 | I26: 是
B27: 线-地电压(相电压)验证 | C27: Fault_AcuRev4100_002_01_case11_9 | D27: 交流电Van、Vbn、Vcn输入额定电压为(120V,120V,120V)顺序，且φA、φB、φC分别为(0°、260°、140°)，Van、Vbn、Vcn、Vlnavg量值满足精度要求0.1% | E27: 1、Acuview2上位机 2、网线/RTU串口线 3、AcuRev4100电表 | F27: 1、连接AcuRev4100电表到Acuview2上，链接状态为connected 2、交流电源输入相电压Van、Vbn、Vcn的额定电压为120V。 3、电表相序设置为ABC，φA、φB、φC分别为(0°、260°、140°) 4、Acuview2上和HMI上检查交流电相电压Van、Vbn、Vcn、Vlnavg测量值是否满足精度要求0.1% | G27: 4、Acuview2上和HMI上检查交流电相电压均在精度范围内，范围(V):119.8800 ~ 120.1200 ， Vlnavg范围(V)：119.8800 ~ 120.1200 | H27: LV2 | I27: 是
B28: 线-地电压(相电压)验证 | C28: Fault_AcuRev4100_002_01_case11_10 | D28: 只加电压,看电压正常精度正常， 电流测量值为0 | E28: 1、Acuview2上位机 2、网线/RTU串口线 3、AcuRev4100电表 4、接线方式3e3p4w y | F28: 1、连接AcuRev4100电表到Acuview2上，链接状态为connected 2、交流电源输入相电压Van、Vbn、Vcn的额定电压为120V。 3、电表相序设置为ABC，φA、φB、φC分别为(0°、240°、120°) 4、电表未接电流。 5、Acuview2上和HMI上检查交流电相电压Van、Vbn、Vcn、Vlnavg测量值是否满足精度要求0.1% 6、ABC三相, 输入通道input1-24、用户user1-12电流是否均为0A | G28: 5、Acuview2上和HMI上检查交流电相电压Van、Vbn、Vcn、Vlnavg测量值满足精度要求0.1% 6、ABC三相, 输入通道input1-24、用户user1-12电流均为0A | H28: LV3
B29: 线-地电压(相电压)验证 | C29: Fault_AcuRev4100_002_01_case11_11 | D29: 电压为0，只加电流, 电流测量值正常，但不计算夹角、功率、能量；电压为10V，电流测量值正常，且计算夹角、功率、能量 | E29: 1、Acuview2上位机 2、网线/RTU串口线 3、AcuRev4100电表 4、接线方式3e3p4w y | F29: 1、连接AcuRev4100电表到Acuview2上，链接状态为connected 2、交流电源输入相电压Van、Vbn、Vcn的额定电压为0V。 3、电表相序设置为ABC，φA、φB、φC分别为(0°、240°、120°) 4、input1-3 设置为3A 5、Acuview2上和HMI上检查交流电相电压Van、Vbn、Vcn、Vlnavg测量值是否为0V。 6、ABC三相, 输入通道input1-3、用户user1电流均为3A 7、交流电源输入相电压Van、Vbn、Vcn的额定电压为10V。 8、电表相序设置为ABC，φA、φB、φC分别为(0°、240°、120°) 9、input1-3 设置为3A 10、ABC三相, 输入通道input1-3、用户user1电流均为3A | G29: 5、Acuview2上和HMI上检查交流电相电压Van、Vbn、Vcn、Vlnavg测量值为0V 6、ABC三相, 输入通道input1-3、用户user1电流均为3A，同时功率、夹角、能量不计算 10、ABC三相, 输入通道input1-3、用户user1电流均为3A，同时计算功率、夹角、能量 | H29: LV3
B30: 线-地电压(相电压)验证 | C30: Fault_AcuRev4100_002_01_case11_12 | D30: 电表接入电压线束，但交流源没有开机的情况下，电表可以测试到电压值为0V | E30: 1、Acuview2上位机 2、网线/RTU串口线 3、AcuRev4100电表 4、接线方式3e3p4w y | F30: 1、电表接入电压线束，但交流源没有开机的情况下， 2、检查电表可以测试到电压值是否为0V | G30: 2、检查电表可以测试到电压值为0V | H30: LV3
B31: 线-线电压(线电压)验证 | C31: Function_AcuRev4100_002_02_case1 | D31: 交流电Van、Vbn、Vcn均输入电压69V和120V, 测量Vab，Vac、Vbc、Vllavg精度均满足要求0.1% | E31: 1、Acuview2上位机 2、网线/RTU串口线 3、AcuRev4100电表 | F31: 1、连接AcuRev4100电表到Acuview2上，链接状态为connected 2、交流电源输入相电压Van、Vbn、Vcn的额定电压为69V。 3、Acuview2上和HMI上检查交流电相电压是否均在精度范围内，范围(V):119.388492 ~ 119.627508， Vllavg范围(V)：119.388492 ~ 119.627508 4、交流电源输入相电压Van、Vbn、Vcn的额定电压为120V。 5、Acuview2上和HMI上检查交流电相电压是否均在精度范围内，范围(V):207.63216 ~ 208.04784， Vllavg范围(V)：207.63216 ~ 208.04784 | G31: 3、Acuview2上和HMI上检查交流电相电压均在精度范围内，范围(V):119.388492 ~ 119.627508， Vllavg范围(V)：119.388492 ~ 119.627508 5、Acuview2上和HMI上检查交流电相电压均在精度范围内，范围(V):207.63216 ~ 208.04784， Vllavg范围(V)：207.63216 ~ 208.04784 | H31: LV1 | I31: 是
B32: 线-线电压(线电压)验证 | C32: Function_AcuRev4100_002_02_case2 | D32: 交流电Van、Vbn、Vcn均输入电压230V和347V,测量Vab，Vac、Vbc、Vllavg精度均满足要求0.1% | E32: 1、Acuview2上位机 2、网线/RTU串口线 3、AcuRev4100电表 | F32: 1、连接AcuRev4100电表到Acuview2上，链接状态为connected 2、交流电源输入相电压Van、Vbn、Vcn的额定电压为230V。 3、Acuview2上和HMI上检查交流电相电压是否均在精度范围内，范围(V):397.96164 ~ 398.75836， Vllavg范围(V)：397.96164 ~ 398.75836 4、交流电源输入相电压Van、Vbn、Vcn的额定电压为。 5、Acuview2上和HMI上检查交流电相电压是否均在精度范围内347，范围(V):600.402996 ~ 601.605004， Vllavg范围(V)：600.402996 ~ 601.605004 | G32: 3、Acuview2上和HMI上检查交流电相电压均在精度范围内，范围(V):397.96164 ~ 398.75836， Vllavg范围(V)：397.96164 ~ 398.75836 5、Acuview2上和HMI上检查交流电相电压均在精度范围内347，范围(V):600.402996 ~ 601.605004， Vllavg范围(V)：600.402996 ~ 601.605004 | H32: LV1 | I32: 是
B33: 线-线电压(线电压)验证 | C33: Function_AcuRev4100_002_02_case3 | D33: 交流电Van、Vbn、Vcn均输入电压220V和380V,测量Vab，Vac、Vbc、Vllavg精度均满足要求0.1% | E33: 1、Acuview2上位机 2、网线/RTU串口线 3、AcuRev4100电表 | F33: 1、连接AcuRev4100电表到Acuview2上，链接状态为connected 2、交流电源输入相电压Van、Vbn、Vcn的额定电压为220V。 3、Acuview2上和HMI上检查交流电相电压是否均在精度范围内，范围(V):380.65896 ~ 381.42104， Vllavg范围(V)：380.65896 ~ 381.42104 4、交流电源输入相电压Van、Vbn、Vcn的额定电压为380V。 5、Acuview2上和HMI上检查交流电相电压是否均在精度范围内，范围(V):657.50184 ~ 658.81816， Vllavg范围(V)：657.50184 ~ 658.81816 | G33: 3、Acuview2上和HMI上检查交流电相电压均在精度范围内，范围(V):380.65896 ~ 381.42104， Vllavg范围(V)：380.65896 ~ 381.42104 5、Acuview2上和HMI上检查交流电相电压均在精度范围内，范围(V):657.50184 ~ 658.81816， Vllavg范围(V)：657.50184 ~ 658.81816 | H33: LV0 | I33: 是
B34: 线-线电压(线电压)验证 | C34: Function_AcuRev4100_002_02_case4 | D34: 交流电Van、Vbn、Vcn均输入电压100V和200V,测量Vab，Vac、Vbc、Vllavg精度均满足要求0.1% | E34: 1、Acuview2上位机 2、网线/RTU串口线 3、AcuRev4100电表 | F34: 1、连接AcuRev4100电表到Acuview2上，链接状态为connected 2、交流电源输入相电压Van、Vbn、Vcn的额定电压为100V。 3、Acuview2上和HMI上检查交流电相电压是否均在精度范围内，范围(V):173.0268 ~ 173.3732， Vllavg范围(V)：173.0268 ~ 173.3732 4、交流电源输入相电压Van、Vbn、Vcn的额定电压为200V。 5、Acuview2上和HMI上检查交流电相电压是否均在精度范围内，范围(V):346.0536 ~ 346.7464， Vllavg范围(V)：346.0536 ~ 346.7464 | G34: 3、Acuview2上和HMI上检查交流电相电压均在精度范围内，范围(V):173.0268 ~ 173.3732， Vllavg范围(V)：173.0268 ~ 173.3732 5、Acuview2上和HMI上检查交流电相电压均在精度范围内，范围(V):346.0536 ~ 346.7464， Vllavg范围(V)：346.0536 ~ 346.7464 | H34: LV2 | I34: 是
B35: 线-线电压(线电压)验证 | C35: Function_AcuRev4100_002_02_case5 | D35: 交流电Van、Vbn、Vcn均输入电压300V和440V,测量Vab，Vac、Vbc、Vllavg精度均满足要求0.1% | E35: 1、Acuview2上位机 2、网线/RTU串口线 3、AcuRev4100电表 | F35: 1、连接AcuRev4100电表到Acuview2上，链接状态为connected 2、交流电源输入相电压Van、Vbn、Vcn的额定电压为300V。 3、Acuview2上和HMI上检查交流电相电压是否均在精度范围内，范围(V):519.0804 ~ 520.1196， Vllavg范围(V)：519.0804 ~ 520.1196 4、交流电源输入相电压Van、Vbn、Vcn的额定电压为440V。 5、Acuview2上和HMI上检查交流电相电压是否均在精度范围内，范围(V):692.1072 ~ 693.4928， Vllavg范围(V)：692.1072 ~ 693.4928 | G35: 3、Acuview2上和HMI上检查交流电相电压均在精度范围内，范围(V):519.0804 ~ 520.1196， Vllavg范围(V)：519.0804 ~ 520.1196 5、Acuview2上和HMI上检查交流电相电压均在精度范围内，范围(V):762.1024 761.3403 ~ 762.8645 ， Vllavg范围(V)：762.1024 761.3403 ~ 762.8645 | H35: LV2 | I35: 是
B36: 线-线电压(线电压)验证 | C36: Fault_AcuRev4100_002_02_case6 | D36: 交流电Van、Vbn、Vcn均输入电压40V和68V, 测量Vab，Vac、Vbc、Vllavg满足精度要求0.1% | E36: 1、Acuview2上位机 2、网线/RTU串口线 3、AcuRev4100电表 | F36: 1、连接AcuRev4100电表到Acuview2上，链接状态为connected 2、交流电源输入相电压Van、Vbn、Vcn的额定电压为40V。 3、Acuview2上和HMI上检查交流电线电压是否有测量显示，满足精度要求0.1% 4、交流电源输入相电压Van、Vbn、Vcn的额定电压为68V。 5、Acuview2上和HMI上检查交流电线电压是否有测量显示,满足精度要求0.1% | G36: 3、Acuview2上和HMI上检查交流电线电压有测量显示，满足精度要求0.1% 5、Acuview2上和HMI上检查交流电线电压有测量显示，满足精度要求0.1% | H36: LV3 | I36: 是
B37: 线-线电压(线电压)验证 | C37: Fault_AcuRev4100_002_02_case7 | D37: 交流电Van、Vbn、Vcn均输入启动电压10.2V、20V,电表有测量值，测量Vab，Vac、Vbc、Vllavg精度没有要求 | E37: 1、Acuview2上位机 2、网线/RTU串口线 3、AcuRev4100电表 | F37: 1、连接AcuRev4100电表到Acuview2上，链接状态为connected 2、交流电源输入相电压Van、Vbn、Vcn的额定电压为10.2V。 3、Acuview2上和HMI上检查交流电线电压是否有测量显示， 精度没有要求 4、交流电源输入相电压Van、Vbn、Vcn的额定电压为20V。 5、Acuview2上和HMI上检查交流电线电压是否有测量显示, 精度没有要求 | G37: 3、Acuview2上和HMI上检查交流电线电压有测量显示，精度没有要求 5、Acuview2上和HMI上检查交流电线电压有测量显示，精度没有要求 | H37: LV3 | I37: 是
B38: 线-线电压(线电压)验证 | C38: Fault_AcuRev4100_002_02_case8 | D38: 交流电Van、Vbn、Vcn均输入电压1V，9V,电表Vab，Vac、Vbc、Vllavg无测量值 | E38: 1、Acuview2上位机 2、网线/RTU串口线 3、AcuRev4100电表 | F38: 1、连接AcuRev4100电表到Acuview2上，链接状态为connected 2、交流电源输入相电压Van、Vbn、Vcn的额定电压为1V。 3、Acuview2上和HMI上检查交流电线电压是否为0V 4、交流电源输入相电压Van、Vbn、Vcn的额定电压为9V。 5、Acuview2上和HMI上检查交流电线电压是否为0V | G38: 3、Acuview2上和HMI上检查交流电线电压为0V 5、Acuview2上和HMI上检查交流电线电压为0V | H38: LV3 | I38: 是
B39: 线-线电压(线电压)验证 | C39: Fault_AcuRev4100_002_02_case8_1 | D39: 交流电Van、Vbn、Vcn均输入电压0V,电表Vab，Vac、Vbc、Vllavg测量值为0V | E39: 1、Acuview2上位机 2、网线/RTU串口线 3、AcuRev4100电表 | F39: 1、连接AcuRev4100电表到Acuview2上，链接状态为connected 2、交流电源输入相电压Van、Vbn、Vcn的额定电压为0V。 3、Acuview2上和HMI上检查交流电线电压是否为0V | G39: 3、Acuview2上和HMI上检查交流电线电压为0V | H39: LV1 | I39: 是
B40: 线-线电压(线电压)验证 | C40: Function_AcuRev4100_002_02_case9 | D40: 交流电Van、Vbn、Vcn输入额定电压为(69V,120V,230V), θA、θB、θC分别为(0°、60°、120°)测量Vab，Vac、Vbc、Vllavg满足精度要求0.1% | E40: 1、Acuview2上位机 2、网线/RTU串口线 3、AcuRev4100电表 | F40: 1、连接AcuRev4100电表到Acuview2上，链接状态为connected 2、交流电源输入相电压Van、Vbn、Vcn的电压为(69V,120V,230V), θA、θB、θC分别为(0°、60°、120°)。 3、Acuview2上和HMI上检查交流电相电压是否均在精度范围内， | G40: 3、Acuview2上和HMI上检查交流电相电压均在精度范围内 备注: 也可以使用excel公式计算任意角度和电压的线电压。 | H40: LV2
...

Sheet 用例统计
A1: TR编号(模块) | B1: TR名称(模块) | C1: 用例总数 | D1: LV0 | E1: LV1 | F1: LV2 | G1: LV3 | H1: LV4 | I1: 需自动化 | J1: 完成自动化 | K1: LV0（10%） | L1: LV1(15%) | M1: LV2（40%） | N1: LV3(25%) | O1: LV4（10%） | P1: 自动化率 | Q1: 备注 | R1: 自动化实现人
A2: TR_AcuRev1320_001 | B2: 交流频率 | C2: =COUNTIFS(测试用例!C:C,"*1320_001*") -> 5 | D2: =COUNTIFS(测试用例!C:C,"*1320_001*",测试用例!H:H,"LV0") -> 1 | E2: =COUNTIFS(测试用例!C:C,"*1320_001*",测试用例!H:H,"LV1") -> 2 | F2: =COUNTIFS(测试用例!C:C,"*1320_001*",测试用例!H:H,"LV2") -> 1 | G2: =COUNTIFS(测试用例!C:C,"*1320_001*",测试用例!H:H,"LV3") -> 1 | H2: =COUNTIFS(测试用例!C:C,"*1320_001*",测试用例!H:H,"LV4") -> 0 | I2: =COUNTIFS(测试用例!C:C,"*1320_001*",测试用例!J:J,"是") -> 0 | J2: =COUNTIFS(测试用例!C:C,"*1320_001*",测试用例!I:I,"是") -> 3 | K2: =D2/C2 -> 0.2 | L2: =E2/C2 -> 0.4 | M2: =F2/C2 -> 0.2 | N2: =G2/C2 -> 0.2 | O2: =H2/C2 -> 0 | P2: =J2/C2 -> 0.6 | Q2: 1320 Sprint1
A3: TR_AcuRev1320_002 | B3: 交流电压 | C3: =COUNTIFS(测试用例!C:C,"*1320_002*") -> 24 | D3: =COUNTIFS(测试用例!C:C,"*1320_002*",测试用例!H:H,"LV0") -> 2 | E3: =COUNTIFS(测试用例!C:C,"*1320_002*",测试用例!H:H,"LV1") -> 3 | F3: =COUNTIFS(测试用例!C:C,"*1320_002*",测试用例!H:H,"LV2") -> 11 | G3: =COUNTIFS(测试用例!C:C,"*1320_002*",测试用例!H:H,"LV3") -> 6 | H3: =COUNTIFS(测试用例!C:C,"*1320_002*",测试用例!H:H,"LV4") -> 2 | I3: =COUNTIFS(测试用例!C:C,"*1320_002*",测试用例!J:J,"是") -> 0 | J3: =COUNTIFS(测试用例!C:C,"*1320_002*",测试用例!I:I,"是") -> 13 | K3: =D3/C3 -> 0.083333333 | L3: =E3/C3 -> 0.125 | M3: =F3/C3 -> 0.45833333 | N3: =G3/C3 -> 0.25 | O3: =H3/C3 -> 0.083333333 | P3: =J3/C3 -> 0.54166667 | Q3: 1320 Sprint1
A4: TR_AcuRev1320_003 | B4: 交流电流 | C4: =COUNTIFS(测试用例!C:C,"*1320_003*") -> 33 | D4: =COUNTIFS(测试用例!C:C,"*1320_003*",测试用例!H:H,"LV0") -> 4 | E4: =COUNTIFS(测试用例!C:C,"*1320_003*",测试用例!H:H,"LV1") -> 13 | F4: =COUNTIFS(测试用例!C:C,"*1320_003*",测试用例!H:H,"LV2") -> 14 | G4: =COUNTIFS(测试用例!C:C,"*1320_003*",测试用例!H:H,"LV3") -> 1 | H4: =COUNTIFS(测试用例!C:C,"*1320_003*",测试用例!H:H,"LV4") -> 1 | I4: =COUNTIFS(测试用例!C:C,"*1320_003*",测试用例!J:J,"是") -> 0 | J4: =COUNTIFS(测试用例!C:C,"*1320_003*",测试用例!I:I,"是") -> 11 | K4: =D4/C4 -> 0.12121212 | L4: =E4/C4 -> 0.39393939 | M4: =F4/C4 -> 0.42424242 | N4: =G4/C4 -> 0.03030303 | O4: =H4/C4 -> 0.03030303 | P4: =J4/C4 -> 0.33333333 | Q4: 1320 Sprint1
A5: TR_AcuRev1320_004 | B5: 交流功率 | C5: =COUNTIFS(测试用例!C:C,"*1320_004*") -> 25 | D5: =COUNTIFS(测试用例!C:C,"*1320_004*",测试用例!H:H,"LV0") -> 3 | E5: =COUNTIFS(测试用例!C:C,"*1320_004*",测试用例!H:H,"LV1") -> 5 | F5: =COUNTIFS(测试用例!C:C,"*1320_004*",测试用例!H:H,"LV2") -> 12 | G5: =COUNTIFS(测试用例!C:C,"*1320_004*",测试用例!H:H,"LV3") -> 4 | H5: =COUNTIFS(测试用例!C:C,"*1320_004*",测试用例!H:H,"LV4") -> 1 | I5: =COUNTIFS(测试用例!C:C,"*1320_004*",测试用例!J:J,"是") -> 0 | J5: =COUNTIFS(测试用例!C:C,"*1320_004*",测试用例!I:I,"是") -> 15 | K5: =D5/C5 -> 0.12 | L5: =E5/C5 -> 0.2 | M5: =F5/C5 -> 0.48 | N5: =G5/C5 -> 0.16 | O5: =H5/C5 -> 0.04 | P5: =J5/C5 -> 0.6 | Q5: 1320 Sprint1
A6: TR_AcuRev1320_005 | B6: 负载特性(RLC) | C6: =COUNTIFS(测试用例!C:C,"*1320_005*") -> 21 | D6: =COUNTIFS(测试用例!C:C,"*1320_005*",测试用例!H:H,"LV0") -> 2 | E6: =COUNTIFS(测试用例!C:C,"*1320_005*",测试用例!H:H,"LV1") -> 6 | F6: =COUNTIFS(测试用例!C:C,"*1320_005*",测试用例!H:H,"LV2") -> 9 | G6: =COUNTIFS(测试用例!C:C,"*1320_005*",测试用例!H:H,"LV3") -> 4 | H6: =COUNTIFS(测试用例!C:C,"*1320_005*",测试用例!H:H,"LV4") -> 0 | I6: =COUNTIFS(测试用例!C:C,"*1320_005*",测试用例!J:J,"是") -> 0 | J6: =COUNTIFS(测试用例!C:C,"*1320_005*",测试用例!I:I,"是") -> 11 | K6: =D6/C6 -> 0.095238095 | L6: =E6/C6 -> 0.28571429 | M6: =F6/C6 -> 0.42857143 | N6: =G6/C6 -> 0.19047619 | O6: =H6/C6 -> 0 | P6: =J6/C6 -> 0.52380952 | Q6: 1320 Sprint1
A7: TR_AcuRev1320_006 | B7: 相角(phase angle) | C7: =COUNTIFS(测试用例!C:C,"*1320_006*") -> 14 | D7: =COUNTIFS(测试用例!C:C,"*1320_006*",测试用例!H:H,"LV0") -> 3 | E7: =COUNTIFS(测试用例!C:C,"*1320_006*",测试用例!H:H,"LV1") -> 2 | F7: =COUNTIFS(测试用例!C:C,"*1320_006*",测试用例!H:H,"LV2") -> 9 | G7: =COUNTIFS(测试用例!C:C,"*1320_006*",测试用例!H:H,"LV3") -> 0 | H7: =COUNTIFS(测试用例!C:C,"*1320_006*",测试用例!H:H,"LV4") -> 0 | I7: =COUNTIFS(测试用例!C:C,"*1320_006*",测试用例!J:J,"是") -> 0 | J7: =COUNTIFS(测试用例!C:C,"*1320_006*",测试用例!I:I,"是") -> 4 | K7: =D7/C7 -> 0.21428571 | L7: =E7/C7 -> 0.14285714 | M7: =F7/C7 -> 0.64285714 | N7: =G7/C7 -> 0 | O7: =H7/C7 -> 0 | P7: =J7/C7 -> 0.28571429 | Q7: 1320 Sprint1
A8: TR_AcuRev1320_007 | B8: 各次谐波 | C8: =COUNTIFS(测试用例!C:C,"*1320_007*") -> 34 | D8: =COUNTIFS(测试用例!C:C,"*1320_007*",测试用例!H:H,"LV0") -> 3 | E8: =COUNTIFS(测试用例!C:C,"*1320_007*",测试用例!H:H,"LV1") -> 6 | F8: =COUNTIFS(测试用例!C:C,"*1320_007*",测试用例!H:H,"LV2") -> 16 | G8: =COUNTIFS(测试用例!C:C,"*1320_007*",测试用例!H:H,"LV3") -> 7 | H8: =COUNTIFS(测试用例!C:C,"*1320_007*",测试用例!H:H,"LV4") -> 2 | I8: =COUNTIFS(测试用例!C:C,"*1320_007*",测试用例!J:J,"是") -> 0 | J8: =COUNTIFS(测试用例!C:C,"*1320_007*",测试用例!I:I,"是") -> 0 | K8: =D8/C8 -> 0.088235294 | L8: =E8/C8 -> 0.17647059 | M8: =F8/C8 -> 0.47058824 | N8: =G8/C8 -> 0.20588235 | O8: =H8/C8 -> 0.058823529 | P8: =J8/C8 -> 0 | Q8: 1320 Sprint1
A9: TR_AcuRev1320_008 | B9: 谐波因数 | C9: =COUNTIFS(测试用例!C:C,"*1320_008*") -> 12 | D9: =COUNTIFS(测试用例!C:C,"*1320_008*",测试用例!H:H,"LV0") -> 1 | E9: =COUNTIFS(测试用例!C:C,"*1320_008*",测试用例!H:H,"LV1") -> 2 | F9: =COUNTIFS(测试用例!C:C,"*1320_008*",测试用例!H:H,"LV2") -> 4 | G9: =COUNTIFS(测试用例!C:C,"*1320_008*",测试用例!H:H,"LV3") -> 1 | H9: =COUNTIFS(测试用例!C:C,"*1320_008*",测试用例!H:H,"LV4") -> 2 | I9: =COUNTIFS(测试用例!C:C,"*1320_008*",测试用例!J:J,"是") -> 0 | J9: =COUNTIFS(测试用例!C:C,"*1320_008*",测试用例!I:I,"是") -> 0 | K9: =D9/C9 -> 0.083333333 | L9: =E9/C9 -> 0.16666667 | M9: =F9/C9 -> 0.33333333 | N9: =G9/C9 -> 0.083333333 | O9: =H9/C9 -> 0.16666667 | P9: =J9/C9 -> 0 | Q9: 1320 Sprint1
A10: TR_AcuRev1320_009 | B10: 电能质量测量 | C10: =COUNTIFS(测试用例!C:C,"*1320_009*") -> 54 | D10: =COUNTIFS(测试用例!C:C,"*1320_009*",测试用例!H:H,"LV0") -> 6 | E10: =COUNTIFS(测试用例!C:C,"*1320_009*",测试用例!H:H,"LV1") -> 16 | F10: =COUNTIFS(测试用例!C:C,"*1320_009*",测试用例!H:H,"LV2") -> 21 | G10: =COUNTIFS(测试用例!C:C,"*1320_009*",测试用例!H:H,"LV3") -> 8 | H10: =COUNTIFS(测试用例!C:C,"*1320_009*",测试用例!H:H,"LV4") -> 3 | I10: =COUNTIFS(测试用例!C:C,"*1320_009*",测试用例!J:J,"是") -> 0 | J10: =COUNTIFS(测试用例!C:C,"*1320_009*",测试用例!I:I,"是") -> 41 | K10: =D10/C10 -> 0.11111111 | L10: =E10/C10 -> 0.2962963 | M10: =F10/C10 -> 0.38888889 | N10: =G10/C10 -> 0.14814815 | O10: =H10/C10 -> 0.055555556 | P10: =J10/C10 -> 0.75925926 | Q10: 1320 Sprint1 | R10: 丛松
A11: TR_AcuRev1320_010 | B11: 电能测量 | C11: =COUNTIFS(测试用例!C:C,"*1320_010*") -> 114 | D11: =COUNTIFS(测试用例!C:C,"*1320_010*",测试用例!H:H,"LV0") -> 10 | E11: =COUNTIFS(测试用例!C:C,"*1320_010*",测试用例!H:H,"LV1") -> 19 | F11: =COUNTIFS(测试用例!C:C,"*1320_010*",测试用例!H:H,"LV2") -> 48 | G11: =COUNTIFS(测试用例!C:C,"*1320_010*",测试用例!H:H,"LV3") -> 22 | H11: =COUNTIFS(测试用例!C:C,"*1320_010*",测试用例!H:H,"LV4") -> 10 | I11: =COUNTIFS(测试用例!C:C,"*1320_010*",测试用例!J:J,"是") -> 0 | J11: =COUNTIFS(测试用例!C:C,"*1320_010*",测试用例!I:I,"是") -> 57 | K11: =D11/C11 -> 0.087719298 | L11: =E11/C11 -> 0.16666667 | M11: =F11/C11 -> 0.42105263 | N11: =G11/C11 -> 0.19298246 | O11: =H11/C11 -> 0.087719298 | P11: =J11/C11 -> 0.5 | Q11: 1320 Sprint1
A12: TR_AcuRev1320_011 | B12: 需量测量 | C12: =COUNTIFS(测试用例!C:C,"*1320_011*") -> 29 | D12: =COUNTIFS(测试用例!C:C,"*1320_011*",测试用例!H:H,"LV0") -> 3 | E12: =COUNTIFS(测试用例!C:C,"*1320_011*",测试用例!H:H,"LV1") -> 2 | F12: =COUNTIFS(测试用例!C:C,"*1320_011*",测试用例!H:H,"LV2") -> 14 | G12: =COUNTIFS(测试用例!C:C,"*1320_011*",测试用例!H:H,"LV3") -> 5 | H12: =COUNTIFS(测试用例!C:C,"*1320_011*",测试用例!H:H,"LV4") -> 5 | I12: =COUNTIFS(测试用例!C:C,"*1320_011*",测试用例!J:J,"是") -> 0 | J12: =COUNTIFS(测试用例!C:C,"*1320_011*",测试用例!I:I,"是") -> 0 | K12: =D12/C12 -> 0.10344828 | L12: =E12/C12 -> 0.068965517 | M12: =F12/C12 -> 0.48275862 | N12: =G12/C12 -> 0.17241379 | O12: =H12/C12 -> 0.17241379 | P12: =J12/C12 -> 0 | Q12: 1320 Sprint1 | R12: 王洋&胡赞
A13: TR_AcuRev1320_012 | B13: 接线配置 | C13: =COUNTIFS(测试用例!C:C,"*1320_012*") -> 46 | D13: =COUNTIFS(测试用例!C:C,"*1320_012*",测试用例!H:H,"LV0") -> 4 | E13: =COUNTIFS(测试用例!C:C,"*1320_012*",测试用例!H:H,"LV1") -> 28 | F13: =COUNTIFS(测试用例!C:C,"*1320_012*",测试用例!H:H,"LV2") -> 7 | G13: =COUNTIFS(测试用例!C:C,"*1320_012*",测试用例!H:H,"LV3") -> 3 | H13: =COUNTIFS(测试用例!C:C,"*1320_012*",测试用例!H:H,"LV4") -> 4 | I13: =COUNTIFS(测试用例!C:C,"*1320_012*",测试用例!J:J,"是") -> 0 | J13: =COUNTIFS(测试用例!C:C,"*1320_012*",测试用例!I:I,"是") -> 0 | K13: =D13/C13 -> 0.086956522 | L13: =E13/C13 -> 0.60869565 | M13: =F13/C13 -> 0.15217391 | N13: =G13/C13 -> 0.065217391 | O13: =H13/C13 -> 0.086956522 | P13: =J13/C13 -> 0 | Q13: 1320 Sprint1
A14: TR_AcuRev1320_013 | B14: 时分用电 | C14: =COUNTIFS(测试用例!C:C,"*1320_013*") -> 91 | D14: =COUNTIFS(测试用例!C:C,"*1320_013*",测试用例!H:H,"LV0") -> 6 | E14: =COUNTIFS(测试用例!C:C,"*1320_013*",测试用例!H:H,"LV1") -> 25 | F14: =COUNTIFS(测试用例!C:C,"*1320_013*",测试用例!H:H,"LV2") -> 38 | G14: =COUNTIFS(测试用例!C:C,"*1320_013*",测试用例!H:H,"LV3") -> 18 | H14: =COUNTIFS(测试用例!C:C,"*1320_013*",测试用例!H:H,"LV4") -> 0 | I14: =COUNTIFS(测试用例!C:C,"*1320_013*",测试用例!J:J,"是") -> 0 | J14: =COUNTIFS(测试用例!C:C,"*1320_013*",测试用例!I:I,"是") -> 0 | K14: =D14/C14 -> 0.065934066 | L14: =E14/C14 -> 0.27472527 | M14: =F14/C14 -> 0.41758242 | N14: =G14/C14 -> 0.1978022 | O14: =H14/C14 -> 0 | P14: =J14/C14 -> 0 | Q14: 1320 Sprint1 | R14: 刘丛松
A15: TR_AcuRev1320_014 | B15: 电能质量事件 | C15: =COUNTIFS(测试用例!C:C,"*1320_014*") -> 138 | D15: =COUNTIFS(测试用例!C:C,"*1320_014*",测试用例!H:H,"LV0") -> 14 | E15: =COUNTIFS(测试用例!C:C,"*1320_014*",测试用例!H:H,"LV1") -> 19 | F15: =COUNTIFS(测试用例!C:C,"*1320_014*",测试用例!H:H,"LV2") -> 90 | G15: =COUNTIFS(测试用例!C:C,"*1320_014*",测试用例!H:H,"LV3") -> 11 | H15: =COUNTIFS(测试用例!C:C,"*1320_014*",测试用例!H:H,"LV4") -> 3 | I15: =COUNTIFS(测试用例!C:C,"*1320_014*",测试用例!J:J,"是") -> 0 | J15: =COUNTIFS(测试用例!C:C,"*1320_014*",测试用例!I:I,"是") -> 0 | K15: =D15/C15 -> 0.10144928 | L15: =E15/C15 -> 0.13768116 | M15: =F15/C15 -> 0.65217391 | N15: =G15/C15 -> 0.079710145 | O15: =H15/C15 -> 0.02173913 | P15: =J15/C15 -> 0 | Q15: 1320 Sprint1
A16: TR_AcuRev1320_015 | B16: 告警功能 | C16: =COUNTIFS(测试用例!C:C,"*1320_015*") -> 93 | D16: =COUNTIFS(测试用例!C:C,"*1320_015*",测试用例!H:H,"LV0") -> 5 | E16: =COUNTIFS(测试用例!C:C,"*1320_015*",测试用例!H:H,"LV1") -> 24 | F16: =COUNTIFS(测试用例!C:C,"*1320_015*",测试用例!H:H,"LV2") -> 50 | G16: =COUNTIFS(测试用例!C:C,"*1320_015*",测试用例!H:H,"LV3") -> 13 | H16: =COUNTIFS(测试用例!C:C,"*1320_015*",测试用例!H:H,"LV4") -> 0 | I16: =COUNTIFS(测试用例!C:C,"*1320_015*",测试用例!J:J,"是") -> 0 | J16: =COUNTIFS(测试用例!C:C,"*1320_015*",测试用例!I:I,"是") -> 0 | K16: =D16/C16 -> 0.053763441 | L16: =E16/C16 -> 0.25806452 | M16: =F16/C16 -> 0.53763441 | N16: =G16/C16 -> 0.13978495 | O16: =H16/C16 -> 0 | P16: =J16/C16 -> 0 | Q16: 1320 Sprint1 | R16: 王丽红
A17: TR_AcuRev1320_016 | B17: 记录与统计 | C17: =COUNTIFS(测试用例!C:C,"*1320_016*") -> 48 | D17: =COUNTIFS(测试用例!C:C,"*1320_016*",测试用例!H:H,"LV0") -> 4 | E17: =COUNTIFS(测试用例!C:C,"*1320_016*",测试用例!H:H,"LV1") -> 10 | F17: =COUNTIFS(测试用例!C:C,"*1320_016*",测试用例!H:H,"LV2") -> 20 | G17: =COUNTIFS(测试用例!C:C,"*1320_016*",测试用例!H:H,"LV3") -> 11 | H17: =COUNTIFS(测试用例!C:C,"*1320_016*",测试用例!H:H,"LV4") -> 3 | I17: =COUNTIFS(测试用例!C:C,"*1320_016*",测试用例!J:J,"是") -> 0 | J17: =COUNTIFS(测试用例!C:C,"*1320_016*",测试用例!I:I,"是") -> 0 | K17: =D17/C17 -> 0.083333333 | L17: =E17/C17 -> 0.20833333 | M17: =F17/C17 -> 0.41666667 | N17: =G17/C17 -> 0.22916667 | O17: =H17/C17 -> 0.0625 | P17: =J17/C17 -> 0 | Q17: 1320 Sprint1
A18: TR_AcuRev1320_017 | B18: DATA Log | C18: =COUNTIFS(测试用例!C:C,"*1320_017*") -> 76 | D18: =COUNTIFS(测试用例!C:C,"*1320_017*",测试用例!H:H,"LV0") -> 4 | E18: =COUNTIFS(测试用例!C:C,"*1320_017*",测试用例!H:H,"LV1") -> 12 | F18: =COUNTIFS(测试用例!C:C,"*1320_017*",测试用例!H:H,"LV2") -> 34 | G18: =COUNTIFS(测试用例!C:C,"*1320_017*",测试用例!H:H,"LV3") -> 17 | H18: =COUNTIFS(测试用例!C:C,"*1320_017*",测试用例!H:H,"LV4") -> 9 | I18: =COUNTIFS(测试用例!C:C,"*1320_017*",测试用例!J:J,"是") -> 0 | J18: =COUNTIFS(测试用例!C:C,"*1320_017*",测试用例!I:I,"是") -> 0 | K18: =D18/C18 -> 0.052631579 | L18: =E18/C18 -> 0.15789474 | M18: =F18/C18 -> 0.44736842 | N18: =G18/C18 -> 0.22368421 | O18: =H18/C18 -> 0.11842105 | P18: =J18/C18 -> 0 | Q18: 1320 Sprint1
A19: TR_AcuRev1320_018 | B19: Input&Output | C19: =COUNTIFS(测试用例!C:C,"*1320_018*") -> 59 | D19: =COUNTIFS(测试用例!C:C,"*1320_018*",测试用例!H:H,"LV0") -> 4 | E19: =COUNTIFS(测试用例!C:C,"*1320_018*",测试用例!H:H,"LV1") -> 12 | F19: =COUNTIFS(测试用例!C:C,"*1320_018*",测试用例!H:H,"LV2") -> 26 | G19: =COUNTIFS(测试用例!C:C,"*1320_018*",测试用例!H:H,"LV3") -> 15 | H19: =COUNTIFS(测试用例!C:C,"*1320_018*",测试用例!H:H,"LV4") -> 2 | I19: =COUNTIFS(测试用例!C:C,"*1320_018*",测试用例!J:J,"是") -> 0 | J19: =COUNTIFS(测试用例!C:C,"*1320_018*",测试用例!I:I,"是") -> 0 | K19: =D19/C19 -> 0.06779661 | L19: =E19/C19 -> 0.20338983 | M19: =F19/C19 -> 0.44067797 | N19: =G19/C19 -> 0.25423729 | O19: =H19/C19 -> 0.033898305 | P19: =J19/C19 -> 0 | Q19: 1320 Sprint1
A20: TR_AcuRev1320_019 | B20: 计时功能 | C20: =COUNTIFS(测试用例!C:C,"*1320_019*") -> 28 | D20: =COUNTIFS(测试用例!C:C,"*1320_019*",测试用例!H:H,"LV0") -> 1 | E20: =COUNTIFS(测试用例!C:C,"*1320_019*",测试用例!H:H,"LV1") -> 5 | F20: =COUNTIFS(测试用例!C:C,"*1320_019*",测试用例!H:H,"LV2") -> 14 | G20: =COUNTIFS(测试用例!C:C,"*1320_019*",测试用例!H:H,"LV3") -> 6 | H20: =COUNTIFS(测试用例!C:C,"*1320_019*",测试用例!H:H,"LV4") -> 2 | I20: =COUNTIFS(测试用例!C:C,"*1320_019*",测试用例!J:J,"是") -> 0 | J20: =COUNTIFS(测试用例!C:C,"*1320_019*",测试用例!I:I,"是") -> 0 | K20: =D20/C20 -> 0.035714286 | L20: =E20/C20 -> 0.17857143 | M20: =F20/C20 -> 0.5 | N20: =G20/C20 -> 0.21428571 | O20: =H20/C20 -> 0.071428571 | P20: =J20/C20 -> 0 | Q20: 1320 Sprint1
A21: TR_AcuRev1320_020 | B21: 数据重置及恢复出厂设置 | C21: =COUNTIFS(测试用例!C:C,"*1320_020*") -> 32 | D21: =COUNTIFS(测试用例!C:C,"*1320_020*",测试用例!H:H,"LV0") -> 2 | E21: =COUNTIFS(测试用例!C:C,"*1320_020*",测试用例!H:H,"LV1") -> 9 | F21: =COUNTIFS(测试用例!C:C,"*1320_020*",测试用例!H:H,"LV2") -> 13 | G21: =COUNTIFS(测试用例!C:C,"*1320_020*",测试用例!H:H,"LV3") -> 5 | H21: =COUNTIFS(测试用例!C:C,"*1320_020*",测试用例!H:H,"LV4") -> 3 | I21: =COUNTIFS(测试用例!C:C,"*1320_020*",测试用例!J:J,"是") -> 0 | J21: =COUNTIFS(测试用例!C:C,"*1320_020*",测试用例!I:I,"是") -> 0 | K21: =D21/C21 -> 0.0625 | L21: =E21/C21 -> 0.28125 | M21: =F21/C21 -> 0.40625 | N21: =G21/C21 -> 0.15625 | O21: =H21/C21 -> 0.09375 | P21: =J21/C21 -> 0 | Q21: 1320 Sprint1
A22: TR_AcuRev1320_021 | B22: 网络模块 | C22: =COUNTIFS(测试用例!C:C,"*1320_021*") -> 85 | D22: =COUNTIFS(测试用例!C:C,"*1320_021*",测试用例!H:H,"LV0") -> 3 | E22: =COUNTIFS(测试用例!C:C,"*1320_021*",测试用例!H:H,"LV1") -> 23 | F22: =COUNTIFS(测试用例!C:C,"*1320_021*",测试用例!H:H,"LV2") -> 32 | G22: =COUNTIFS(测试用例!C:C,"*1320_021*",测试用例!H:H,"LV3") -> 16 | H22: =COUNTIFS(测试用例!C:C,"*1320_021*",测试用例!H:H,"LV4") -> 11 | I22: =COUNTIFS(测试用例!C:C,"*1320_021*",测试用例!J:J,"是") -> 0 | J22: =COUNTIFS(测试用例!C:C,"*1320_021*",测试用例!I:I,"是") -> 0 | K22: =D22/C22 -> 0.035294118 | L22: =E22/C22 -> 0.27058824 | M22: =F22/C22 -> 0.37647059 | N22: =G22/C22 -> 0.18823529 | O22: =H22/C22 -> 0.12941176 | P22: =J22/C22 -> 0 | Q22: 1320 Sprint1
A23: TR_AcuRev1320_022 | B23: BACnet通信协议 | C23: =COUNTIFS(测试用例!C:C,"*1320_022*") -> 23 | D23: =COUNTIFS(测试用例!C:C,"*1320_022*",测试用例!H:H,"LV0") -> 2 | E23: =COUNTIFS(测试用例!C:C,"*1320_022*",测试用例!H:H,"LV1") -> 12 | F23: =COUNTIFS(测试用例!C:C,"*1320_022*",测试用例!H:H,"LV2") -> 5 | G23: =COUNTIFS(测试用例!C:C,"*1320_022*",测试用例!H:H,"LV3") -> 3 | H23: =COUNTIFS(测试用例!C:C,"*1320_022*",测试用例!H:H,"LV4") -> 1 | I23: =COUNTIFS(测试用例!C:C,"*1320_022*",测试用例!J:J,"是") -> 0 | J23: =COUNTIFS(测试用例!C:C,"*1320_022*",测试用例!I:I,"是") -> 0 | K23: =D23/C23 -> 0.086956522 | L23: =E23/C23 -> 0.52173913 | M23: =F23/C23 -> 0.2173913 | N23: =G23/C23 -> 0.13043478 | O23: =H23/C23 -> 0.043478261 | P23: =J23/C23 -> 0 | Q23: 1320 Sprint1 | R23: 王丽红
A24: TR_AcuRev1320_023 | B24: Firmware升级 | C24: =COUNTIFS(测试用例!C:C,"*1320_023*") -> 40 | D24: =COUNTIFS(测试用例!C:C,"*1320_023*",测试用例!H:H,"LV0") -> 2 | E24: =COUNTIFS(测试用例!C:C,"*1320_023*",测试用例!H:H,"LV1") -> 8 | F24: =COUNTIFS(测试用例!C:C,"*1320_023*",测试用例!H:H,"LV2") -> 18 | G24: =COUNTIFS(测试用例!C:C,"*1320_023*",测试用例!H:H,"LV3") -> 11 | H24: =COUNTIFS(测试用例!C:C,"*1320_023*",测试用例!H:H,"LV4") -> 1 | I24: =COUNTIFS(测试用例!C:C,"*1320_023*",测试用例!J:J,"是") -> 0 | J24: =COUNTIFS(测试用例!C:C,"*1320_023*",测试用例!I:I,"是") -> 0 | K24: =D24/C24 -> 0.05 | L24: =E24/C24 -> 0.2 | M24: =F24/C24 -> 0.45 | N24: =G24/C24 -> 0.275 | O24: =H24/C24 -> 0.025 | P24: =J24/C24 -> 0 | Q24: 1320 Sprint1 | R24: 胡赞
A25: TR_AcuRev1320_024 | B25: 铅封功能 | C25: =COUNTIFS(测试用例!C:C,"*1320_024*") -> 61 | D25: =COUNTIFS(测试用例!C:C,"*1320_024*",测试用例!H:H,"LV0") -> 2 | E25: =COUNTIFS(测试用例!C:C,"*1320_024*",测试用例!H:H,"LV1") -> 13 | F25: =COUNTIFS(测试用例!C:C,"*1320_024*",测试用例!H:H,"LV2") -> 32 | G25: =COUNTIFS(测试用例!C:C,"*1320_024*",测试用例!H:H,"LV3") -> 9 | H25: =COUNTIFS(测试用例!C:C,"*1320_024*",测试用例!H:H,"LV4") -> 4 | I25: =COUNTIFS(测试用例!C:C,"*1320_024*",测试用例!J:J,"是") -> 0 | J25: =COUNTIFS(测试用例!C:C,"*1320_024*",测试用例!I:I,"是") -> 0 | K25: =D25/C25 -> 0.032786885 | L25: =E25/C25 -> 0.21311475 | M25: =F25/C25 -> 0.52459016 | N25: =G25/C25 -> 0.14754098 | O25: =H25/C25 -> 0.06557377 | P25: =J25/C25 -> 0 | Q25: 1320 Sprint1
A26: TR_AcuRev1320_025 | B26: 校准功能 | C26: =COUNTIFS(测试用例!C:C,"*1320_025*") -> 6 | D26: =COUNTIFS(测试用例!C:C,"*1320_025*",测试用例!H:H,"LV0") -> 4 | E26: =COUNTIFS(测试用例!C:C,"*1320_025*",测试用例!H:H,"LV1") -> 0 | F26: =COUNTIFS(测试用例!C:C,"*1320_025*",测试用例!H:H,"LV2") -> 0 | G26: =COUNTIFS(测试用例!C:C,"*1320_025*",测试用例!H:H,"LV3") -> 1 | H26: =COUNTIFS(测试用例!C:C,"*1320_025*",测试用例!H:H,"LV4") -> 1 | I26: =COUNTIFS(测试用例!C:C,"*1320_025*",测试用例!J:J,"是") -> 0 | J26: =COUNTIFS(测试用例!C:C,"*1320_025*",测试用例!I:I,"是") -> 0 | K26: =D26/C26 -> 0.66666667 | L26: =E26/C26 -> 0 | M26: =F26/C26 -> 0 | N26: =G26/C26 -> 0.16666667 | O26: =H26/C26 -> 0.16666667 | P26: =J26/C26 -> 0 | Q26: 1320 Sprint1
