Workbook

Sheet block
A1: blockId | B1: type | C1: start | D1: count | E1: isEnable | F1: NAME
A2: 0 | B2: VIRTUAL_BLOCK | C2: 0 | D2: 1 | E2: true | F2: isOnline
A3: 1 | B3: HOLDING_REGISTER | C3: 8192 | D3: 72 | E3: true | F3: System Basic Reading | G3: =C3+D3 -> 8264
A4: 2 | B4: HOLDING_REGISTER | C4: 8264 | D4: 112 | E4: true | F4: Input Channal Basic Reading 1 | G4: =C4+D4 -> 8376
A5: 3 | B5: HOLDING_REGISTER | C5: 8376 | D5: 112 | E5: true | F5: Input Channal Basic Reading 2 | G5: =C5+D5 -> 8488
A6: 4 | B6: HOLDING_REGISTER | C6: 8488 | D6: 112 | E6: true | F6: Input Channal Basic Reading 3 | G6: =C6+D6 -> 8600
A7: 5 | B7: HOLDING_REGISTER | C7: 8600 | D7: 72 | E7: true | F7: User Channal Basic Reading 1 | G7: =C7+D7 -> 8672
A8: 6 | B8: HOLDING_REGISTER | C8: 8672 | D8: 72 | E8: true | F8: User Channal Basic Reading 2 | G8: =C8+D8 -> 8744
A9: 7 | B9: HOLDING_REGISTER | C9: 8960 | D9: 48 | E9: true | F9: Demand 1 | G9: =C9+D9 -> 9008
A10: 8 | B10: HOLDING_REGISTER | C10: 9008 | D10: 96 | E10: true | F10: Demand 2 | G10: =C10+D10 -> 9104
A11: 9 | B11: HOLDING_REGISTER | C11: 9104 | D11: 96 | E11: true | F11: Demand 3 | G11: =C11+D11 -> 9200
A12: 10 | B12: HOLDING_REGISTER | C12: 9200 | D12: 96 | E12: true | F12: Demand 4 | G12: =C12+D12 -> 9296
A13: 11 | B13: HOLDING_REGISTER | C13: 9296 | D13: 72 | E13: true | F13: Demand 5 | G13: =C13+D13 -> 9368
A14: 12 | B14: HOLDING_REGISTER | C14: 9368 | D14: 72 | E14: true | F14: Demand 6 | G14: =C14+D14 -> 9440
... A107: 105 | B107: HOLDING_REGISTER | C107: 4352 | D107: 42 | E107: true | F107: Device Settings Basic 3 | G107: =C107+D107 -> 4394
A108: 106 | B108: HOLDING_REGISTER | C108: 4400 | D108: 21 | E108: true | F108: Device Settings Basic 4 | G108: =C108+D108 -> 4421 | K108: Energy pulse constant
A109: 107 | B109: HOLDING_REGISTER | C109: 25344 | D109: 2 | E109: true | F109: SOE Log Status | G109: =C109+D109 -> 25346 | K109: Pulse Constant

Sheet blockParams
A1: ID | B1: blockId | C1: paramId | D1: Start(Dec) | E1: descrption | F1: paramType | G1: unit | H1: dataType | I1: byteOrder | J1: RW | K1: Reg | L1: scale | M1: analysisUnitId | N1: north | O1: conf | P1: range | Q1: readings | S1: paramType
A2: 1 | B2: 0 | C2: =B2 & "-" & COUNTIF($B$2:B2, B2) -> 0-1 | D2: 0 | E2: IsOnline | F2: IsOnline | H2: isOnline | I2: 1 | J2: R | K2: 1 | L2: 1 | P2: 7 | S2: IsOnline
A3: 2 | B3: =_xlfn.XLOOKUP(1,(VALUE(D3)>=VALUE(block!$C$3:$C$500))*(VALUE(D3)<VALUE(block!$C$3:$C$500)+VALUE(block!$D$3:$D$500)),block!$A$3:$A$500,"无匹配",0,1) -> 1 | C3: =B3 & "-" & COUNTIF($B$2:B3, B3) -> 1-1 | D3: 8192 | E3: System Frequency | F3: FREQ_Hz | G3: Hz | H3: float32 | I3: =IF(H3="uint16",1,IF(H3="int16",3,IF(H3="uint32",6,IF(H3="int32",10,IF(H3="uint64",14,IF(H3="int64",18,IF(H3="float32",22,""))))))) -> 22 | J3: R | K3: 2 | L3: 1 | N3: 4 | P3: 4-7-8-40 | Q3: 9-2-35-1 | S3: FREQ_Hz
A4: 3 | B4: =_xlfn.XLOOKUP(1,(VALUE(D4)>=VALUE(block!$C$3:$C$500))*(VALUE(D4)<VALUE(block!$C$3:$C$500)+VALUE(block!$D$3:$D$500)),block!$A$3:$A$500,"无匹配",0,1) -> 1 | C4: =B4 & "-" & COUNTIF($B$2:B4, B4) -> 1-2 | D4: 8194 | E4: Phase A Line-to-Neutral Voltage | F4: VLN_a_V | G4: V | H4: float32 | I4: =_xlfn.XLOOKUP(1,(VALUE(L3866)>=VALUE(block!$C$3:'block'!$C$500))*(VALUE(block!L3866)<VALUE(block!$C$3:'block'!$C$500)+VALUE(block!$D$3:'block'!$D$500)),block!$A$3:'block'!$A$500,"无匹配",0,1) -> 55 | J4: R | K4: 2 | L4: 1 | N4: 4 | P4: 4-7-8-40 | Q4: 9-2-35-1 | S4: VLN_a_V
A5: 4 | B5: =_xlfn.XLOOKUP(1,(VALUE(D5)>=VALUE(block!$C$3:$C$500))*(VALUE(D5)<VALUE(block!$C$3:$C$500)+VALUE(block!$D$3:$D$500)),block!$A$3:$A$500,"无匹配",0,1) -> 1 | C5: =B5 & "-" & COUNTIF($B$2:B5, B5) -> 1-3 | D5: 8196 | E5: Phase B Line-to-Neutral Voltage | F5: VLN_b_V | G5: V | H5: float32 | I5: =_xlfn.XLOOKUP(1,(VALUE(L3867)>=VALUE(block!$C$3:'block'!$C$500))*(VALUE(block!L3867)<VALUE(block!$C$3:'block'!$C$500)+VALUE(block!$D$3:'block'!$D$500)),block!$A$3:'block'!$A$500,"无匹配",0,1) -> 55 | J5: R | K5: 2 | L5: 1 | N5: 4 | P5: 4-7-8-40 | Q5: 9-2-35-1 | S5: VLN_b_V
A6: 5 | B6: =_xlfn.XLOOKUP(1,(VALUE(D6)>=VALUE(block!$C$3:$C$500))*(VALUE(D6)<VALUE(block!$C$3:$C$500)+VALUE(block!$D$3:$D$500)),block!$A$3:$A$500,"无匹配",0,1) -> 1 | C6: =B6 & "-" & COUNTIF($B$2:B6, B6) -> 1-4 | D6: 8198 | E6: Phase C Line-to-Neutral Voltage | F6: VLN_c_V | G6: V | H6: float32 | I6: =_xlfn.XLOOKUP(1,(VALUE(L3868)>=VALUE(block!$C$3:'block'!$C$500))*(VALUE(block!L3868)<VALUE(block!$C$3:'block'!$C$500)+VALUE(block!$D$3:'block'!$D$500)),block!$A$3:'block'!$A$500,"无匹配",0,1) -> 55 | J6: R | K6: 2 | L6: 1 | N6: 4 | P6: 4-7-8-40 | Q6: 9-2-35-1 | S6: VLN_c_V
A7: 6 | B7: =_xlfn.XLOOKUP(1,(VALUE(D7)>=VALUE(block!$C$3:$C$500))*(VALUE(D7)<VALUE(block!$C$3:$C$500)+VALUE(block!$D$3:$D$500)),block!$A$3:$A$500,"无匹配",0,1) -> 1 | C7: =B7 & "-" & COUNTIF($B$2:B7, B7) -> 1-5 | D7: 8200 | E7: Average Line-to-Neutral Voltage | F7: VLN_avg_V | G7: V | H7: float32 | I7: =_xlfn.XLOOKUP(1,(VALUE(L3869)>=VALUE(block!$C$3:'block'!$C$500))*(VALUE(block!L3869)<VALUE(block!$C$3:'block'!$C$500)+VALUE(block!$D$3:'block'!$D$500)),block!$A$3:'block'!$A$500,"无匹配",0,1) -> 55 | J7: R | K7: 2 | L7: 1 | N7: 4 | P7: 4-7-8-40 | Q7: 9-2-1 | S7: VLN_avg_V
A8: 7 | B8: =_xlfn.XLOOKUP(1,(VALUE(D8)>=VALUE(block!$C$3:$C$500))*(VALUE(D8)<VALUE(block!$C$3:$C$500)+VALUE(block!$D$3:$D$500)),block!$A$3:$A$500,"无匹配",0,1) -> 1 | C8: =B8 & "-" & COUNTIF($B$2:B8, B8) -> 1-6 | D8: 8202 | E8: Phase A-B Line-to-Line Voltage | F8: VLL_ab_V | G8: V | H8: float32 | I8: =_xlfn.XLOOKUP(1,(VALUE(L3870)>=VALUE(block!$C$3:'block'!$C$500))*(VALUE(block!L3870)<VALUE(block!$C$3:'block'!$C$500)+VALUE(block!$D$3:'block'!$D$500)),block!$A$3:'block'!$A$500,"无匹配",0,1) -> 55 | J8: R | K8: 2 | L8: 1 | N8: 4 | P8: 4-7-8-40 | Q8: 9-2-1 | S8: VLL_ab_V
A9: 8 | B9: =_xlfn.XLOOKUP(1,(VALUE(D9)>=VALUE(block!$C$3:$C$500))*(VALUE(D9)<VALUE(block!$C$3:$C$500)+VALUE(block!$D$3:$D$500)),block!$A$3:$A$500,"无匹配",0,1) -> 1 | C9: =B9 & "-" & COUNTIF($B$2:B9, B9) -> 1-7 | D9: 8204 | E9: Phase B-C Line-to-Line Voltage | F9: VLL_bc_V | G9: V | H9: float32 | I9: =_xlfn.XLOOKUP(1,(VALUE(L3871)>=VALUE(block!$C$3:'block'!$C$500))*(VALUE(block!L3871)<VALUE(block!$C$3:'block'!$C$500)+VALUE(block!$D$3:'block'!$D$500)),block!$A$3:'block'!$A$500,"无匹配",0,1) -> 55 | J9: R | K9: 2 | L9: 1 | N9: 4 | P9: 4-7-8-40 | Q9: 9-2-1 | S9: VLL_bc_V
A10: 9 | B10: =_xlfn.XLOOKUP(1,(VALUE(D10)>=VALUE(block!$C$3:$C$500))*(VALUE(D10)<VALUE(block!$C$3:$C$500)+VALUE(block!$D$3:$D$500)),block!$A$3:$A$500,"无匹配",0,1) -> 1 | C10: =B10 & "-" & COUNTIF($B$2:B10, B10) -> 1-8 | D10: 8206 | E10: Phase C-A Line-to-Line Voltage | F10: VLL_ca_V | G10: V | H10: float32 | I10: =_xlfn.XLOOKUP(1,(VALUE(L3872)>=VALUE(block!$C$3:'block'!$C$500))*(VALUE(block!L3872)<VALUE(block!$C$3:'block'!$C$500)+VALUE(block!$D$3:'block'!$D$500)),block!$A$3:'block'!$A$500,"无匹配",0,1) -> 55 | J10: R | K10: 2 | L10: 1 | N10: 4 | P10: 4-7-8-40 | Q10: 9-2-1 | S10: VLL_ca_V
A11: 10 | B11: =_xlfn.XLOOKUP(1,(VALUE(D11)>=VALUE(block!$C$3:$C$500))*(VALUE(D11)<VALUE(block!$C$3:$C$500)+VALUE(block!$D$3:$D$500)),block!$A$3:$A$500,"无匹配",0,1) -> 1 | C11: =B11 & "-" & COUNTIF($B$2:B11, B11) -> 1-9 | D11: 8208 | E11: Average Line-to-Line Voltage | F11: VLL_avg_V | G11: V | H11: float32 | I11: =_xlfn.XLOOKUP(1,(VALUE(L3873)>=VALUE(block!$C$3:'block'!$C$500))*(VALUE(block!L3873)<VALUE(block!$C$3:'block'!$C$500)+VALUE(block!$D$3:'block'!$D$500)),block!$A$3:'block'!$A$500,"无匹配",0,1) -> 55 | J11: R | K11: 2 | L11: 1 | N11: 4 | P11: 4-7-8-40 | Q11: 9-2-1 | S11: VLL_avg_V
A12: 11 | B12: =_xlfn.XLOOKUP(1,(VALUE(D12)>=VALUE(block!$C$3:$C$500))*(VALUE(D12)<VALUE(block!$C$3:$C$500)+VALUE(block!$D$3:$D$500)),block!$A$3:$A$500,"无匹配",0,1) -> 1 | C12: =B12 & "-" & COUNTIF($B$2:B12, B12) -> 1-10 | D12: 8210 | E12: Phase A Line-to-Neutral Voltage Phase Angle | F12: ANG_VLN_a | G12: ° | H12: float32 | I12: =_xlfn.XLOOKUP(1,(VALUE(L3874)>=VALUE(block!$C$3:'block'!$C$500))*(VALUE(block!L3874)<VALUE(block!$C$3:'block'!$C$500)+VALUE(block!$D$3:'block'!$D$500)),block!$A$3:'block'!$A$500,"无匹配",0,1) -> 55 | J12: R | K12: 2 | L12: 1 | N12: 4 | P12: 4-7-8-40 | Q12: 9-2-1 | S12: ANG_VLN_a
A13: 12 | B13: =_xlfn.XLOOKUP(1,(VALUE(D13)>=VALUE(block!$C$3:$C$500))*(VALUE(D13)<VALUE(block!$C$3:$C$500)+VALUE(block!$D$3:$D$500)),block!$A$3:$A$500,"无匹配",0,1) -> 1 | C13: =B13 & "-" & COUNTIF($B$2:B13, B13) -> 1-11 | D13: 8212 | E13: Phase B Line-to-Neutral Voltage Phase Angle | F13: ANG_VLN_b | G13: ° | H13: float32 | I13: =_xlfn.XLOOKUP(1,(VALUE(L3875)>=VALUE(block!$C$3:'block'!$C$500))*(VALUE(block!L3875)<VALUE(block!$C$3:'block'!$C$500)+VALUE(block!$D$3:'block'!$D$500)),block!$A$3:'block'!$A$500,"无匹配",0,1) -> 55 | J13: R | K13: 2 | L13: 1 | N13: 4 | P13: 4-7-8-40 | Q13: 9-2-1 | S13: ANG_VLN_b
A14: 13 | B14: =_xlfn.XLOOKUP(1,(VALUE(D14)>=VALUE(block!$C$3:$C$500))*(VALUE(D14)<VALUE(block!$C$3:$C$500)+VALUE(block!$D$3:$D$500)),block!$A$3:$A$500,"无匹配",0,1) -> 1 | C14: =B14 & "-" & COUNTIF($B$2:B14, B14) -> 1-12 | D14: 8214 | E14: Phase C Line-to-Neutral Voltage Phase Angle | F14: ANG_VLN_c | G14: ° | H14: float32 | I14: =_xlfn.XLOOKUP(1,(VALUE(L3876)>=VALUE(block!$C$3:'block'!$C$500))*(VALUE(block!L3876)<VALUE(block!$C$3:'block'!$C$500)+VALUE(block!$D$3:'block'!$D$500)),block!$A$3:'block'!$A$500,"无匹配",0,1) -> 55 | J14: R | K14: 2 | L14: 1 | N14: 4 | P14: 4-7-8-40 | Q14: 9-2-1 | S14: ANG_VLN_c
A15: 14 | B15: =_xlfn.XLOOKUP(1,(VALUE(D15)>=VALUE(block!$C$3:$C$500))*(VALUE(D15)<VALUE(block!$C$3:$C$500)+VALUE(block!$D$3:$D$500)),block!$A$3:$A$500,"无匹配",0,1) -> 1 | C15: =B15 & "-" & COUNTIF($B$2:B15, B15) -> 1-13 | D15: 8216 | E15: Phase A Current | F15: I_a_A | G15: A | H15: float32 | I15: =_xlfn.XLOOKUP(1,(VALUE(L3877)>=VALUE(block!$C$3:'block'!$C$500))*(VALUE(block!L3877)<VALUE(block!$C$3:'block'!$C$500)+VALUE(block!$D$3:'block'!$D$500)),block!$A$3:'block'!$A$500,"无匹配",0,1) -> 55 | J15: R | K15: 2 | L15: 1 | N15: 4 | P15: 4-7-8-40 | Q15: 9-2-1 | S15: I_a_A
... A18: 17 | B18: =_xlfn.XLOOKUP(1,(VALUE(D18)>=VALUE(block!$C$3:$C$500))*(VALUE(D18)<VALUE(block!$C$3:$C$500)+VALUE(block!$D$3:$D$500)),block!$A$3:$A$500,"无匹配",0,1) -> 1 | C18: =B18 & "-" & COUNTIF($B$2:B18, B18) -> 1-16 | D18: 8222 | E18: Phase A Apparent Power | F18: S_a_kVA | G18: kVA | H18: float32 | I18: =_xlfn.XLOOKUP(1,(VALUE(L3880)>=VALUE(block!$C$3:'block'!$C$500))*(VALUE(block!L3880)<VALUE(block!$C$3:'block'!$C$500)+VALUE(block!$D$3:'block'!$D$500)),block!$A$3:'block'!$A$500,"无匹配",0,1) -> 55 | J18: R | K18: 2 | L18: 1 | N18: 4 | P18: 4-7-8-40 | Q18: 9-2-1 | S18: S_a_kVA
A19: 18 | B19: =_xlfn.XLOOKUP(1,(VALUE(D19)>=VALUE(block!$C$3:$C$500))*(VALUE(D19)<VALUE(block!$C$3:$C$500)+VALUE(block!$D$3:$D$500)),block!$A$3:$A$500,"无匹配",0,1) -> 1 | C19: =B19 & "-" & COUNTIF($B$2:B19, B19) -> 1-17 | D19: 8224 | E19: Phase A Load Nature | F19: LC_a | H19: uint32 | I19: =_xlfn.XLOOKUP(1,(VALUE(L3881)>=VALUE(block!$C$3:'block'!$C$500))*(VALUE(block!L3881)<VALUE(block!$C$3:'block'!$C$500)+VALUE(block!$D$3:'block'!$D$500)),block!$A$3:'block'!$A$500,"无匹配",0,1) -> 55 | J19: R | K19: 2 | L19: 1 | Q19: 9
A20: 19 | B20: =_xlfn.XLOOKUP(1,(VALUE(D20)>=VALUE(block!$C$3:$C$500))*(VALUE(D20)<VALUE(block!$C$3:$C$500)+VALUE(block!$D$3:$D$500)),block!$A$3:$A$500,"无匹配",0,1) -> 1 | C20: =B20 & "-" & COUNTIF($B$2:B20, B20) -> 1-18 | D20: 8226 | E20: Phase A Power Factor | F20: PF_a | G20: % | H20: float32 | I20: =_xlfn.XLOOKUP(1,(VALUE(L3882)>=VALUE(block!$C$3:'block'!$C$500))*(VALUE(block!L3882)<VALUE(block!$C$3:'block'!$C$500)+VALUE(block!$D$3:'block'!$D$500)),block!$A$3:'block'!$A$500,"无匹配",0,1) -> 55 | J20: R | K20: 2 | L20: 1 | N20: 4 | P20: 4-7-8-40 | Q20: 9 | S20: PF_a
A21: 20 | B21: =_xlfn.XLOOKUP(1,(VALUE(D21)>=VALUE(block!$C$3:$C$500))*(VALUE(D21)<VALUE(block!$C$3:$C$500)+VALUE(block!$D$3:$D$500)),block!$A$3:$A$500,"无匹配",0,1) -> 1 | C21: =B21 & "-" & COUNTIF($B$2:B21, B21) -> 1-19 | D21: 8228 | E21: Phase B Current | F21: I_b_A | G21: A | H21: float32 | I21: =_xlfn.XLOOKUP(1,(VALUE(L3883)>=VALUE(block!$C$3:'block'!$C$500))*(VALUE(block!L3883)<VALUE(block!$C$3:'block'!$C$500)+VALUE(block!$D$3:'block'!$D$500)),block!$A$3:'block'!$A$500,"无匹配",0,1) -> 55 | J21: R | K21: 2 | L21: 1 | N21: 4 | P21: 4-7-8-40 | Q21: 9-2-1 | S21: I_b_A
A22: 21 | B22: =_xlfn.XLOOKUP(1,(VALUE(D22)>=VALUE(block!$C$3:$C$500))*(VALUE(D22)<VALUE(block!$C$3:$C$500)+VALUE(block!$D$3:$D$500)),block!$A$3:$A$500,"无匹配",0,1) -> 1 | C22: =B22 & "-" & COUNTIF($B$2:B22, B22) -> 1-20 | D22: 8230 | E22: Phase B Active Power | F22: P_b_kW | G22: kW | H22: float32 | I22: =_xlfn.XLOOKUP(1,(VALUE(L3884)>=VALUE(block!$C$3:'block'!$C$500))*(VALUE(block!L3884)<VALUE(block!$C$3:'block'!$C$500)+VALUE(block!$D$3:'block'!$D$500)),block!$A$3:'block'!$A$500,"无匹配",0,1) -> 55 | J22: R | K22: 2 | L22: 1 | N22: 4 | P22: 4-7-8-40 | Q22: 9-2-1 | S22: P_b_kW
A23: 22 | B23: =_xlfn.XLOOKUP(1,(VALUE(D23)>=VALUE(block!$C$3:$C$500))*(VALUE(D23)<VALUE(block!$C$3:$C$500)+VALUE(block!$D$3:$D$500)),block!$A$3:$A$500,"无匹配",0,1) -> 1 | C23: =B23 & "-" & COUNTIF($B$2:B23, B23) -> 1-21 | D23: 8232 | E23: Phase B Reactive Power | F23: Q_b_kvar | G23: kvar | H23: float32 | I23: =_xlfn.XLOOKUP(1,(VALUE(L3885)>=VALUE(block!$C$3:'block'!$C$500))*(VALUE(block!L3885)<VALUE(block!$C$3:'block'!$C$500)+VALUE(block!$D$3:'block'!$D$500)),block!$A$3:'block'!$A$500,"无匹配",0,1) -> 55 | J23: R | K23: 2 | L23: 1 | N23: 4 | P23: 4-7-8-40 | Q23: 9-2-1 | S23: Q_b_kvar
A24: 23 | B24: =_xlfn.XLOOKUP(1,(VALUE(D24)>=VALUE(block!$C$3:$C$500))*(VALUE(D24)<VALUE(block!$C$3:$C$500)+VALUE(block!$D$3:$D$500)),block!$A$3:$A$500,"无匹配",0,1) -> 1 | C24: =B24 & "-" & COUNTIF($B$2:B24, B24) -> 1-22 | D24: 8234 | E24: Phase B Apparent Power | F24: S_b_kVA | G24: kVA | H24: float32 | I24: =_xlfn.XLOOKUP(1,(VALUE(L3886)>=VALUE(block!$C$3:'block'!$C$500))*(VALUE(block!L3886)<VALUE(block!$C$3:'block'!$C$500)+VALUE(block!$D$3:'block'!$D$500)),block!$A$3:'block'!$A$500,"无匹配",0,1) -> 55 | J24: R | K24: 2 | L24: 1 | N24: 4 | P24: 4-7-8-40 | Q24: 9-2-1 | S24: S_b_kVA
A25: 24 | B25: =_xlfn.XLOOKUP(1,(VALUE(D25)>=VALUE(block!$C$3:$C$500))*(VALUE(D25)<VALUE(block!$C$3:$C$500)+VALUE(block!$D$3:$D$500)),block!$A$3:$A$500,"无匹配",0,1) -> 1 | C25: =B25 & "-" & COUNTIF($B$2:B25, B25) -> 1-23 | D25: 8236 | E25: Phase B Load Nature | F25: LC_b | H25: uint32 | I25: =_xlfn.XLOOKUP(1,(VALUE(L3887)>=VALUE(block!$C$3:'block'!$C$500))*(VALUE(block!L3887)<VALUE(block!$C$3:'block'!$C$500)+VALUE(block!$D$3:'block'!$D$500)),block!$A$3:'block'!$A$500,"无匹配",0,1) -> 55 | J25: R | K25: 2 | L25: 1 | Q25: 9
A26: 25 | B26: =_xlfn.XLOOKUP(1,(VALUE(D26)>=VALUE(block!$C$3:$C$500))*(VALUE(D26)<VALUE(block!$C$3:$C$500)+VALUE(block!$D$3:$D$500)),block!$A$3:$A$500,"无匹配",0,1) -> 1 | C26: =B26 & "-" & COUNTIF($B$2:B26, B26) -> 1-24 | D26: 8238 | E26: Phase B Power Factor | F26: PF_b | G26: % | H26: float32 | I26: =_xlfn.XLOOKUP(1,(VALUE(L3888)>=VALUE(block!$C$3:'block'!$C$500))*(VALUE(block!L3888)<VALUE(block!$C$3:'block'!$C$500)+VALUE(block!$D$3:'block'!$D$500)),block!$A$3:'block'!$A$500,"无匹配",0,1) -> 55 | J26: R | K26: 2 | L26: 1 | N26: 4 | P26: 4-7-8-40 | Q26: 9 | S26: PF_b
A27: 26 | B27: =_xlfn.XLOOKUP(1,(VALUE(D27)>=VALUE(block!$C$3:$C$500))*(VALUE(D27)<VALUE(block!$C$3:$C$500)+VALUE(block!$D$3:$D$500)),block!$A$3:$A$500,"无匹配",0,1) -> 1 | C27: =B27 & "-" & COUNTIF($B$2:B27, B27) -> 1-25 | D27: 8240 | E27: Phase C Current | F27: I_c_A | G27: A | H27: float32 | I27: =_xlfn.XLOOKUP(1,(VALUE(L3889)>=VALUE(block!$C$3:'block'!$C$500))*(VALUE(block!L3889)<VALUE(block!$C$3:'block'!$C$500)+VALUE(block!$D$3:'block'!$D$500)),block!$A$3:'block'!$A$500,"无匹配",0,1) -> 55 | J27: R | K27: 2 | L27: 1 | N27: 4 | P27: 4-7-8-40 | Q27: 9-2-1 | S27: I_c_A
A28: 27 | B28: =_xlfn.XLOOKUP(1,(VALUE(D28)>=VALUE(block!$C$3:$C$500))*(VALUE(D28)<VALUE(block!$C$3:$C$500)+VALUE(block!$D$3:$D$500)),block!$A$3:$A$500,"无匹配",0,1) -> 1 | C28: =B28 & "-" & COUNTIF($B$2:B28, B28) -> 1-26 | D28: 8242 | E28: Phase C Active Power | F28: P_c_kW | G28: kW | H28: float32 | I28: =_xlfn.XLOOKUP(1,(VALUE(L3890)>=VALUE(block!$C$3:'block'!$C$500))*(VALUE(block!L3890)<VALUE(block!$C$3:'block'!$C$500)+VALUE(block!$D$3:'block'!$D$500)),block!$A$3:'block'!$A$500,"无匹配",0,1) -> 55 | J28: R | K28: 2 | L28: 1 | N28: 4 | P28: 4-7-8-40 | Q28: 9-2-1 | S28: P_c_kW
A29: 28 | B29: =_xlfn.XLOOKUP(1,(VALUE(D29)>=VALUE(block!$C$3:$C$500))*(VALUE(D29)<VALUE(block!$C$3:$C$500)+VALUE(block!$D$3:$D$500)),block!$A$3:$A$500,"无匹配",0,1) -> 1 | C29: =B29 & "-" & COUNTIF($B$2:B29, B29) -> 1-27 | D29: 8244 | E29: Phase C Reactive Power | F29: Q_c_kvar | G29: kvar | H29: float32 | I29: =_xlfn.XLOOKUP(1,(VALUE(L3891)>=VALUE(block!$C$3:'block'!$C$500))*(VALUE(block!L3891)<VALUE(block!$C$3:'block'!$C$500)+VALUE(block!$D$3:'block'!$D$500)),block!$A$3:'block'!$A$500,"无匹配",0,1) -> 55 | J29: R | K29: 2 | L29: 1 | N29: 4 | P29: 4-7-8-40 | Q29: 9-2-1 | S29: Q_c_kvar
A30: 29 | B30: =_xlfn.XLOOKUP(1,(VALUE(D30)>=VALUE(block!$C$3:$C$500))*(VALUE(D30)<VALUE(block!$C$3:$C$500)+VALUE(block!$D$3:$D$500)),block!$A$3:$A$500,"无匹配",0,1) -> 1 | C30: =B30 & "-" & COUNTIF($B$2:B30, B30) -> 1-28 | D30: 8246 | E30: Phase C Apparent Power | F30: S_c_kVA | G30: kVA | H30: float32 | I30: =_xlfn.XLOOKUP(1,(VALUE(L3892)>=VALUE(block!$C$3:'block'!$C$500))*(VALUE(block!L3892)<VALUE(block!$C$3:'block'!$C$500)+VALUE(block!$D$3:'block'!$D$500)),block!$A$3:'block'!$A$500,"无匹配",0,1) -> 55 | J30: R | K30: 2 | L30: 1 | N30: 4 | P30: 4-7-8-40 | Q30: 9-2-1 | S30: S_c_kVA
A31: 30 | B31: =_xlfn.XLOOKUP(1,(VALUE(D31)>=VALUE(block!$C$3:$C$500))*(VALUE(D31)<VALUE(block!$C$3:$C$500)+VALUE(block!$D$3:$D$500)),block!$A$3:$A$500,"无匹配",0,1) -> 1 | C31: =B31 & "-" & COUNTIF($B$2:B31, B31) -> 1-29 | D31: 8248 | E31: Phase C Load Nature | F31: LC_c | H31: uint32 | I31: =_xlfn.XLOOKUP(1,(VALUE(L3893)>=VALUE(block!$C$3:'block'!$C$500))*(VALUE(block!L3893)<VALUE(block!$C$3:'block'!$C$500)+VALUE(block!$D$3:'block'!$D$500)),block!$A$3:'block'!$A$500,"无匹配",0,1) -> 55 | J31: R | K31: 2 | L31: 1 | Q31: 9
A32: 31 | B32: =_xlfn.XLOOKUP(1,(VALUE(D32)>=VALUE(block!$C$3:$C$500))*(VALUE(D32)<VALUE(block!$C$3:$C$500)+VALUE(block!$D$3:$D$500)),block!$A$3:$A$500,"无匹配",0,1) -> 1 | C32: =B32 & "-" & COUNTIF($B$2:B32, B32) -> 1-30 | D32: 8250 | E32: Phase C Power Factor | F32: PF_c | G32: % | H32: float32 | I32: =_xlfn.XLOOKUP(1,(VALUE(L3894)>=VALUE(block!$C$3:'block'!$C$500))*(VALUE(block!L3894)<VALUE(block!$C$3:'block'!$C$500)+VALUE(block!$D$3:'block'!$D$500)),block!$A$3:'block'!$A$500,"无匹配",0,1) -> 55 | J32: R | K32: 2 | L32: 1 | N32: 4 | P32: 4-7-8-40 | Q32: 9 | S32: PF_c
A33: 32 | B33: =_xlfn.XLOOKUP(1,(VALUE(D33)>=VALUE(block!$C$3:$C$500))*(VALUE(D33)<VALUE(block!$C$3:$C$500)+VALUE(block!$D$3:$D$500)),block!$A$3:$A$500,"无匹配",0,1) -> 1 | C33: =B33 & "-" & COUNTIF($B$2:B33, B33) -> 1-31 | D33: 8252 | E33: System Average Current | F33: I_avg_A | G33: A | H33: float32 | I33: =_xlfn.XLOOKUP(1,(VALUE(L3895)>=VALUE(block!$C$3:'block'!$C$500))*(VALUE(block!L3895)<VALUE(block!$C$3:'block'!$C$500)+VALUE(block!$D$3:'block'!$D$500)),block!$A$3:'block'!$A$500,"无匹配",0,1) -> 55 | J33: R | K33: 2 | L33: 1 | N33: 4 | P33: 4-7-8-40 | Q33: 9-2-1 | S33: I_avg_A
A34: 33 | B34: =_xlfn.XLOOKUP(1,(VALUE(D34)>=VALUE(block!$C$3:$C$500))*(VALUE(D34)<VALUE(block!$C$3:$C$500)+VALUE(block!$D$3:$D$500)),block!$A$3:$A$500,"无匹配",0,1) -> 1 | C34: =B34 & "-" & COUNTIF($B$2:B34, B34) -> 1-32 | D34: 8254 | E34: System Active Power | F34: P_kW | G34: kW | H34: float32 | I34: =_xlfn.XLOOKUP(1,(VALUE(L3896)>=VALUE(block!$C$3:'block'!$C$500))*(VALUE(block!L3896)<VALUE(block!$C$3:'block'!$C$500)+VALUE(block!$D$3:'block'!$D$500)),block!$A$3:'block'!$A$500,"无匹配",0,1) -> 55 | J34: R | K34: 2 | L34: 1 | N34: 4 | P34: 4-7-8-40 | Q34: 9-2-1 | S34: P_kW
A35: 34 | B35: =_xlfn.XLOOKUP(1,(VALUE(D35)>=VALUE(block!$C$3:$C$500))*(VALUE(D35)<VALUE(block!$C$3:$C$500)+VALUE(block!$D$3:$D$500)),block!$A$3:$A$500,"无匹配",0,1) -> 1 | C35: =B35 & "-" & COUNTIF($B$2:B35, B35) -> 1-33 | D35: 8256 | E35: System Reactive Power | F35: Q_kvar | G35: kvar | H35: float32 | I35: =_xlfn.XLOOKUP(1,(VALUE(L3897)>=VALUE(block!$C$3:'block'!$C$500))*(VALUE(block!L3897)<VALUE(block!$C$3:'block'!$C$500)+VALUE(block!$D$3:'block'!$D$500)),block!$A$3:'block'!$A$500,"无匹配",0,1) -> 55 | J35: R | K35: 2 | L35: 1 | N35: 4 | P35: 4-7-8-40 | Q35: 9-2-1 | S35: Q_kvar
A36: 35 | B36: =_xlfn.XLOOKUP(1,(VALUE(D36)>=VALUE(block!$C$3:$C$500))*(VALUE(D36)<VALUE(block!$C$3:$C$500)+VALUE(block!$D$3:$D$500)),block!$A$3:$A$500,"无匹配",0,1) -> 1 | C36: =B36 & "-" & COUNTIF($B$2:B36, B36) -> 1-34 | D36: 8258 | E36: System Apparent Power | F36: S_kVA | G36: kVA | H36: float32 | I36: =_xlfn.XLOOKUP(1,(VALUE(L3898)>=VALUE(block!$C$3:'block'!$C$500))*(VALUE(block!L3898)<VALUE(block!$C$3:'block'!$C$500)+VALUE(block!$D$3:'block'!$D$500)),block!$A$3:'block'!$A$500,"无匹配",0,1) -> 55 | J36: R | K36: 2 | L36: 1 | N36: 4 | P36: 4-7-8-40 | Q36: 9-2-1 | S36: S_kVA
A37: 36 | B37: =_xlfn.XLOOKUP(1,(VALUE(D37)>=VALUE(block!$C$3:$C$500))*(VALUE(D37)<VALUE(block!$C$3:$C$500)+VALUE(block!$D$3:$D$500)),block!$A$3:$A$500,"无匹配",0,1) -> 1 | C37: =B37 & "-" & COUNTIF($B$2:B37, B37) -> 1-35 | D37: 8260 | E37: System Load Nature | F37: LC | H37: uint32 | I37: =_xlfn.XLOOKUP(1,(VALUE(L3899)>=VALUE(block!$C$3:'block'!$C$500))*(VALUE(block!L3899)<VALUE(block!$C$3:'block'!$C$500)+VALUE(block!$D$3:'block'!$D$500)),block!$A$3:'block'!$A$500,"无匹配",0,1) -> 55 | J37: R | K37: 2 | L37: 1 | Q37: 9
A38: 37 | B38: =_xlfn.XLOOKUP(1,(VALUE(D38)>=VALUE(block!$C$3:$C$500))*(VALUE(D38)<VALUE(block!$C$3:$C$500)+VALUE(block!$D$3:$D$500)),block!$A$3:$A$500,"无匹配",0,1) -> 1 | C38: =B38 & "-" & COUNTIF($B$2:B38, B38) -> 1-36 | D38: 8262 | E38: System Power Factor | F38: PF | G38: % | H38: float32 | I38: =_xlfn.XLOOKUP(1,(VALUE(L3900)>=VALUE(block!$C$3:'block'!$C$500))*(VALUE(block!L3900)<VALUE(block!$C$3:'block'!$C$500)+VALUE(block!$D$3:'block'!$D$500)),block!$A$3:'block'!$A$500,"无匹配",0,1) -> 55 | J38: R | K38: 2 | L38: 1 | N38: 4 | P38: 4-7-8-40 | Q38: 9 | S38: PF
A39: 38 | B39: =_xlfn.XLOOKUP(1,(VALUE(D39)>=VALUE(block!$C$3:$C$500))*(VALUE(D39)<VALUE(block!$C$3:$C$500)+VALUE(block!$D$3:$D$500)),block!$A$3:$A$500,"无匹配",0,1) -> 2 | C39: =B39 & "-" & COUNTIF($B$2:B39, B39) -> 2-1 | D39: 8264 | E39: Input Channel 1 Current | F39: I_001_A | G39: A | H39: float32 | I39: =_xlfn.XLOOKUP(1,(VALUE(L3901)>=VALUE(block!$C$3:'block'!$C$500))*(VALUE(block!L3901)<VALUE(block!$C$3:'block'!$C$500)+VALUE(block!$D$3:'block'!$D$500)),block!$A$3:'block'!$A$500,"无匹配",0,1) -> 55 | J39: R | K39: 2 | L39: 1 | N39: 4 | P39: 4-7-8 | Q39: 10-2-1-35 | S39: I_001_A
A40: 39 | B40: =_xlfn.XLOOKUP(1,(VALUE(D40)>=VALUE(block!$C$3:$C$500))*(VALUE(D40)<VALUE(block!$C$3:$C$500)+VALUE(block!$D$3:$D$500)),block!$A$3:$A$500,"无匹配",0,1) -> 2 | C40: =B40 & "-" & COUNTIF($B$2:B40, B40) -> 2-2 | D40: 8266 | E40: Input Channel 1 Active Power | F40: P_001_kW | G40: kW | H40: float32 | I40: =_xlfn.XLOOKUP(1,(VALUE(L3902)>=VALUE(block!$C$3:'block'!$C$500))*(VALUE(block!L3902)<VALUE(block!$C$3:'block'!$C$500)+VALUE(block!$D$3:'block'!$D$500)),block!$A$3:'block'!$A$500,"无匹配",0,1) -> 55 | J40: R | K40: 2 | L40: 1 | N40: 4 | P40: 4-7-8 | Q40: 10-2-1-35 | S40: P_001_kW
A41: 40 | B41: =_xlfn.XLOOKUP(1,(VALUE(D41)>=VALUE(block!$C$3:$C$500))*(VALUE(D41)<VALUE(block!$C$3:$C$500)+VALUE(block!$D$3:$D$500)),block!$A$3:$A$500,"无匹配",0,1) -> 2 | C41: =B41 & "-" & COUNTIF($B$2:B41, B41) -> 2-3 | D41: 8268 | E41: Input Channel 1 Reactive Power | F41: Q_001_kvar | G41: kvar | H41: float32 | I41: =_xlfn.XLOOKUP(1,(VALUE(L3903)>=VALUE(block!$C$3:'block'!$C$500))*(VALUE(block!L3903)<VALUE(block!$C$3:'block'!$C$500)+VALUE(block!$D$3:'block'!$D$500)),block!$A$3:'block'!$A$500,"无匹配",0,1) -> 55 | J41: R | K41: 2 | L41: 1 | N41: 4 | P41: 4-7-8 | Q41: 10-2-1 | S41: Q_001_kvar
A42: 41 | B42: =_xlfn.XLOOKUP(1,(VALUE(D42)>=VALUE(block!$C$3:$C$500))*(VALUE(D42)<VALUE(block!$C$3:$C$500)+VALUE(block!$D$3:$D$500)),block!$A$3:$A$500,"无匹配",0,1) -> 2 | C42: =B42 & "-" & COUNTIF($B$2:B42, B42) -> 2-4 | D42: 8270 | E42: Input Channel 1 Apparent Power | F42: S_001_kVA | G42: kVA | H42: float32 | I42: =_xlfn.XLOOKUP(1,(VALUE(L3904)>=VALUE(block!$C$3:'block'!$C$500))*(VALUE(block!L3904)<VALUE(block!$C$3:'block'!$C$500)+VALUE(block!$D$3:'block'!$D$500)),block!$A$3:'block'!$A$500,"无匹配",0,1) -> 55 | J42: R | K42: 2 | L42: 1 | N42: 4 | P42: 4-7-8 | Q42: 10-2-1 | S42: S_001_kVA
...

Sheet analysisUnits
A1: analysisUnitId | B1: analysisUnitTypeName

Sheet analysisParams
A1: threePhaseMeterAnalysis | B1: threePhaseMeterAnalysis | C1: threePhaseMeterAnalysis | D1: threePhaseMeterAnalysis | E1: threePhaseMeterAnalysis
A2: three_phase_realtime | B2: three_phase_energy_demand | C2: three_phase_thd | D2: three_phase_harmonics | E2: three_phase_sequence
A3: VLN_a_V | B3: EP_IMP_a_kWh | C3: THD_V_a_% | D3: HAR2_V_a_% | E3: SEQ_POS_REAL_I
A4: ANG_VLN_a | B4: EQ_IMP_a_kvarh | C4: OTHD_V_a_% | D4: HAR3_V_a_% | E4: SEQ_NEG_REAL_I
A5: VLL_ab_V | B5: EP_EXP_a_kWh | C5: ETHD_V_a_% | D5: HAR4_V_a_% | E5: SEQ_ZERO_REAL_I
A6: ANG_VLL_ab | B6: EQ_EXP_a_kvarh | C6: CF_V_a_% | D6: HAR5_V_a_% | E6: SEQ_POS_IMG_I
A7: I_a_A | B7: EP_NET_a_kWh | C7: THD_I_a_% | D7: HAR6_V_a_% | E7: SEQ_NEG_IMG_I
A8: ANG_I_a | B8: EQ_NET_a_kvarh | C8: OTHD_I_a_% | D8: HAR7_V_a_% | E8: SEQ_ZERO_IMG_I
A9: P_a_kW | B9: EP_TOTAL_a_kWh | C9: ETHD_I_a_% | D9: HAR8_V_a_% | E9: SEQ_POS_REAL_V
A10: Q_a_kvar | B10: EQ_TOTAL_a_kvarh | C10: TDD_I_a_% | D10: HAR9_V_a_% | E10: SEQ_NEG_REAL_V
A11: S_a_kVA | B11: ES_a_kVAh | C11: CF_I_a_% | D11: HAR10_V_a_% | E11: SEQ_ZERO_REAL_V
A12: LC_a | B12: EP_IMP_b_kWh | C12: KF_I_a_% | D12: HAR11_V_a_% | E12: SEQ_POS_IMG_V
... A18: VLL_bc_V | B18: EP_TOTAL_b_kWh | C18: OTHD_I_b_% | D18: HAR17_V_a_% | E18: SEQ_ZERO_RATIO_I_%
A19: ANG_VLL_bb | B19: EQ_TOTAL_b_kvarh | C19: ETHD_I_b_% | D19: HAR18_V_a_%
A20: I_b_A | B20: ES_b_kVAh | C20: TDD_I_b_% | D20: HAR19_V_a_%
A21: ANG_I_b | B21: EP_IMP_c_kWh | C21: CF_I_b_% | D21: HAR20_V_a_%
A22: P_b_kW | B22: EQ_IMP_c_kvarh | C22: KF_I_b_% | D22: HAR21_V_a_%
A23: Q_b_kvar | B23: EP_EXP_c_kWh | C23: THD_V_c_% | D23: HAR22_V_a_%
A24: S_b_kVA | B24: EQ_EXP_c_kvarh | C24: OTHD_V_c_% | D24: HAR23_V_a_%
A25: LC_b | B25: EP_NET_c_kWh | C25: ETHD_V_c_% | D25: HAR24_V_a_%
A26: PF_b | B26: EQ_NET_c_kvarh | C26: CF_V_c_% | D26: HAR25_V_a_%
A27: LEAD_PF_b | B27: EP_TOTAL_c_kWh | C27: THD_I_c_% | D27: HAR26_V_a_%
A28: LAG_PF_b | B28: EQ_TOTAL_c_kvarh | C28: OTHD_I_c_% | D28: HAR27_V_a_%
A29: VLN_c_V | B29: ES_c_kVAh | C29: ETHD_I_c_% | D29: HAR28_V_a_%
A30: ANG_VLN_c | B30: EP_IMP_kWh | C30: TDD_I_c_% | D30: HAR29_V_a_%
... A42: VLN_avg_V | B42: DMD_P_b_kW | C42: KF_I_avg_% | D42: HAR41_V_a_%
A43: VLL_avg_V | B43: DMD_Q_b_kvar | D43: HAR42_V_a_%
A44: I_avg_A | B44: DMD_S_b_kVA | D44: HAR43_V_a_%
A45: LC_avg | B45: DMD_P_c_kW | D45: HAR44_V_a_%
A46: I_n_A | B46: DMD_Q_c_kvar | D46: HAR45_V_a_%
A47: P_kW | B47: DMD_S_c_kVA | D47: HAR46_V_a_%
A48: Q_kvar | B48: DMD_P_kW | D48: HAR47_V_a_%
A49: S_kVA | B49: DMD_Q_kvar | D49: HAR48_V_a_%
A50: PF | B50: DMD_S_kVA | D50: HAR49_V_a_%
A51: LEAD_PF | D51: HAR50_V_a_%
A52: LAG_PF | D52: HAR51_V_a_%
A53: FREQ_Hz | D53: HAR52_V_a_%
D54: HAR53_V_a_%
D55: HAR54_V_a_%
D56: HAR55_V_a_%
...

Sheet analysisNames
A1: analysisId | B1: analysisUnitId | C1: analysisName
A2: 1 | B2: 1 | C2: three_phase_realtime
A3: 2 | B3: 1 | C3: three_phase_energy_demand
A4: 3 | B4: 1 | C4: three_phase_thd
A5: 4 | B5: 1 | C5: three_phase_harmonics
A6: 5 | B6: 1 | C6: three_phase_sequence

Sheet applications
A1: appId | B1: appName | C1: isTimer | D1: groupId | E1: interval | F1: isEnable | G1: jsonConfig | H1: appType | I1: 说明
A2: 1 | B2: bacnet | C2: true | D2: 4 | E2: 5000 | F2: true | G2: "" | H2: 2 | I2: 不可选,使用datalog_range,目前有:AcuCloud,BACnet/IP,SNMP
A3: 2 | B3: alarm | C3: true | D3: 0 | E3: 0 | F3: true | G3: "" | H3: 2 | I3: 2.2.1章节使用
A4: 3 | B4: alarm_ao_range | C4: true | D4: 8 | E4: 1000 | F4: true | G4: "" | H4: 2 | I4: alarm_ao功能通过此app获取数据，然后根据自己的列表匹配后通过调用doAppParamsConfig,app传aio设备serialnumber，appname传ctr_ao
A5: 4 | B5: north | C5: true | D5: 4 | E5: 60000 | F5: true | G5: "" | H5: 2 | I5: 不可选,使用datalog_range,目前有:AcuCloud,BACnet/IP,SNMP
A6: 5 | B6: realtime_system | C6: true | D6: 9 | E6: 200 | F6: true | G6: "" | H6: 1
A7: 6 | B7: realtime_channel | C7: true | D7: 10 | E7: 200 | F7: true | G7: "" | H7: 1
A8: 7 | B8: energy_system | C8: true | D8: 11 | E8: 3000 | F8: true | G8: "" | H8: 1
A9: 8 | B9: energy_channel | C9: true | D9: 12 | E9: 3000 | F9: true | G9: "" | H9: 1
A10: 9 | B10: thd_system | C10: true | D10: 13 | E10: 3000 | F10: true | G10: "" | H10: 1
A11: 10 | B11: thd_channel | C11: true | D11: 14 | E11: 3000 | F11: true | G11: "" | H11: 1
A12: 11 | B12: demand_system | C12: true | D12: 15 | E12: 60000 | F12: true | G12: "" | H12: 1
A13: 12 | B13: demand_channel | C13: true | D13: 16 | E13: 60000 | F13: true | G13: "" | H13: 1
A14: 13 | B14: PowerQuality | C14: true | D14: 17 | E14: 5000 | F14: true | G14: "" | H14: 1
A15: 14 | B15: deviceInfo | C15: true | D15: 18 | E15: 60000 | F15: true | G15: "" | H15: 1
A16: 15 | B16: SOElog | C16: true | D16: 19 | E16: 5000 | F16: true | G16: "" | H16: 1
A17: 16 | B17: max_demand_system | C17: true | D17: 20 | E17: 5000 | F17: true | G17: "" | H17: 1
... A27: 26 | B27: GeneralSetting | C27: true | D27: 30 | E27: 3000 | F27: true | G27: "" | H27: 1
A28: 27 | B28: trendlog | C28: true | D28: 1 | E28: 3000 | F28: true | G28: "" | H28: 1 | I28: 可选datalog_range参数范围，将参数选择添加到group：mqtt
A29: 28 | B29: trendlogreal | C29: true | D29: 2 | E29: 3000 | F29: true | G29: "" | H29: 1 | I29: 可选datalog_range参数范围，将参数选择添加到group：trendlog_real
A30: 29 | B30: trendlogenergy | C30: true | D30: 3 | E30: 3000 | F30: true | G30: "" | H30: 1 | I30: 可选datalog_range参数范围，将参数选择添加到group：trendlogenergy
A31: 30 | B31: datalog1 | C31: true | D31: 32 | E31: 5000 | F31: true | G31: "" | H31: 1 | I31: 可选datalog_range参数范围，将参数选择添加到group：postparam
A32: 31 | B32: datalog2 | C32: true | D32: 32 | E32: 5000 | F32: true | G32: "" | H32: 1
A33: 32 | B33: datalog3 | C33: true | D33: 32 | E33: 5000 | F33: true | G33: "" | H33: 1
A34: 33 | B34: deviceInspectionInfo | C34: true | D34: 35 | E34: 5000 | F34: true | G34: "" | H34: 1
A35: 34 | B35: squence_system | C35: true | D35: 36 | E35: 5000 | F35: true | G35: "" | H35: 1
A36: 35 | B36: squence_channel | C36: true | D36: 37 | E36: 5000 | F36: true | G36: "" | H36: 1
A37: 36 | B37: harmonic_system | C37: true | D37: 38 | E37: 5000 | F37: true | G37: "" | H37: 1
A38: 37 | B38: harmonic_channel | C38: true | D38: 39 | E38: 5000 | F38: true | G38: "" | H38: 1
A39: 38 | B39: snmp | C39: true | D39: 4 | E39: 5000 | F39: true | G39: "" | H39: 1
A40: 39 | B40: io | C40: true | D40: 26 | E40: 5000 | F40: true | G40: "" | H40: 1
A41: 40 | B41: management | C41: false | D41: 45 | E41: 5000 | F41: false | G41: "" | H41: 2 | I41: 加到此处是为调用doAppParamsConfig设置寄存器使用，但此app下参数都没有读属性，所以不能调用getParamByApplicationInfo读值， 开机时tApp isTimerEnable，isEnable 同时为1时会加到采集队列 之后按需采集appType=2的app会释放

Sheet groups
A1: groupId | B1: groupType | C1: paramCount
A2: 1 | B2: trend | D2: select from datalog_range, | E2: 此分组参数是在web界面选择增减的 9月5日文档说选择范围是datalog_range 9月6日文档没提
A3: 2 | B3: trendreal | E3: 9-16文档第59页说可以选，subo10月13日输出了范围，固定
A4: 3 | B4: trendenergy
A5: 4 | B5: north_range | D5: range | E5: AcuCloud,BACnet/IP,SNMP不可选择,MQTT可选择参数，范围都是这个。比datalog_range还多energy参数
A6: 5 | B6: diCounterRange | E6: 比alarm_ao_range多energy(9月5日)DI status, DI counter, RO Status, DO status; AcuCloud,BACnet/IP,SNMP不可选择MQTT可选择参数，范围都是这个。比datalog_range还多energy参数
A7: 6 | B7: alarm_ao_maxmin_range | E7: Demand没有min所以min默认0
A8: 7 | B8: alarm_range | E8: 比alarm_ao_range多DI status
A9: 8 | B9: alarm_ao_range | E9: Basic Parameter (不含LN),Demand, Power Quality (不含individual harmonics)
A10: 9 | B10: realtime_system | D10: readings
A11: 10 | B11: realtime_channel
A12: 11 | B12: energy_system
A13: 12 | B13: energy_channel
A14: 13 | B14: thd_system
A15: 14 | B15: thd_channel
A16: 15 | B16: demand_system
A17: 16 | B17: demand_channel
A18: 17 | B18: PowerQuality
A19: 18 | B19: deviceInfo
A20: 19 | B20: SOElog
A21: 20 | B21: max_demand_system
A22: 21 | B22: max_demand_channel
... A24: 23 | B24: maxmin_system
A25: 24 | B25: maxmin_channel | E25: 20-23-36-38
A26: 25 | B26: roStatusRange | D26: range | E26: 暂时没用，后边增加时会替换
A27: 26 | B27: io | D27: readings
A28: 27 | B28: deviceSetting_ClassS | D28: conf
A29: 28 | B29: deviceSetting_UserAndCt
A30: 29 | B30: deviceSetting_Batch_UserAndCt
A31: 30 | B31: deviceSetting_General | E31: 2.4Management
A32: 31 | B32: mqtt | D32: select from basicParamRange demandRange powerQualityRange energyRange
A33: 32 | B33: datalog
A34: 33 | B34: SNMP
A35: 34 | B35: doStatusRange | D35: range
A36: 35 | B36: deviceInspectionInfo | D36: readings
A37: 36 | B37: squence_system | D37: readings
A38: 37 | B38: squence_channel | D38: readings
A39: 38 | B39: harmonic_system | D39: readings
A40: 39 | B40: harmonic_channel | D40: readings
A41: 40 | B41: basicParamRange | D41: range
...

Sheet deviceTemplateInfo
A1: label | B1: description | C1: version | D1: firmwareVersion | E1: deviceType | F1: protocol | G1: pqEvent | H1: pqEventProto | I1: waveform | J1: waveformProto
A2: AcuRev-4110 | B2: AcuRev-4110 three-phase AC meter | C2: v1.00p01 | D2: v1.01p22 | E2: threePhaseACMeter | F2: { "type": "Modbus", "transports": ["modbus-tcp", "modbus-rtu"] } | G2: true | H2: AcuRev4110-Class-S-Event | I2: true | J2: AcuRev4110-Class-S-Waveform
