Workbook

Sheet 进展统计
A1: AcuRev-100 Vx.xx版本软件测试报告
A2: 【测试日期】 | E2: 【版本目标】
A3: 【软件版本】 | E3: 【硬件版本】
A4: 整体测试进展
A5: 一句话进展:
A6: 风险&阻塞
A7: 序号 | B7: 问题描述 | C7: 责任人 | D7: 期望解决日期
A9: 发现问题列表
A10: 问题单号 | B10: 问题简要描述 | E10: 严重程度 | F10: 类别
A15: 测试进展
A16: 型号:AcuRev-101
A17: 序号 | B17: 测试模块 | C17: 用例数 | D17: Passed | E17: Failed | F17: Blocked | G17: Unavailable | H17: 执行率
A18: 1 | B18: 交流频率 | C18: =COUNTIF('AcuRev-100测试用例'!$C:$C,"*_001_*") -> 4 | D18: =COUNTIFS('AcuRev-100测试用例'!$C:$C,"*_001_*",'AcuRev-100测试用例'!$K:$K,"Passed") -> 0 | E18: =COUNTIFS('AcuRev-100测试用例'!$C:$C,"*_001_*",'AcuRev-100测试用例'!$K:$K,"Failed") -> 0 | F18: =COUNTIFS('AcuRev-100测试用例'!$C:$C,"*_001_*",'AcuRev-100测试用例'!$K:$K,"Blocked") -> 0 | G18: =COUNTIFS('AcuRev-100测试用例'!$C:$C,"*_001_*",'AcuRev-100测试用例'!$K:$K,"Unavailable") -> 0 | H18: =(D18+E18+F18+G18)/C18 -> 0
A19: 2 | B19: 相电压 | C19: =COUNTIF('AcuRev-100测试用例'!$C:$C,"*_002_*") -> 7 | D19: =COUNTIFS('AcuRev-100测试用例'!$C:$C,"*_002_*",'AcuRev-100测试用例'!$K:$K,"Passed") -> 0 | E19: =COUNTIFS('AcuRev-100测试用例'!$C:$C,"*_002_*",'AcuRev-100测试用例'!$K:$K,"Failed") -> 0 | F19: =COUNTIFS('AcuRev-100测试用例'!$C:$C,"*_002_*",'AcuRev-100测试用例'!$K:$K,"Blocked") -> 0 | G19: =COUNTIFS('AcuRev-100测试用例'!$C:$C,"*_002_*",'AcuRev-100测试用例'!$K:$K,"Unavailable") -> 0 | H19: =(D19+E19+F19+G19)/C19 -> 0
A20: 3 | B20: 线电压 | C20: =COUNTIF('AcuRev-100测试用例'!$C:$C,"*_003_*") -> 4 | D20: =COUNTIFS('AcuRev-100测试用例'!$C:$C,"*_003_*",'AcuRev-100测试用例'!$K:$K,"Passed") -> 0 | E20: =COUNTIFS('AcuRev-100测试用例'!$C:$C,"*_003_*",'AcuRev-100测试用例'!$K:$K,"Failed") -> 0 | F20: =COUNTIFS('AcuRev-100测试用例'!$C:$C,"*_003_*",'AcuRev-100测试用例'!$K:$K,"Blocked") -> 0 | G20: =COUNTIFS('AcuRev-100测试用例'!$C:$C,"*_003_*",'AcuRev-100测试用例'!$K:$K,"Unavailable") -> 0 | H20: =(D20+E20+F20+G20)/C20 -> 0
A21: 4 | B21: 电流测量 | C21: =COUNTIF('AcuRev-100测试用例'!$C:$C,"*_004_*") -> 22 | D21: =COUNTIFS('AcuRev-100测试用例'!$C:$C,"*_004_*",'AcuRev-100测试用例'!$K:$K,"Passed") -> 0 | E21: =COUNTIFS('AcuRev-100测试用例'!$C:$C,"*_004_*",'AcuRev-100测试用例'!$K:$K,"Failed") -> 0 | F21: =COUNTIFS('AcuRev-100测试用例'!$C:$C,"*_004_*",'AcuRev-100测试用例'!$K:$K,"Blocked") -> 0 | G21: =COUNTIFS('AcuRev-100测试用例'!$C:$C,"*_004_*",'AcuRev-100测试用例'!$K:$K,"Unavailable") -> 0 | H21: =(D21+E21+F21+G21)/C21 -> 0
A22: 5 | B22: PF·功率 | C22: =COUNTIF('AcuRev-100测试用例'!$C:$C,"*_005_*") -> 14 | D22: =COUNTIFS('AcuRev-100测试用例'!$C:$C,"*_005_*",'AcuRev-100测试用例'!$K:$K,"Passed") -> 0 | E22: =COUNTIFS('AcuRev-100测试用例'!$C:$C,"*_005_*",'AcuRev-100测试用例'!$K:$K,"Failed") -> 0 | F22: =COUNTIFS('AcuRev-100测试用例'!$C:$C,"*_005_*",'AcuRev-100测试用例'!$K:$K,"Blocked") -> 0 | G22: =COUNTIFS('AcuRev-100测试用例'!$C:$C,"*_005_*",'AcuRev-100测试用例'!$K:$K,"Unavailable") -> 0 | H22: =(D22+E22+F22+G22)/C22 -> 0
A23: 6 | B23: 相角 | C23: =COUNTIF('AcuRev-100测试用例'!$C:$C,"*_006_*") -> 4 | D23: =COUNTIFS('AcuRev-100测试用例'!$C:$C,"*_006_*",'AcuRev-100测试用例'!$K:$K,"Passed") -> 0 | E23: =COUNTIFS('AcuRev-100测试用例'!$C:$C,"*_006_*",'AcuRev-100测试用例'!$K:$K,"Failed") -> 0 | F23: =COUNTIFS('AcuRev-100测试用例'!$C:$C,"*_006_*",'AcuRev-100测试用例'!$K:$K,"Blocked") -> 0 | G23: =COUNTIFS('AcuRev-100测试用例'!$C:$C,"*_006_*",'AcuRev-100测试用例'!$K:$K,"Unavailable") -> 0 | H23: =(D23+E23+F23+G23)/C23 -> 0
A24: 7 | B24: 电能累计 | C24: =COUNTIF('AcuRev-100测试用例'!$C:$C,"*_007_*") -> 13 | D24: =COUNTIFS('AcuRev-100测试用例'!$C:$C,"*_007_*",'AcuRev-100测试用例'!$K:$K,"Passed") -> 0 | E24: =COUNTIFS('AcuRev-100测试用例'!$C:$C,"*_007_*",'AcuRev-100测试用例'!$K:$K,"Failed") -> 0 | F24: =COUNTIFS('AcuRev-100测试用例'!$C:$C,"*_007_*",'AcuRev-100测试用例'!$K:$K,"Blocked") -> 0 | G24: =COUNTIFS('AcuRev-100测试用例'!$C:$C,"*_007_*",'AcuRev-100测试用例'!$K:$K,"Unavailable") -> 0 | H24: =(D24+E24+F24+G24)/C24 -> 0
A25: 8 | B25: 脉冲 | C25: =COUNTIF('AcuRev-100测试用例'!$C:$C,"*_008_*") -> 11 | D25: =COUNTIFS('AcuRev-100测试用例'!$C:$C,"*_008_*",'AcuRev-100测试用例'!$K:$K,"Passed") -> 0 | E25: =COUNTIFS('AcuRev-100测试用例'!$C:$C,"*_008_*",'AcuRev-100测试用例'!$K:$K,"Failed") -> 0 | F25: =COUNTIFS('AcuRev-100测试用例'!$C:$C,"*_008_*",'AcuRev-100测试用例'!$K:$K,"Blocked") -> 0 | G25: =COUNTIFS('AcuRev-100测试用例'!$C:$C,"*_008_*",'AcuRev-100测试用例'!$K:$K,"Unavailable") -> 0 | H25: =(D25+E25+F25+G25)/C25 -> 0
A26: 9 | B26: 接线验证 | C26: =COUNTIF('AcuRev-100测试用例'!$C:$C,"*_009_*") -> 13 | D26: =COUNTIFS('AcuRev-100测试用例'!$C:$C,"*_009_*",'AcuRev-100测试用例'!$K:$K,"Passed") -> 0 | E26: =COUNTIFS('AcuRev-100测试用例'!$C:$C,"*_009_*",'AcuRev-100测试用例'!$K:$K,"Failed") -> 0 | F26: =COUNTIFS('AcuRev-100测试用例'!$C:$C,"*_009_*",'AcuRev-100测试用例'!$K:$K,"Blocked") -> 0 | G26: =COUNTIFS('AcuRev-100测试用例'!$C:$C,"*_009_*",'AcuRev-100测试用例'!$K:$K,"Unavailable") -> 0 | H26: =(D26+E26+F26+G26)/C26 -> 0
A27: 10 | B27: 接线检查 | C27: =COUNTIF('AcuRev-100测试用例'!$C:$C,"*_010_*") -> 67 | D27: =COUNTIFS('AcuRev-100测试用例'!$C:$C,"*_010_*",'AcuRev-100测试用例'!$K:$K,"Passed") -> 0 | E27: =COUNTIFS('AcuRev-100测试用例'!$C:$C,"*_010_*",'AcuRev-100测试用例'!$K:$K,"Failed") -> 0 | F27: =COUNTIFS('AcuRev-100测试用例'!$C:$C,"*_010_*",'AcuRev-100测试用例'!$K:$K,"Blocked") -> 0 | G27: =COUNTIFS('AcuRev-100测试用例'!$C:$C,"*_010_*",'AcuRev-100测试用例'!$K:$K,"Unavailable") -> 0 | H27: =(D27+E27+F27+G27)/C27 -> 0
A28: 11 | B28: 计时功能 | C28: =COUNTIF('AcuRev-100测试用例'!$C:$C,"*_011_*") -> 12 | D28: =COUNTIFS('AcuRev-100测试用例'!$C:$C,"*_011_*",'AcuRev-100测试用例'!$K:$K,"Passed") -> 0 | E28: =COUNTIFS('AcuRev-100测试用例'!$C:$C,"*_011_*",'AcuRev-100测试用例'!$K:$K,"Failed") -> 0 | F28: =COUNTIFS('AcuRev-100测试用例'!$C:$C,"*_011_*",'AcuRev-100测试用例'!$K:$K,"Blocked") -> 0 | G28: =COUNTIFS('AcuRev-100测试用例'!$C:$C,"*_011_*",'AcuRev-100测试用例'!$K:$K,"Unavailable") -> 0 | H28: =(D28+E28+F28+G28)/C28 -> 0
A29: 12 | B29: LCD显示及LED指示灯 | C29: =COUNTIF('AcuRev-100测试用例'!$C:$C,"*_012_*") -> 5 | D29: =COUNTIFS('AcuRev-100测试用例'!$C:$C,"*_012_*",'AcuRev-100测试用例'!$K:$K,"Passed") -> 0 | E29: =COUNTIFS('AcuRev-100测试用例'!$C:$C,"*_012_*",'AcuRev-100测试用例'!$K:$K,"Failed") -> 0 | F29: =COUNTIFS('AcuRev-100测试用例'!$C:$C,"*_012_*",'AcuRev-100测试用例'!$K:$K,"Blocked") -> 0 | G29: =COUNTIFS('AcuRev-100测试用例'!$C:$C,"*_012_*",'AcuRev-100测试用例'!$K:$K,"Unavailable") -> 0 | H29: =(D29+E29+F29+G29)/C29 -> 0
A30: 13 | B30: 铅封 | C30: =COUNTIF('AcuRev-100测试用例'!$C:$C,"*_013_*") -> 5 | D30: =COUNTIFS('AcuRev-100测试用例'!$C:$C,"*_013_*",'AcuRev-100测试用例'!$K:$K,"Passed") -> 0 | E30: =COUNTIFS('AcuRev-100测试用例'!$C:$C,"*_013_*",'AcuRev-100测试用例'!$K:$K,"Failed") -> 0 | F30: =COUNTIFS('AcuRev-100测试用例'!$C:$C,"*_013_*",'AcuRev-100测试用例'!$K:$K,"Blocked") -> 0 | G30: =COUNTIFS('AcuRev-100测试用例'!$C:$C,"*_013_*",'AcuRev-100测试用例'!$K:$K,"Unavailable") -> 0 | H30: =(D30+E30+F30+G30)/C30 -> 0
A31: 14 | B31: Firmware升级 | C31: =COUNTIF('AcuRev-100测试用例'!$C:$C,"*_014_*") -> 17 | D31: =COUNTIFS('AcuRev-100测试用例'!$C:$C,"*_014_*",'AcuRev-100测试用例'!$K:$K,"Passed") -> 0 | E31: =COUNTIFS('AcuRev-100测试用例'!$C:$C,"*_014_*",'AcuRev-100测试用例'!$K:$K,"Failed") -> 0 | F31: =COUNTIFS('AcuRev-100测试用例'!$C:$C,"*_014_*",'AcuRev-100测试用例'!$K:$K,"Blocked") -> 0 | G31: =COUNTIFS('AcuRev-100测试用例'!$C:$C,"*_014_*",'AcuRev-100测试用例'!$K:$K,"Unavailable") -> 0 | H31: =(D31+E31+F31+G31)/C31 -> 0
A32: 15 | B32: 数据重置及恢复出厂设置 | C32: =COUNTIF('AcuRev-100测试用例'!$C:$C,"*_015_*") -> 3 | D32: =COUNTIFS('AcuRev-100测试用例'!$C:$C,"*_015_*",'AcuRev-100测试用例'!$K:$K,"Passed") -> 0 | E32: =COUNTIFS('AcuRev-100测试用例'!$C:$C,"*_015_*",'AcuRev-100测试用例'!$K:$K,"Failed") -> 0 | F32: =COUNTIFS('AcuRev-100测试用例'!$C:$C,"*_015_*",'AcuRev-100测试用例'!$K:$K,"Blocked") -> 0 | G32: =COUNTIFS('AcuRev-100测试用例'!$C:$C,"*_015_*",'AcuRev-100测试用例'!$K:$K,"Unavailable") -> 0 | H32: =(D32+E32+F32+G32)/C32 -> 0
A33: 16 | B33: 通讯模块 | C33: =COUNTIF('AcuRev-100测试用例'!$C:$C,"*_016_*") -> 15 | D33: =COUNTIFS('AcuRev-100测试用例'!$C:$C,"*_016_*",'AcuRev-100测试用例'!$K:$K,"Passed") -> 0 | E33: =COUNTIFS('AcuRev-100测试用例'!$C:$C,"*_016_*",'AcuRev-100测试用例'!$K:$K,"Failed") -> 0 | F33: =COUNTIFS('AcuRev-100测试用例'!$C:$C,"*_016_*",'AcuRev-100测试用例'!$K:$K,"Blocked") -> 0 | G33: =COUNTIFS('AcuRev-100测试用例'!$C:$C,"*_016_*",'AcuRev-100测试用例'!$K:$K,"Unavailable") -> 0 | H33: =(D33+E33+F33+G33)/C33 -> 0
A34: 17 | B34: 密码 | C34: =COUNTIF('AcuRev-100测试用例'!$C:$C,"*_017_*") -> 5 | D34: =COUNTIFS('AcuRev-100测试用例'!$C:$C,"*_017_*",'AcuRev-100测试用例'!$K:$K,"Passed") -> 0 | E34: =COUNTIFS('AcuRev-100测试用例'!$C:$C,"*_017_*",'AcuRev-100测试用例'!$K:$K,"Failed") -> 0 | F34: =COUNTIFS('AcuRev-100测试用例'!$C:$C,"*_017_*",'AcuRev-100测试用例'!$K:$K,"Blocked") -> 0 | G34: =COUNTIFS('AcuRev-100测试用例'!$C:$C,"*_017_*",'AcuRev-100测试用例'!$K:$K,"Unavailable") -> 0 | H34: =(D34+E34+F34+G34)/C34 -> 0
B35: 用例总数 | C35: =SUM(C18:C34) -> 221 | D35: =SUM(D18:D34) -> 0 | E35: =SUM(E18:E34) -> 0 | F35: =SUM(F18:F34) -> 0 | G35: =SUM(G18:G34) -> 0 | H35: =(D35+E35+F35+G35)/C35 -> 0

Sheet AcuRev-100测试用例
A1: 模块 | B1: 子模块 | C1: 用例编号 | D1: 用例标题 | E1: 预置条件 | F1: 测试步骤 | G1: 预期结果 | H1: 级别 | I1: 是否可自动化 | J1: 调试结果 | K1: 测试结果 | L1: 备注
A2: 交流频率 | B2: 交流频率 | C2: Function_AC meter_001_01_case1 | D2: 交流电在45 HZ 、55HZ、65 Hz，测量精度要求0.01HZ | E2: 1、Acuview2上位机 2、RTU串口线 3、AcuRev-100电表 | F2: 1、连接AcuRev-100电表到Acuview2上，链接状态为connected 1.1、电表上设置50HZ 2、交流电源输入频率为45HZ。 3、Acuview2上检查交流电频率是否在精度范围内，范围:44.99~45.01 Hz 4、交流电源输入频率为55HZ。 5、Acuview2上检查交流电频率是否在精度范围内，范围: 54.99~55.01 Hz 6、交流电源输入频率为65HZ。 7、Acuview2上检查交流电频率是否在精度范围内，范围:64.99~65.01 Hz | G2: 步骤3：Acuview2上交流电频率显示在 44.99~45.01 Hz 范围内； 步骤5：Acuview2上交流电频率显示在 54.99~55.01 Hz 范围内； 步骤7：Acuview2上交流电频率显示在 64.99~65.01 Hz 范围内 | H2: LV2 | I2: 是 | J2: [2026-07-15 换板+固件更新复测] 转手工(用户裁决): 切频率必发角度帧→源瞬断→新固件瞬断后ADC异常测量恒0(需恢复出厂设置恢复,疑似固件缺陷已记knowledge context), 自动化无法稳定执行; 自动化文件与case_map条目已删除 [2026-07-14] 通过 [自动化2026-07-08] 非额定频点恒偏低: 45→44.90, 55→54.90, 65→64.80(要求±0.01Hz, 且分辨率仅0.1Hz); 50/60Hz正常, 疑似固件问题 [2026-07-13] 原始报告json缺失(reports目录被清理), 证据链断裂, 结论降级待重测(监督复核意见); 07-08结论仅存文字记录 | L2: 转手工：切频率必发角度帧→源瞬断，新固件下瞬断后ADC异常测量恒0（疑似固件缺陷已记knowledge），自动化无法稳定执行；2026-07-14自动化曾实测通过
A3: 交流频率 | B3: 交流频率 | C3: Function_AC meter_001_01_case2 | D3: 交流电在50HZ 、60 Hz，测量精度要求0.01HZ | E3: 1、Acuview2上位机 2、RTU串口线 3、AcuRev-100电表 | F3: 1、连接AcuRev-100电表到Acuview2上，链接状态为connected 1.1、电表上设置60HZ 2、交流电源输入频率为50HZ。 3、Acuview2上检查交流电频率是否在精度范围内，范围: 49.99~50.01 Hz 4、交流电源输入频率为60HZ。 5、Acuview2上检查交流电频率是否在精度范围内，范围:59.99~60.01 Hz | G3: 步骤3：Acuview2上交流电频率显示在 49.99~50.01 Hz 范围内； 步骤5：Acuview2上交流电频率显示在 59.99~60.01 Hz 范围内 | H3: LV0 | I3: 是 | J3: [2026-07-15 换板+固件更新复测] 转手工(用户裁决): 同case1, 切频率瞬断触发ADC异常读不到数值; 自动化文件与case_map条目已删除 [2026-07-14] 通过 [自动化2026-07-08] 50/60Hz 两点实测均在±0.01Hz内 [2026-07-13] 原始报告json缺失(reports目录被清理), 证据链断裂, 结论降级待重测(监督复核意见); 07-08结论仅存文字记录 | L3: 转手工：同case1，切频率瞬断触发ADC异常读不到数值；2026-07-08实测50/60Hz均在±0.01Hz内
A4: 交流频率 | B4: 交流频率 | C4: Function_AC meter_001_01_case3 | D4: 电表上设置60HZ, 交流电在40HZ 、70 Hz，无测量精度要求（超出45-65Hz计量范围，探索性用例，不保证可测） | E4: 1、Acuview2上位机 2、RTU串口线 3、AcuRev-100电表 | F4: 1、连接AcuRev-100电表到Acuview2上，链接状态为connected 1.1、电表上设置60HZ 2、交流电源输入频率为40HZ。 3、Acuview2上检查交流电频率可以测试到频率数据，无精度要求 4、交流电源输入频率为70HZ。 5、Acuview2上检查交流电频率可以测试到频率数据，无精度要求 | G4: 3、Acuview2上检查交流电频率可以测试到频率数据，无精度要求 5、Acuview2上检查交流电频率可以测试到频率数据，无精度要求 | H4: LV3 | I4: 是 | J4: 转手工(2026-07-13 裁决): 源CL3021 40Hz下发被拒、70Hz掉输出0V致自供电表断电, 无可自动化测点 | L4: 转手工：源CL3021不支持40Hz（下发被拒）/70Hz（输出掉0V致自供电表断电），无可自动化测点；换支持40-70Hz的源后可重评
A5: 交流频率 | B5: 交流频率 | C5: Function_AC meter_001_01_case4 | D5: 空载情况下，电表频率显示0 | E5: 1、Acuview2上位机 2、RTU串口线 3、AcuRev-100电表 | F5: 1、输出50HZ频率 2、关闭源输出 3、Acuview2上位机查看系统频率 | G5: 3、关闭源输出，频率显示0 | H5: LV1 | I5: 否 | J5: [2026-07-13] 转手工(用户裁决): 自供电表关源=电表断电,Modbus不可读; USB口供电能力未验证,验证通过后可重新评估自动化 | L5: 不可自动化：空载需关源＝给自供电表断电，Modbus无法回读；USB供电能力未验证
A6: 交流电压（相电压） | B6: 线-地电压(相电压)验证 | C6: Function_AC meter_002_01_case1 | D6: 交流电Van、Vbn、Vcn输入额定电压分别均为120V,测量Van、Vbn、Vcn、Vlnavg满足精度要求0.2% | E6: 1、Acuview2上位机 2、RTU串口线 3、AcuRev-100电表 | F6: 1、连接AcuRev-100电表到Acuview2上，链接状态为connected 2、交流电源输入相电压Van、Vbn、Vcn的额定电压为120V。 3、Acuview2上检查交流电相电压是否均在精度范围内 | G6: 3、Acuview2上检查交流电相电压均在精度范围内，范围(V):119.760 ~ 120.240 Vlnavg范围(V)：119.760 ~ 120.240 | H6: LV0 | I6: 是 | J6: 已调试 | K6: 未通过：判据读数全零——已知板子ADC芯片损坏问题(2026-07-14)，自动化流程本身已调通(设源/前置配置/救源/断言/报告全链路OK)，换板后重跑出有效结果 | L6: 未通过：已知板卡ADC芯片损坏读数为零，自动化全链路已调通，换板后重跑出有效结果
A7: 交流电压（相电压） | B7: 线-地电压(相电压)验证 | C7: Function_AC meter_002_01_case2 | D7: 交流电Van、Vbn、Vcn输入额定电压分别均为220V,277V,测量Van、Vbn、Vcn、Vlnavg满足精度要求0.2% | E7: 1、Acuview2上位机 2、RTU串口线 3、AcuRev-100电表 | F7: 1、连接AcuRev-100电表到Acuview2上，链接状态为connected 2、交流电源输入相电压Van、Vbn、Vcn的额定电压为220V。 3、Acuview2上检查交流电相电压是否均在精度范围内 4、交流电源输入相电压Van、Vbn、Vcn的额定电压为277V。 5、Acuview2上检查交流电相电压是否均在精度范围内 | G7: 3、Acuview2上检查交流电相电压均在精度范围内，范围(V):219.560 ~ 220.440，Vlnavg范围(V)：219.560 ~ 220.440 5、Acuview2上检查交流电相电压均在精度范围内，范围(V):276.446 ~ 277.554，Vlnavg范围(V)：276.446 ~ 277.554 | H7: LV1 | I7: 是 | J7: 已调试 | K7: 未通过：判据读数全零——已知板子ADC芯片损坏问题(2026-07-14)，自动化流程本身已调通(设源/前置配置/救源/断言/报告全链路OK)，换板后重跑出有效结果 | L7: 未通过：已知板卡ADC芯片损坏读数为零，自动化全链路已调通，换板后重跑出有效结果
A8: 交流电压（相电压） | B8: 线-地电压(相电压)验证 | C8: Function_AC meter_002_01_case3 | D8: 交流电Van、Vbn、Vcn输入临界电压分别均为10.2V、20V,电表有测量值,测量Van、Vbn、Vcn、Vlnavg没有精度要求 | E8: 1、Acuview2上位机 2、RTU串口线 3、AcuRev-100电表 | F8: 1、连接AcuRev-100电表到Acuview2上，链接状态为connected 2、交流电源输入相电压Van、Vbn、Vcn的额定电压为10.2V。 3、Acuview2上检查交流电相电压是否有测量显示，精度没有要求 4、交流电源输入相电压Van、Vbn、Vcn的额定电压为20V。 5、Acuview2上检查交流电相电压是否有测量显示，精度没有要求 | G8: 3、Acuview2上检查交流电相电压有测量显示，没有精度要求 5、Acuview2上检查交流电相电压有测量显示，没有精度要求 | H8: LV3 | I8: 是 | J8: 已调试 | K8: 未通过：判据读数全零——已知板子ADC芯片损坏问题(2026-07-14)，自动化流程本身已调通(设源/前置配置/救源/断言/报告全链路OK)，换板后重跑出有效结果 | L8: 未通过：已知板卡ADC芯片损坏读数为零，自动化全链路已调通，换板后重跑出有效结果
A9: 交流电压（相电压） | B9: 线-地电压(相电压)验证 | C9: Function_AC meter_002_01_case4 | D9: 交流电Van、Vbn、Vcn输入电压分别均为0V，1V，9V,电表Van、Vbn、Vcn、Vlnavg无测量值 | E9: 1、Acuview2上位机 2、RTU串口线 3、AcuRev-100电表 | F9: 1、连接AcuRev-100电表到Acuview2上，链接状态为connected 2、交流电源输入相电压Van、Vbn、Vcn的额定电压为0V。 3、Acuview2上检查交流电相电压是否为0V 4、交流电源输入相电压Van、Vbn、Vcn的额定电压为1V。 5、Acuview2上检查交流电相电压是否为0V，不考虑精度 6、交流电源输入相电压Van、Vbn、Vcn的额定电压为9V。 7、Acuview2上检查交流电相电压是否为0V，不考虑精度 | G9: 3、5、7、Acuview2上检查交流电相电压为0V | H9: LV4 | I9: 是 | J9: 已调试 | K9: 未通过：判据读数全零——已知板子ADC芯片损坏问题(2026-07-14)，自动化流程本身已调通(设源/前置配置/救源/断言/报告全链路OK)，换板后重跑出有效结果 | L9: 未通过：已知板卡ADC芯片损坏读数为零，自动化全链路已调通，换板后重跑出有效结果
A10: 交流电压（相电压） | B10: 线-地电压(相电压)验证 | C10: Function_AC meter_002_01_case5 | D10: 交流电Van、Vbn、Vcn输入额定电压为(120V,220V,277V),测量Van、Vbn、Vcn、Vlnavg满足精度要求0.2% | E10: 1、Acuview2上位机 2、RTU串口线 3、AcuRev-100电表 | F10: 1、连接AcuRev-100电表到Acuview2上，链接状态为connected 2、交流电源输入相电压Van、Vbn、Vcn的额定电压分别为(120V,220V,277V)。 3、Acuview2上检查交流电相电压是否均在精度范围内，Van范围,Vbn范围,Vcn范围,Vlnavg范围 | G10: 3、Acuview2上检查交流电相电压均在精度范围内， Van范围(V):119.760 ~ 120.240， Vbn范围(V):219.560 ~ 220.440， Vcn范围(V):276.446 ~ 277.554， Vlnavg范围(V):205.255 ~ 206.078 | H10: LV1 | I10: 是 | J10: 已调试 | K10: 未通过：判据读数全零——已知板子ADC芯片损坏问题(2026-07-14)，自动化流程本身已调通(设源/前置配置/救源/断言/报告全链路OK)，换板后重跑出有效结果 | L10: 未通过：已知板卡ADC芯片损坏读数为零，自动化全链路已调通，换板后重跑出有效结果
A11: 交流电压（相电压） | B11: 线-地电压(相电压)验证 | C11: Function_AC meter_002_01_case6 | D11: 交流电Van、Vbn、Vcn输入额定电压为(120V,120V,120V)顺序，且φA、φB、φC分别为(0°、130°、250°)，Van、Vbn、Vcn、Vlnavg测量值满足精度要求0.2% | E11: 1、Acuview2上位机 2、RTU串口线 3、AcuRev-100电表 | F11: 1、连接AcuRev-100电表到Acuview2上，链接状态为connected 2、交流电源输入相电压Van、Vbn、Vcn的额定电压为120V。 3、电表相序设置为ABC，φA、φB、φC分别为(0°、130°、250°) 4、Acuview2上检查交流电相电压Van、Vbn、Vcn、Vlnavg测量值是否满足精度要求 | G11: 4、Acuview2上检查交流电相电压均在精度范围内，范围(V):119.760 ~ 120.240， Vlnavg范围(V)：119.760 ~ 120.240 | H11: LV2 | I11: 是 | J11: 已调试 | K11: 未通过：判据读数全零——已知板子ADC芯片损坏问题(2026-07-14)，自动化流程本身已调通(设源/前置配置/救源/断言/报告全链路OK)，换板后重跑出有效结果 | L11: 未通过：已知板卡ADC芯片损坏读数为零，自动化全链路已调通，换板后重跑出有效结果
A12: 交流电压（相电压） | B12: 线-地电压(相电压)验证 | C12: Function_AC meter_002_01_case7 | D12: 电压为0，只加电流, 电流测量值正常，但不计算夹角、功率、能量；电压为10V，电流测量值正常，且计算夹角、功率、能量 | E12: 1、Acuview2上位机 2、RTU串口线 3、AcuRev-100电表 | F12: 1、连接AcuRev-100电表到Acuview2上，链接状态为connected 2、交流电源输入相电压Van、Vbn、Vcn的额定电压为0V。 3、电表相序设置为ABC，φA、φB、φC分别为(0°、240°、120°) 4、input1-3 设置为3A 5、Acuview2上检查交流电相电压Van、Vbn、Vcn、Vlnavg测量值是否为0V。 6、ABC三相, 输入通道input1-3电流均为3A 7、交流电源输入相电压Van、Vbn、Vcn的额定电压为10V。 8、电表相序设置为ABC，φA、φB、φC分别为(0°、240°、120°) 9、input1-3 设置为3A 10、ABC三相, 输入通道input1-3电流均为3A | G12: 5、Acuview2上检查交流电相电压Van、Vbn、Vcn、Vlnavg测量值为0V 6、ABC三相, 输入通道input1-3、均为3A，同时功率、夹角、能量不计算 10、ABC三相, 输入通道input1-3、电流均为3A，同时计算功率、夹角、能量 | H12: LV3 | I12: 是 | J12: 已调试 | K12: 未通过：判据读数全零——已知板子ADC芯片损坏问题(2026-07-14)，自动化流程本身已调通(设源/前置配置/救源/断言/报告全链路OK)，换板后重跑出有效结果 | L12: 未通过：已知板卡ADC芯片损坏读数为零，自动化全链路已调通，换板后重跑出有效结果
A13: 交变电压（线电压） | B13: 线-线电压(线电压)验证 | C13: Function_AC meter_003_01_case1 | D13: 交流电Van、Vbn、Vcn均输入电压220V和277V, 测量Vab、Vbc、Vca、Vllavg精度均满足要求0.2% | E13: 1、Acuview2上位机 2、RTU串口线 3、AcuRev-100电表 | F13: 1、连接AcuRev-100电表到Acuview2上，链接状态为connected 2、交流电源输入相电压Van、Vbn、Vcn的额定电压为220V。 3、Acuview2上检查交流电相电压是否均在精度范围内， 4、交流电源输入相电压Van、Vbn、Vcn的额定电压为277V。 5、Acuview2上检查交流电相电压是否均在精度范围内， | G13: 3、Acuview2上检查交流电线电压均在精度范围内， 范围(V):380.289 ~ 381.813， Vllavg范围(V)：380.289 ~ 381.813 5、Acuview2上检查交流电线电压均在精度范围内， 范围(V):478.819 ~ 480.738， Vllavg范围(V)：478.819 ~ 480.738 | H13: LV0 | I13: 是 | J13: 已调试 | K13: 未通过：判据读数全零——已知板子ADC芯片损坏问题(2026-07-14)，自动化流程本身已调通(设源/前置配置/救源/断言/报告全链路OK)，换板后重跑出有效结果 | L13: 未通过：已知板卡ADC芯片损坏读数为零，自动化全链路已调通，换板后重跑出有效结果
A14: 交变电压（线电压） | B14: 线-线电压(线电压)验证 | C14: Function_AC meter_003_01_case2 | D14: 交流电Van、Vbn、Vcn均输入临界电压10.2V、20V,电表有测量值，测量Vab、Vbc、Vca、Vllavg精度没有要求 | E14: 1、Acuview2上位机 2、RTU串口线 3、AcuRev-100电表 | F14: 1、连接AcuRev-100电表到Acuview2上，链接状态为connected 2、交流电源输入相电压Van、Vbn、Vcn的额定电压为10.2V。 3、Acuview2上检查交流电线电压是否有测量显示， 精度没有要求 4、交流电源输入相电压Van、Vbn、Vcn的额定电压为20V。 5、Acuview2上检查交流电线电压是否有测量显示, 精度没有要求 | G14: 3、Acuview2上检查交流电线电压有测量显示，精度没有要求 5、Acuview2上检查交流电线电压有测量显示，精度没有要求 | H14: LV3 | I14: 是 | J14: 已调试 | K14: 未通过：判据读数全零——已知板子ADC芯片损坏问题(2026-07-14)，自动化流程本身已调通(设源/前置配置/救源/断言/报告全链路OK)，换板后重跑出有效结果 | L14: 未通过：已知板卡ADC芯片损坏读数为零，自动化全链路已调通，换板后重跑出有效结果
A15: 交变电压（线电压） | B15: 线-线电压(线电压)验证 | C15: Function_AC meter_003_01_case3 | D15: 交流电Van、Vbn、Vcn均输入电压0V，1V，9V,电表Vab，Vbc、Vca、Vllavg无测量值 | E15: 1、Acuview2上位机 2、RTU串口线 3、AcuRev-100电表 | F15: 1、连接AcuRev-100电表到Acuview2上，链接状态为connected 2、交流电源输入相电压Van、Vbn、Vcn的额定电压为0V。 3、Acuview2上检查交流电线电压是否为0V 4、交流电源输入相电压Van、Vbn、Vcn的额定电压为1V。 5、Acuview2上检查交流电线电压是否为0V 6、交流电源输入相电压Van、Vbn、Vcn的额定电压为9V。 7、Acuview2上检查交流电线电压是否为0V | G15: 3、5、7、Acuview2上检查交流电线电压为0V | H15: LV3 | I15: 是 | J15: 已调试 | K15: 未通过：判据读数全零——已知板子ADC芯片损坏问题(2026-07-14)，自动化流程本身已调通(设源/前置配置/救源/断言/报告全链路OK)，换板后重跑出有效结果 | L15: 未通过：已知板卡ADC芯片损坏读数为零，自动化全链路已调通，换板后重跑出有效结果
A16: 交变电压（线电压） | B16: 线-线电压(线电压)验证 | C16: Function_AC meter_003_01_case4 | D16: 交流电Van、Vbn、Vcn输入额定电压为(120V,220V,270V), θA、θB、θC分别为(0°、60°、120°)测量Vab、Vbc、Vca、Vllavg满足精度要求0.2% | E16: 1、Acuview2上位机 2、RTU串口线 3、AcuRev-100电表 | F16: 1、连接AcuRev-100电表到Acuview2上，链接状态为connected 2、交流电源输入相电压Van、Vbn、Vcn的电压为(120V,220V,270V), θA、θB、θC分别为(0°、60°、120°)。 3、Acuview2上检查交流电线电压是否均在精度范围内， | G16: 3、Acuview2上检查交流电线电压均在精度范围内 Vab范围(V)：190.406 ~ 191.170 Vca范围(V)：345.285 ~ 346.669 Vbc范围(V)：248.300 ~ 249.295 Vllavg范围(V)：261.330 ~ 262.378 | H16: LV2 | I16: 是 | J16: 已调试 | K16: 未通过：判据读数全零——已知板子ADC芯片损坏问题(2026-07-14)，自动化流程本身已调通(设源/前置配置/救源/断言/报告全链路OK)，换板后重跑出有效结果 | L16: 未通过：已知板卡ADC芯片损坏读数为零，自动化全链路已调通，换板后重跑出有效结果
A17: 电流测量 | B17: 相电流测量验证 | C17: Function_AC meter_004_01_case1 | D17: CT选型333mV(200A)，3E4WY，三路电流分别为(50A、100A，200A)，在上位机上分别配置为对应A相、B相、C相，测量Ia,Ib,Ic,Iavg满足精度0.2% | E17: 1、Acuview2上位机 2、RTU串口线 3、AcuRev-100电表 4、接线方式3E4WY | F17: 1、连接AcuRev-100电表到Acuview2上，链接状态为connected 1.1、使用5A/333mV CT，将CT变比值设置为200 2、使用台体输入三路电流分别为(1.25A、2.5A，5A)，在上位机上分别配置为对应A相、B相、C相 3、Acuview2上检查交流电相电流是否均在精度范围内 | G17: 3、Acuview2上检查交流电相电流均在精度范围内 Ia： 49.900 ~ 50.100 Ib: 99.800 ~ 100.200 Ic: 199.600 ~ 200.400 Iavg: 116.433 ~ 116.900 | H17: LV0 | I17: 是 | J17: 已生成待调试：mV用例回归原文配置(333mV)，待接入5A/333mV CT回路后调试(2026-07-14) | L17: 待调试：mV用例回归原文配置（333mV），待台面接入5A/333mV CT回路后调试
A18: 电流测量 | B18: 相电流测量验证 | C18: Function_AC meter_004_01_case2 | D18: CT选型333mV(200A)，三路电流分别为Imin（2，2，2）,在上位机上分别配置为对应A相、B相、C相，精度满足精度0.2%,三路电流分别为(0.2,0.1,0.2),无精度要求 备注：0.2A为Ist | E18: 1、Acuview2上位机 2、RTU串口线 3、AcuRev-100电表 4、接线方式3E4WY | F18: 1、连接AcuRev-100电表到Acuview2上，链接状态为connected 2、输入三路电流分别为（0.05，0.05，0.05）,在上位机上分别配置为对应A相、B相、C相。 3、精度保证的电流范围应符合要求 4、输入三路电流分别为（0.005，0.0025，0.005）,在上位机上分别配置为对应A相、B相、C相，无精度要求 | G18: 3、Acuview2上检查交流电相电流均在精度范围内 Ia： 1.996 ~ 2.004 Ib: 1.996 ~ 2.004 Ic: 1.996 ~ 2.004 Iavg: 1.996 ~ 2.004 4、Acuview2上检查交流电相电流显示约为：0.2,0.1,0.2(无精度要求；Ib=0.1A低于Ist 0.2A，按PRS §3.1仅功率/电能不累计，电流显示是否归零待需求澄清，不作硬判据) | H18: LV0 | I18: 是 | J18: 已生成待调试：mV用例回归原文配置(333mV)，待接入5A/333mV CT回路后调试(2026-07-14) | L18: 待调试：mV用例回归原文配置（333mV），待台面接入5A/333mV CT回路后调试
A19: 电流测量 | B19: 相电流测量验证 | C19: Function_AC meter_004_01_case3 | D19: CT选型333mV(200A)，一路电流为（100A），在上位机均配置为对应A相，测量Ia,Ib,Ic,Iavg满足精度0.2% | E19: 1、Acuview2上位机 2、RTU串口线 3、AcuRev-100电表 4、接线方式3E4WY | F19: 1、连接AcuRev-100电表到Acuview2上，链接状态为connected 2、输入一路电流分别为（2.5A），在上位机均配置为对应A相 3、Acuview2上检查交流电相电流是否均在精度范围内 | G19: 3、Acuview2上检查交流电相电流均在精度范围内 Ia： 99.800 ~ 100.200 Ib: 0 ~ 0 Ic: 0 ~ 0 Iavg: 33.267 ~ 33.400 | H19: LV1 | I19: 是 | J19: 已生成待调试：mV用例回归原文配置(333mV)，待接入5A/333mV CT回路后调试(2026-07-14) | L19: 待调试：mV用例回归原文配置（333mV），待台面接入5A/333mV CT回路后调试
A20: 电流测量 | B20: 相电流测量验证 | C20: Function_AC meter_004_01_case4 | D20: CT选型333mV(200A)，两路电流分别为(200A、240A),在上位机均配置为对应B相和C相，测量Ia,Ib,Ic,Iavg满足精度0.2% | E20: 1、Acuview2上位机 2、RTU串口线 3、AcuRev-100电表 4、接线方式3E4WY | F20: 1、连接AcuRev-100电表到Acuview2上，链接状态为connected 2、输入两路电流分别为(5A、6A),在上位机均配置为对应B相和C相。 3、Acuview2上检查交流电相电流是否均在精度范围内 | G20: 3、Acuview2上检查交流电相电流均在精度范围内 Ia： 0 ~ 0 Ib: 199.600 ~ 200.400 Ic: 239.520 ~ 240.480 Iavg: 146.373 ~ 146.960 | H20: LV1 | I20: 是 | J20: 已生成待调试：mV用例回归原文配置(333mV)，待接入5A/333mV CT回路后调试(2026-07-14) | L20: 待调试：mV用例回归原文配置（333mV），待台面接入5A/333mV CT回路后调试
A21: 电流测量 | B21: 相电流测量验证 | C21: Function_AC meter_004_01_case5 | D21: CT选型333mV(200A)，三路电流分别为(50A、100A，120A)，顺序ABC，相角设置为(0°、240°、120°)，电表设置电流分别为Positive、Negative，在上位机上分别配置为对应A相、B相、C相，测量Ia,Ib,Ic,Iavg满足精度0.2% | E21: 1、Acuview2上位机 2、RTU串口线 3、AcuRev-100电表 4、接线方式3E4WY | F21: 1、连接AcuRev-100电表到Acuview2上，链接状态为connected 2、输入三路电流分别为(1.25A、2.5A，3A)，在上位机上分别配置为对应A相、B相、C相 3、电表上设置为顺序ABC， 相角设置为(0°、240°、120°) 4、电表设置电流方向为Positive 5、Acuview2上检查交流电相电流是否均在精度范围内 6、电表设置电流方向为Negative 7、Acuview2上检查交流电相电流是否均在精度范围内 | G21: 5、Acuview2上检查交流电相电流均在精度范围内 Ia： 49.900 ~ 50.100 Ib: 99.800 ~ 100.200 Ic: 119.760 ~ 120.240 Iavg: 89.820 ~ 90.180 6、Acuview2上检查交流电相电流均在精度范围内 Ia： 49.900 ~ 50.100 Ib: 99.800 ~ 100.200 Ic: 119.760 ~ 120.240 Iavg: 89.820 ~ 90.180 用户通道&输入通道&系统参数PF 为-1 用户通道&输入通道&系统参数有功功率P为负数 | H21: LV2 | I21: 是 | J21: 已生成待调试：mV用例回归原文配置(333mV)，待接入5A/333mV CT回路后调试(2026-07-14) | L21: 待调试：mV用例回归原文配置（333mV），待台面接入5A/333mV CT回路后调试
A22: 电流测量 | B22: 相电流测量验证 | C22: Function_AC meter_004_01_case6 | D22: CT选型333mV(400A)，3E4WY，三路电流分别为(50A、200A，400A)，在上位机上分别配置为对应A相、B相、C相，测量Ia,Ib,Ic,Iavg满足精度0.2% | E22: 1、Acuview2上位机 2、RTU串口线 3、AcuRev-100电表 4、接线方式3E4WY | F22: 1、连接AcuRev-100电表到Acuview2上，链接状态为connected 2、输入三路电流分别为(0.625A、2.5A，5A)，在上位机上分别配置为对应A相、B相、C相 3、Acuview2上检查交流电相电流是否均在精度范围内 | G22: 3、Acuview2上检查交流电相电流均在精度范围内 Ia： 49.900 ~ 50.100 Ib: 199.600 ~ 200.400 Ic: 399.200 ~ 400.800 Iavg: 216.233 ~ 217.100 | H22: LV1 | I22: 是 | J22: 已生成待调试：mV用例回归原文配置(333mV)，待接入5A/333mV CT回路后调试(2026-07-14) | L22: 待调试：mV用例回归原文配置（333mV），待台面接入5A/333mV CT回路后调试
A23: 电流测量 | B23: 相电流测量验证 | C23: Function_AC meter_004_01_case7 | D23: CT选型333mV(400A)，三路电流分别为Imin（4A，4A，4A）,在上位机上分别配置为对应A相、B相、C相，精度保证的电流范围0.2%,输入三路电流分别为（0.4A，0.4A，0.4A） 备注：0.4A为Ist | E23: 1、Acuview2上位机 2、RTU串口线 3、AcuRev-100电表 4、接线方式3E4WY | F23: 1、连接AcuRev-100电表到Acuview2上，链接状态为connected 2、输入三路电流分别为（0.05，0.05，0.05）,在上位机上分别配置为对应A相、B相、C相。 3、精度保证的电流范围是否符合精度要求 4、源输入电流A\B\C三相分别为（0.005，0，0.005） | G23: 3、Acuview2上检查交流电相电流均在精度范围内 Ia： 3.992 ~ 4.008 Ib: 3.992 ~ 4.008 Ic: 3.992 ~ 4.008 Iavg: 3.992 ~ 4.008 4、Acuview2上检查交流电相电流分别为：0.4,0,0.4(无精度要求) | H23: LV1 | I23: 是 | J23: 已生成待调试：mV用例回归原文配置(333mV)，待接入5A/333mV CT回路后调试(2026-07-14) | L23: 待调试：mV用例回归原文配置（333mV），待台面接入5A/333mV CT回路后调试
A24: 电流测量 | B24: 相电流测量验证 | C24: Function_AC meter_004_01_case8 | D24: CT选型100mA(200A)，3E4WY，三路电流分别为(50A、100A，200A)，在上位机上分别配置为对应A相、B相、C相，测量Ia,Ib,Ic,Iavg满足精度0.2% | E24: 1、Acuview2上位机 2、RTU串口线 3、AcuRev-100电表 4、接线方式3E4WY | F24: 1、连接AcuRev-100电表到Acuview2上，链接状态为connected 2、输入三路电流分别为(5A、10A，20A)，在上位机上分别配置为对应A相、B相、C相 3、Acuview2上检查交流电相电流是否均在精度范围内 | G24: 3、Acuview2上检查交流电相电流均在精度范围内 Ia： 49.900 ~ 50.100 Ib: 99.800 ~ 100.200 Ic: 199.600 ~ 200.400 Iavg: 116.433 ~ 116.900 | H24: LV1 | I24: 是 | J24: 已调试 | K24: 未通过：判据读数全零——已知板子ADC芯片损坏问题(2026-07-14)，自动化流程本身已调通(设源/前置配置/救源/断言/报告全链路OK)，换板后重跑出有效结果 | L24: 未通过：已知板卡ADC芯片损坏读数为零，自动化全链路已调通，换板后重跑出有效结果
A25: 电流测量 | B25: 相电流测量验证 | C25: Function_AC meter_004_01_case9 | D25: CT选型100mA(200A)，三路电流分别为Imin（2，2，2）,在上位机上分别配置为对应A相、B相、C相，精度满足精度0.2%,三路电流分别为(0.2,0.1,0.2),无精度要求 备注：0.2A为Ist | E25: 1、Acuview2上位机 2、RTU串口线 3、AcuRev-100电表 4、接线方式3E4WY | F25: 1、连接AcuRev-100电表到Acuview2上，链接状态为connected 2、输入三路电流分别为（0.2，0.2，0.2）,在上位机上分别配置为对应A相、B相、C相。 3、精度保证的电流范围是否符合 精度要求 4、源输入电流A\B\C三相分别为（0.02，0.01，0.02） | G25: 3、Acuview2上检查交流电相电流均在精度范围内 Ia： 1.996 ~ 2.004 Ib: 1.996 ~ 2.004 Ic: 1.996 ~ 2.004 Iavg: 1.996 ~ 2.004 4、Acuview2上检查交流电相电流分别为：0.2,0.1,0.2(无精度要求) | H25: LV1 | I25: 是 | J25: 已调试 | K25: 未通过：判据读数全零——已知板子ADC芯片损坏问题(2026-07-14)，自动化流程本身已调通(设源/前置配置/救源/断言/报告全链路OK)，换板后重跑出有效结果 | L25: 未通过：已知板卡ADC芯片损坏读数为零，自动化全链路已调通，换板后重跑出有效结果
A26: 电流测量 | B26: 相电流测量验证 | C26: Function_AC meter_004_01_case10 | D26: CT选型100mA(400A)，3E4WY，三路电流分别为(50A、200A，400A)，在上位机上分别配置为对应A相、B相、C相，测量Ia,Ib,Ic,Iavg满足精度0.2% | E26: 1、Acuview2上位机 2、RTU串口线 3、AcuRev-100电表 4、接线方式3E4WY | F26: 1、连接AcuRev-100电表到Acuview2上，链接状态为connected 2、输入三路电流分别为(2.5A、10A，20A)，在上位机上分别配置为对应A相、B相、C相 3、Acuview2上检查交流电相电流是否均在精度范围内 | G26: 3、Acuview2上检查交流电相电流均在精度范围内 Ia： 49.900 ~ 50.100 Ib: 199.600 ~ 200.400 Ic: 399.200 ~ 400.800 Iavg: 216.233 ~ 217.100 | H26: LV2 | I26: 是 | J26: 已调试 | K26: 未通过：判据读数全零——已知板子ADC芯片损坏问题(2026-07-14)，自动化流程本身已调通(设源/前置配置/救源/断言/报告全链路OK)，换板后重跑出有效结果 | L26: 未通过：已知板卡ADC芯片损坏读数为零，自动化全链路已调通，换板后重跑出有效结果
A27: 电流测量 | B27: 相电流测量验证 | C27: Function_AC meter_004_01_case11 | D27: CT选型100mA(400A)，三路电流分别为Imin（4A，4A，4A）,在上位机上分别配置为对应A相、B相、C相，精度保证的电流范围0.2%,输入三路电流分别为（0.4A，0A，0.4A） 备注：0.4A为Ist | E27: 1、Acuview2上位机 2、RTU串口线 3、AcuRev-100电表 4、接线方式3E4WY | F27: 1、连接AcuRev-100电表到Acuview2上，链接状态为connected 2、输入三路电流分别为（0.2，0.2，0.2）,在上位机上分别配置为对应A相、B相、C相 3、精度保证的电流范围是否符合精度的要求 4、输入三路电流分别为（0.02，0，0.02）,在上位机上分别配置为对应A相、B相、C相 | G27: 3、Acuview2上检查交流电相电流均在精度范围内 Ia： 3.992 ~ 4.008 Ib: 3.992 ~ 4.008 Ic: 3.992 ~ 4.008 Iavg: 3.992 ~ 4.008 4、Acuview2上检查交流电相电流分别为：（0.4A，0A，0.4A）(无精度要求) | H27: LV1 | I27: 是 | J27: 已调试 | K27: 未通过：判据读数全零——已知板子ADC芯片损坏问题(2026-07-14)，自动化流程本身已调通(设源/前置配置/救源/断言/报告全链路OK)，换板后重跑出有效结果 | L27: 未通过：已知板卡ADC芯片损坏读数为零，自动化全链路已调通，换板后重跑出有效结果
A28: 电流测量 | B28: 相电流测量验证 | C28: Function_AC meter_004_01_case12 | D28: CT选型100mA(800A)，3E4WY，三路电流分别为(50A、400A，800A)，在上位机上分别配置为对应A相、B相、C相，测量Ia,Ib,Ic,Iavg满足精度0.2% | E28: 1、Acuview2上位机 2、RTU串口线 3、AcuRev-100电表 4、接线方式3E4WY | F28: 1、连接AcuRev-100电表到Acuview2上，链接状态为connected 2、输入三路电流分别为(1.25A、10A，20A)，在上位机上分别配置为对应A相、B相、C相 3、Acuview2上检查交流电相电流是否均在精度范围内 | G28: 3、Acuview2上检查交流电相电流均在精度范围内 Ia： 49.900 ~ 50.100 Ib: 399.200 ~ 400.800 Ic: 798.400 ~ 801.600 Iavg: 415.833 ~ 417.500 | H28: LV1 | I28: 是 | J28: 已调试 | K28: 未通过：判据读数全零——已知板子ADC芯片损坏问题(2026-07-14)，自动化流程本身已调通(设源/前置配置/救源/断言/报告全链路OK)，换板后重跑出有效结果 | L28: 未通过：已知板卡ADC芯片损坏读数为零，自动化全链路已调通，换板后重跑出有效结果
A29: 电流测量 | B29: 相电流测量验证 | C29: Function_AC meter_004_01_case13 | D29: CT选型100mA(800A)，三路电流分别为（8，8，8）,在上位机上分别配置为对应A相、B相、C相，精度保证的电流范围0.2%,输入三路电流分别为（0.8A，0A，0.8A） 备注：0.8A为Ist | E29: 1、Acuview2上位机 2、RTU串口线 3、AcuRev-100电表 4、接线方式3E4WY | F29: 1、连接AcuRev-100电表到Acuview2上，链接状态为connected 2、输入三路电流分别为（0.2，0.2，0.2）,在上位机上分别配置为对应A相、B相、C相。 3、精度保证的电流范围是否符合精度要求 4、源输入电流A\B\C三相分别为（0.02，0，0.02） | G29: 3、Acuview2上检查交流电相电流均在精度范围内 Ia： 7.984 ~ 8.016 Ib: 7.984 ~ 8.016 Ic: 7.984 ~ 8.016 Iavg: 7.984 ~ 8.016 4、Acuview2上检查交流电相电流分别为：（0.8A，0A，0.8A）(无精度要求) | H29: LV2 | I29: 是 | J29: 已调试 | K29: 未通过：判据读数全零——已知板子ADC芯片损坏问题(2026-07-14)，自动化流程本身已调通(设源/前置配置/救源/断言/报告全链路OK)，换板后重跑出有效结果 | L29: 未通过：已知板卡ADC芯片损坏读数为零，自动化全链路已调通，换板后重跑出有效结果
A30: 电流测量 | B30: 相电流测量验证 | C30: Function_AC meter_004_01_case14 | D30: CT选型100mA(1200A)，3E4WY，三路电流分别为(50A、600A，1200A)，在上位机上分别配置为对应A相、B相、C相，测量Ia,Ib,Ic,Iavg满足精度0.2% | E30: 1、Acuview2上位机 2、RTU串口线 3、AcuRev-100电表 4、接线方式3E4WY | F30: 1、连接AcuRev-100电表到Acuview2上，链接状态为connected 2、输入三路电流分别为(0.8333A、10A，20A)，在上位机上分别配置为对应A相、B相、C相 3、Acuview2上检查交流电相电流是否均在精度范围内 | G30: 3、Acuview2上检查交流电相电流均在精度范围内 Ia： 49.900 ~ 50.100 Ib: 598.800 ~ 601.200 Ic: 1197.600 ~ 1202.400 Iavg: 615.433 ~ 617.900 | H30: LV1 | I30: 是 | J30: 已调试 | K30: 未通过：判据读数全零——已知板子ADC芯片损坏问题(2026-07-14)，自动化流程本身已调通(设源/前置配置/救源/断言/报告全链路OK)，换板后重跑出有效结果 | L30: 未通过：已知板卡ADC芯片损坏读数为零，自动化全链路已调通，换板后重跑出有效结果
A31: 电流测量 | B31: 相电流测量验证 | C31: Function_AC meter_004_01_case15 | D31: CT选型100mA(1200A)，三路电流分别为（12，12，12）,在上位机上分别配置为对应A相、B相、C相，精度保证的电流范围0.2%,输入三路电流分别为（1.2A，1.2A，1.2A） 备注：0.8A为Ist | E31: 1、Acuview2上位机 2、RTU串口线 3、AcuRev-100电表 4、接线方式3E4WY | F31: 1、连接AcuRev-100电表到Acuview2上，链接状态为connected 2、输入三路电流分别为（0.2，0.2，0.2）,在上位机上分别配置为对应A相、B相、C相。 3、精度保证的电流范围是否符合精度要求 4、源输入电流A\B\C三相分别为（0.02，0，0.02） | G31: 3、Acuview2上检查交流电相电流均在精度范围内 Ia： 11.976 ~ 12.024 Ib: 11.976 ~ 12.024 Ic: 11.976 ~ 12.024 Iavg: 11.976 ~ 12.024 4、Acuview2上检查交流电相电流分别为：（1.2A，1.2A，1.2A）(无精度要求) | H31: LV1 | I31: 是 | J31: 已调试 | K31: 未通过：判据读数全零——已知板子ADC芯片损坏问题(2026-07-14)，自动化流程本身已调通(设源/前置配置/救源/断言/报告全链路OK)，换板后重跑出有效结果 | L31: 未通过：已知板卡ADC芯片损坏读数为零，自动化全链路已调通，换板后重跑出有效结果
A32: 电流测量 | B32: 相电流测量验证 | C32: Function_AC meter_004_01_case16 | D32: CT选型RCT(500A)，3E4WY，输入三路电流分别为(50A、300A，500A)，在上位机上分别配置为对应A相、B相、C相，测量Ia,Ib,Ic,Iavg满足精度0.2% | E32: 1、Acuview2上位机 2、RTU串口线 3、AcuRev-100电表 4、接线方式3E4WY | F32: 1、连接AcuRev-100电表到Acuview2上，链接状态为connected 2、输入三路电流分别为(0.5A、3A，5A)，在上位机上分别配置为对应A相、B相、C相 3、Acuview2上检查交流电相电流是否均在精度范围内 | G32: 3、Acuview2上检查交流电相电流均在精度范围内 Ia： 49.900 ~ 50.100 Ib: 299.400 ~ 300.600 Ic: 499.000 ~ 501.000 Iavg: 282.767 ~ 283.900 | H32: LV1 | I32: 是 | J32: 已生成待调试：CT类型(80mA/RCT)无寄存器枚举映射，待固件/工程师确认(2026-07-14) | L32: 待调试：80mA/RCT无CT类型寄存器枚举映射，待固件/工程师确认后调试
A33: 电流测量 | B33: 相电流测量验证 | C33: Function_AC meter_004_01_case17 | D33: CT选型RCT(1000A)，3E4WY，输入三路电流分别为(400A、600A，800A)，在上位机上分别配置为对应A相、B相、C相，测量Ia,Ib,Ic,Iavg满足精度0.2% | E33: 1、Acuview2上位机 2、RTU串口线 3、AcuRev-100电表 4、接线方式3E4WY | F33: 1、连接AcuRev-100电表到Acuview2上，链接状态为connected 2、输入三路电流分别为(2A、3A，4A)，在上位机上分别配置为对应A相、B相、C相 3、Acuview2上检查交流电相电流是否均在精度范围内 | G33: 3、Acuview2上检查交流电相电流均在精度范围内 Ia： 399.200 ~ 400.800 Ib: 598.800 ~ 601.200 Ic: 798.400 ~ 801.600 Iavg: 598.800 ~ 601.200 | H33: LV2 | I33: 是 | J33: 已生成待调试：CT类型(80mA/RCT)无寄存器枚举映射，待固件/工程师确认(2026-07-14) | L33: 待调试：80mA/RCT无CT类型寄存器枚举映射，待固件/工程师确认后调试
A34: 电流测量 | B34: 相电流测量验证 | C34: Function_AC meter_004_01_case18 | D34: CT选型100mA(5A)，3E4WY，CT一次侧额定电流取5-2000A范围下限5A，三路显示电流均为2.5A，测量Ia,Ib,Ic,Iavg满足精度0.2% | E34: 1、Acuview2上位机 2、RTU串口线 3、AcuRev-100电表 4、接线方式3E4WY | F34: 1、连接AcuRev-100电表到Acuview2上，链接状态为connected 2、上位机配置CT Type=100mA、CT Primary=5（范围下限） 3、源输入三路电流均为10A（经台体CT 20A/100mA，显示系数=Primary/20=0.25，对应显示2.5A；源Ic带载不足，不取20A），分别配置为对应A相、B相、C相 4、Acuview2上检查Ia、Ib、Ic、Iavg是否均在精度范围内 5、恢复CT Primary=1000（默认值） | G34: 4、Acuview2上检查交流电相电流均在精度范围内 Ia：2.495 ~ 2.505 Ib：2.495 ~ 2.505 Ic：2.495 ~ 2.505 Iavg：2.495 ~ 2.505 5、回读CT Primary=1000，还原成功 | H34: LV1 | I34: 是 | J34: 已调试 | K34: 未通过：判据读数全零——已知板子ADC芯片损坏问题(2026-07-14)，自动化流程本身已调通(CT Primary字面值前置写入成功/设源/断言/报告全链路OK)，换板后重跑出有效结果 | L34: 未通过：已知板卡ADC芯片损坏读数为零，换板后重跑；本次已真机实证固件支持CT Primary 5-2000A字面值写入(5/1500/2000均写入回读一致)，helpers已切字面值口径，跑后已还原1000；07-14台面反馈源Ic 20A过载→源电流降10A(显示2.5A)已修正重跑
A35: 电流测量 | B35: 相电流测量验证 | C35: Function_AC meter_004_01_case19 | D35: CT选型100mA(2000A)，3E4WY，CT一次侧额定电流取5-2000A范围上限2000A，三路显示电流均为1000A，测量Ia,Ib,Ic,Iavg满足精度0.2% | E35: 1、Acuview2上位机 2、RTU串口线 3、AcuRev-100电表 4、接线方式3E4WY | F35: 1、连接AcuRev-100电表到Acuview2上，链接状态为connected 2、上位机配置CT Type=100mA、CT Primary=2000（范围上限） 3、源输入三路电流均为10A（经台体CT 20A/100mA，显示系数=Primary/20=100，对应显示1000A），分别配置为对应A相、B相、C相 4、Acuview2上检查Ia、Ib、Ic、Iavg是否均在精度范围内 5、恢复CT Primary=1000（默认值） | G35: 4、Acuview2上检查交流电相电流均在精度范围内 Ia：998.0 ~ 1002.0 Ib：998.0 ~ 1002.0 Ic：998.0 ~ 1002.0 Iavg：998.0 ~ 1002.0 5、回读CT Primary=1000，还原成功 | H35: LV1 | I35: 是 | J35: 已调试 | K35: 未通过：判据读数全零——已知板子ADC芯片损坏问题(2026-07-14)，自动化流程本身已调通(CT Primary字面值前置写入成功/设源/断言/报告全链路OK)，换板后重跑出有效结果 | L35: 未通过：已知板卡ADC芯片损坏读数为零，换板后重跑；本次已真机实证固件支持CT Primary 5-2000A字面值写入(5/1500/2000均写入回读一致)，helpers已切字面值口径，跑后已还原1000
A36: 电流测量 | B36: 相电流测量验证 | C36: Function_AC meter_004_01_case20 | D36: CT选型100mA(1500A)，3E4WY，CT一次侧额定电流取5-2000A范围内任意值1500A，三路显示电流均为750A，测量Ia,Ib,Ic,Iavg满足精度0.2% | E36: 1、Acuview2上位机 2、RTU串口线 3、AcuRev-100电表 4、接线方式3E4WY | F36: 1、连接AcuRev-100电表到Acuview2上，链接状态为connected 2、上位机配置CT Type=100mA、CT Primary=1500（范围内任意非档位值） 3、源输入三路电流均为10A（经台体CT 20A/100mA，显示系数=Primary/20=75，对应显示750A），分别配置为对应A相、B相、C相 4、Acuview2上检查Ia、Ib、Ic、Iavg是否均在精度范围内 5、恢复CT Primary=1000（默认值） | G36: 4、Acuview2上检查交流电相电流均在精度范围内 Ia：748.5 ~ 751.5 Ib：748.5 ~ 751.5 Ic：748.5 ~ 751.5 Iavg：748.5 ~ 751.5 5、回读CT Primary=1000，还原成功 | H36: LV3 | I36: 是 | J36: 已调试 | K36: 未通过：判据读数全零——已知板子ADC芯片损坏问题(2026-07-14)，自动化流程本身已调通(CT Primary字面值前置写入成功/设源/断言/报告全链路OK)，换板后重跑出有效结果 | L36: 未通过：已知板卡ADC芯片损坏读数为零，换板后重跑；本次已真机实证固件支持CT Primary 5-2000A字面值写入(5/1500/2000均写入回读一致)，helpers已切字面值口径，跑后已还原1000
A37: 电流测量 | B37: 对应不同接线方式电流验证 | C37: Function_AC meter_004_02_case1 | D37: CT选型333mV(200A)，1E2W输入InputA电流为100A，测量InputA电流精度0.2% | E37: 1、Acuview2上位机 2、RTU串口线 3、AcuRev-100电表 4、1E2W | F37: 1、连接AcuRev-100电表到Acuview2上，链接状态为connected 2、1E2W输入InputA电流为2.5A 3、Acuview2上检查电流InputA是否均在精度范围内 | G37: 3、Acuview2上检查电流InputA在精度范围内 IA: 99.800 ~ 100.200 | H37: LV0 | I37: 是 | J37: 已生成待调试：mV用例回归原文配置(333mV)，待接入5A/333mV CT回路后调试(2026-07-14) | L37: 待调试：mV用例回归原文配置（333mV），待台面接入5A/333mV CT回路后调试
A38: 电流测量 | B38: 对应不同接线方式电流验证 | C38: Function_AC meter_004_02_case2 | D38: CT选型333mV(200A)，2E3W1P接线输入InputA、InputC电流为(100A、200A)，测量InputA、InputC电流精度0.2% | E38: 1、Acuview2上位机 2、RTU串口线 3、AcuRev-100电表 4、2E3W1P | F38: 1、连接AcuRev-100电表到Acuview2上，链接状态为connected 2、2E3W1P接线输入InputA、InputC电流为(2.5A、5A) 3、Acuview2上检查电流InputA、InputC是否均在精度范围内 | G38: 3、Acuview2上检查电流InputA、InputC均在精度范围内 Ia: 99.800 ~ 100.200 Ic: 199.600 ~ 200.400 | H38: LV0 | I38: 是 | J38: 已生成待调试：mV用例回归原文配置(333mV)，待接入5A/333mV CT回路后调试(2026-07-14) | L38: 待调试：mV用例回归原文配置（333mV），待台面接入5A/333mV CT回路后调试
A39: PF、功率 | B39: PF、功率 | C39: Function_AC meter_005_01_case1 | D39: CT选型333mV(200A)，3E4WY接线，输入ABC电压均为220V，(A&B&C相)电流为(50A、50A、50A)，电压角度分别为(0，240，120)，电流角度分别为(0，240，120)，AC meter上检查测量PF、功率 | E39: 1、Acuview2上位机 2、RTU串口线 3、AcuRev-100电表 4、3E4WY | F39: 1、连接AcuRev-100电表到Acuview2上，链接状态为connected 2、输入(A&B&C相)电流为(1.25A、1.25A、1.25A)，电压均为220V 3、电压角度分别为(0，240，120)，电流角度分别为(0，240，120) 4、AC meter上检查测量PF、功率精度是否满足要求 | G39: 4、AC meter上检查测量PF、功率精度满足要求 有功功率 P 取值（±0.2%，工程设计目标；认证硬指标为0.5%）： A相：10978.0 ~ 11022.0 W B相：10978.0 ~ 11022.0 W C相：10978.0 ~ 11022.0 W 系统：32934.0 ~ 33066.0 W 无功功率 Q 取值（±0.5%，以额定S为基准，SRS §3.5）： A相：-55.0 ~ 55.0 VAR B相：-55.0 ~ 55.0 VAR C相：-55.0 ~ 55.0 VAR 系统：-165.0 ~ 165.0 VAR 视在功率 S 取值（±0.5%，SRS §3.5）： A相：10945.0 ~ 11055.0 VA B相：10945.0 ~ 11055.0 VA C相：10945.0 ~ 11055.0 VA 系统：32835.0 ~ 33165.0 VA 功率因数 PF 取值：（Class 0.2，±0.002） A相：PF 0.998 ~ 1.002 B相：PF 0.998 ~ 1.002 C相：PF 0.998 ~ 1.002 系统：PF 0.998 ~ 1.002 | H39: LV0 | I39: 是 | J39: 已生成待调试：mV用例回归原文配置(333mV)，待接入5A/333mV CT回路后调试(2026-07-14) | L39: 待调试：mV用例回归原文配置（333mV），待台面接入5A/333mV CT回路后调试
A40: PF、功率 | B40: PF、功率 | C40: Function_AC meter_005_01_case2 | D40: CT选型333mV(200A)，3E4WY接线，输入ABC电压均为120V，(A&B&C相)电流为(100A、100A、100A)，电压角度分别为(0、240、120)，电流角度分别为(30、270、150)，AC meter上检查测量PF、功率 | E40: 1、Acuview2上位机 2、RTU串口线 3、AcuRev-100电表 4、3E4WY | F40: 1、连接AcuRev-100电表到Acuview2上，链接状态为connected 2、(A&B&C相)电流为(2.5A、2.5A、2.5A)，电压均为120V 3、电压角度分别为(0、240、120)，电流角度分别为(30、270、150) 4、AC meter上检查测量PF、功率精度是否满足要求 | G40: 4、AC meter上检查测量PF、功率精度满足要求 有功功率 P 取值（±0.2%，工程设计目标；认证硬指标为0.5%）： A相：10371.5 ~ 10413.1 W B相：10371.5 ~ 10413.1 W C相：10371.5 ~ 10413.1 W 系统：31114.5 ~ 31239.3 W 无功功率 Q 取值（±0.5%，以额定S为基准，SRS §3.5）： A相：-6060.0 ~ -5940.0 VAR B相：-6060.0 ~ -5940.0 VAR C相：-6060.0 ~ -5940.0 VAR 系统：-18180.0 ~ -17820.0 VAR 视在功率 S 取值（±0.5%，SRS §3.5）： A相：11940.0 ~ 12060.0 VA B相：11940.0 ~ 12060.0 VA C相：11940.0 ~ 12060.0 VA 系统：35820.0 ~ 36180.0 VA 功率因数 PF 取值：（Class 0.2，±0.002） A相：PF 0.864 ~ 0.868 B相：PF 0.864 ~ 0.868 C相：PF 0.864 ~ 0.868 系统：PF 0.864 ~ 0.868 | H40: LV1 | I40: 是 | J40: 已生成待调试：mV用例回归原文配置(333mV)，待接入5A/333mV CT回路后调试(2026-07-14) | L40: 待调试：mV用例回归原文配置（333mV），待台面接入5A/333mV CT回路后调试
...
